/scratch/cnt0024/hmg2840/albert7a/anaconda3/lib/python3.7/site-packages/distributed/utils.py:136: RuntimeWarning: Couldn't detect a suitable IP address for reaching '8.8.8.8', defaulting to '127.0.0.1': [Errno 101] Network is unreachable
  RuntimeWarning,
distributed.nanny - INFO -         Start Nanny at: 'tcp://172.30.10.91:42863'
distributed.nanny - INFO -         Start Nanny at: 'tcp://172.30.10.91:36123'
distributed.nanny - INFO -         Start Nanny at: 'tcp://172.30.10.91:41186'
distributed.nanny - INFO -         Start Nanny at: 'tcp://172.30.10.91:45712'
distributed.nanny - INFO -         Start Nanny at: 'tcp://172.30.10.91:46091'
distributed.nanny - INFO -         Start Nanny at: 'tcp://172.30.10.91:39577'
distributed.nanny - INFO -         Start Nanny at: 'tcp://172.30.10.91:36604'
distributed.nanny - INFO -         Start Nanny at: 'tcp://172.30.10.91:35316'
distributed.nanny - INFO -         Start Nanny at: 'tcp://172.30.10.91:37537'
distributed.nanny - INFO -         Start Nanny at: 'tcp://172.30.10.91:42420'
distributed.nanny - INFO -         Start Nanny at: 'tcp://172.30.10.91:46362'
distributed.nanny - INFO -         Start Nanny at: 'tcp://172.30.10.91:34318'
distributed.nanny - INFO -         Start Nanny at: 'tcp://172.30.10.91:41919'
distributed.nanny - INFO -         Start Nanny at: 'tcp://172.30.10.91:39524'
distributed.nanny - INFO -         Start Nanny at: 'tcp://172.30.10.91:39205'
distributed.nanny - INFO -         Start Nanny at: 'tcp://172.30.10.91:35452'
distributed.nanny - INFO -         Start Nanny at: 'tcp://172.30.10.91:35151'
distributed.nanny - INFO -         Start Nanny at: 'tcp://172.30.10.91:46858'
distributed.nanny - INFO -         Start Nanny at: 'tcp://172.30.10.91:36260'
distributed.nanny - INFO -         Start Nanny at: 'tcp://172.30.10.91:43001'
distributed.nanny - INFO -         Start Nanny at: 'tcp://172.30.10.91:38092'
distributed.nanny - INFO -         Start Nanny at: 'tcp://172.30.10.91:37912'
distributed.nanny - INFO -         Start Nanny at: 'tcp://172.30.10.91:42097'
distributed.nanny - INFO -         Start Nanny at: 'tcp://172.30.10.91:35354'
distributed.nanny - INFO -         Start Nanny at: 'tcp://172.30.10.91:43741'
distributed.nanny - INFO -         Start Nanny at: 'tcp://172.30.10.91:44800'
distributed.nanny - INFO -         Start Nanny at: 'tcp://172.30.10.91:43474'
distributed.nanny - INFO -         Start Nanny at: 'tcp://172.30.10.91:44084'
/scratch/cnt0024/hmg2840/albert7a/anaconda3/lib/python3.7/site-packages/distributed/utils.py:136: RuntimeWarning: Couldn't detect a suitable IP address for reaching '8.8.8.8', defaulting to '127.0.0.1': [Errno 101] Network is unreachable
  RuntimeWarning,
distributed.worker - INFO -       Start worker at:   tcp://172.30.10.91:34282
/scratch/cnt0024/hmg2840/albert7a/anaconda3/lib/python3.7/site-packages/distributed/utils.py:136: RuntimeWarning: Couldn't detect a suitable IP address for reaching '8.8.8.8', defaulting to '127.0.0.1': [Errno 101] Network is unreachable
  RuntimeWarning,
distributed.worker - INFO -       Start worker at:   tcp://172.30.10.91:33655
/scratch/cnt0024/hmg2840/albert7a/anaconda3/lib/python3.7/site-packages/distributed/utils.py:136: RuntimeWarning: Couldn't detect a suitable IP address for reaching '8.8.8.8', defaulting to '127.0.0.1': [Errno 101] Network is unreachable
  RuntimeWarning,
distributed.worker - INFO -       Start worker at:   tcp://172.30.10.91:38597
/scratch/cnt0024/hmg2840/albert7a/anaconda3/lib/python3.7/site-packages/distributed/utils.py:136: RuntimeWarning: Couldn't detect a suitable IP address for reaching '8.8.8.8', defaulting to '127.0.0.1': [Errno 101] Network is unreachable
  RuntimeWarning,
distributed.worker - INFO -       Start worker at:   tcp://172.30.10.91:38074
/scratch/cnt0024/hmg2840/albert7a/anaconda3/lib/python3.7/site-packages/distributed/utils.py:136: RuntimeWarning: Couldn't detect a suitable IP address for reaching '8.8.8.8', defaulting to '127.0.0.1': [Errno 101] Network is unreachable
  RuntimeWarning,
distributed.worker - INFO -       Start worker at:   tcp://172.30.10.91:35993
/scratch/cnt0024/hmg2840/albert7a/anaconda3/lib/python3.7/site-packages/distributed/utils.py:136: RuntimeWarning: Couldn't detect a suitable IP address for reaching '8.8.8.8', defaulting to '127.0.0.1': [Errno 101] Network is unreachable
  RuntimeWarning,
distributed.worker - INFO -       Start worker at:   tcp://172.30.10.91:46221
/scratch/cnt0024/hmg2840/albert7a/anaconda3/lib/python3.7/site-packages/distributed/utils.py:136: RuntimeWarning: Couldn't detect a suitable IP address for reaching '8.8.8.8', defaulting to '127.0.0.1': [Errno 101] Network is unreachable
  RuntimeWarning,
distributed.worker - INFO -       Start worker at:   tcp://172.30.10.91:46723
/scratch/cnt0024/hmg2840/albert7a/anaconda3/lib/python3.7/site-packages/distributed/utils.py:136: RuntimeWarning: Couldn't detect a suitable IP address for reaching '8.8.8.8', defaulting to '127.0.0.1': [Errno 101] Network is unreachable
  RuntimeWarning,
distributed.worker - INFO -       Start worker at:   tcp://172.30.10.91:43698
/scratch/cnt0024/hmg2840/albert7a/anaconda3/lib/python3.7/site-packages/distributed/utils.py:136: RuntimeWarning: Couldn't detect a suitable IP address for reaching '8.8.8.8', defaulting to '127.0.0.1': [Errno 101] Network is unreachable
  RuntimeWarning,
distributed.worker - INFO -       Start worker at:   tcp://172.30.10.91:39318
distributed.worker - INFO -          Listening to:   tcp://172.30.10.91:34282
distributed.worker - INFO -          Listening to:   tcp://172.30.10.91:33655
distributed.worker - INFO -          Listening to:   tcp://172.30.10.91:38597
/scratch/cnt0024/hmg2840/albert7a/anaconda3/lib/python3.7/site-packages/distributed/utils.py:136: RuntimeWarning: Couldn't detect a suitable IP address for reaching '8.8.8.8', defaulting to '127.0.0.1': [Errno 101] Network is unreachable
  RuntimeWarning,
distributed.worker - INFO -       Start worker at:   tcp://172.30.10.91:39571
distributed.worker - INFO -          Listening to:   tcp://172.30.10.91:38074
distributed.worker - INFO -          Listening to:   tcp://172.30.10.91:35993
distributed.worker - INFO -          Listening to:   tcp://172.30.10.91:43698
distributed.worker - INFO -          Listening to:   tcp://172.30.10.91:39318
distributed.worker - INFO -          dashboard at:         172.30.10.91:34168
distributed.worker - INFO -          dashboard at:         172.30.10.91:46751
distributed.worker - INFO -          dashboard at:         172.30.10.91:37806
distributed.worker - INFO -          Listening to:   tcp://172.30.10.91:46723
distributed.worker - INFO -          Listening to:   tcp://172.30.10.91:39571
distributed.worker - INFO -          dashboard at:         172.30.10.91:39928
distributed.worker - INFO -          dashboard at:         172.30.10.91:46218
/scratch/cnt0024/hmg2840/albert7a/anaconda3/lib/python3.7/site-packages/distributed/utils.py:136: RuntimeWarning: Couldn't detect a suitable IP address for reaching '8.8.8.8', defaulting to '127.0.0.1': [Errno 101] Network is unreachable
  RuntimeWarning,
distributed.worker - INFO -       Start worker at:   tcp://172.30.10.91:43708
distributed.worker - INFO -          dashboard at:         172.30.10.91:40190
distributed.worker - INFO - Waiting to connect to:   tcp://172.30.100.5:35587
distributed.worker - INFO - Waiting to connect to:   tcp://172.30.100.5:35587
distributed.worker - INFO -          dashboard at:         172.30.10.91:40755
distributed.worker - INFO - Waiting to connect to:   tcp://172.30.100.5:35587
distributed.worker - INFO -          Listening to:   tcp://172.30.10.91:46221
distributed.worker - INFO - Waiting to connect to:   tcp://172.30.100.5:35587
distributed.worker - INFO -          dashboard at:         172.30.10.91:46151
distributed.worker - INFO - Waiting to connect to:   tcp://172.30.100.5:35587
distributed.worker - INFO -          dashboard at:         172.30.10.91:46565
distributed.worker - INFO - Waiting to connect to:   tcp://172.30.100.5:35587
/scratch/cnt0024/hmg2840/albert7a/anaconda3/lib/python3.7/site-packages/distributed/utils.py:136: RuntimeWarning: Couldn't detect a suitable IP address for reaching '8.8.8.8', defaulting to '127.0.0.1': [Errno 101] Network is unreachable
  RuntimeWarning,
distributed.worker - INFO -       Start worker at:   tcp://172.30.10.91:40156
/scratch/cnt0024/hmg2840/albert7a/anaconda3/lib/python3.7/site-packages/distributed/utils.py:136: RuntimeWarning: Couldn't detect a suitable IP address for reaching '8.8.8.8', defaulting to '127.0.0.1': [Errno 101] Network is unreachable
  RuntimeWarning,
distributed.worker - INFO -       Start worker at:   tcp://172.30.10.91:34989
distributed.worker - INFO - -------------------------------------------------
/scratch/cnt0024/hmg2840/albert7a/anaconda3/lib/python3.7/site-packages/distributed/utils.py:136: RuntimeWarning: Couldn't detect a suitable IP address for reaching '8.8.8.8', defaulting to '127.0.0.1': [Errno 101] Network is unreachable
  RuntimeWarning,
distributed.worker - INFO -       Start worker at:   tcp://172.30.10.91:43613
distributed.worker - INFO - -------------------------------------------------
distributed.worker - INFO -          Listening to:   tcp://172.30.10.91:43708
distributed.worker - INFO - -------------------------------------------------
/scratch/cnt0024/hmg2840/albert7a/anaconda3/lib/python3.7/site-packages/distributed/utils.py:136: RuntimeWarning: Couldn't detect a suitable IP address for reaching '8.8.8.8', defaulting to '127.0.0.1': [Errno 101] Network is unreachable
  RuntimeWarning,
distributed.worker - INFO -       Start worker at:   tcp://172.30.10.91:34406
/scratch/cnt0024/hmg2840/albert7a/anaconda3/lib/python3.7/site-packages/distributed/utils.py:136: RuntimeWarning: Couldn't detect a suitable IP address for reaching '8.8.8.8', defaulting to '127.0.0.1': [Errno 101] Network is unreachable
  RuntimeWarning,
distributed.worker - INFO -       Start worker at:   tcp://172.30.10.91:44359
distributed.worker - INFO - Waiting to connect to:   tcp://172.30.100.5:35587
distributed.worker - INFO - -------------------------------------------------
distributed.worker - INFO - -------------------------------------------------
distributed.worker - INFO - Waiting to connect to:   tcp://172.30.100.5:35587
/scratch/cnt0024/hmg2840/albert7a/anaconda3/lib/python3.7/site-packages/distributed/utils.py:136: RuntimeWarning: Couldn't detect a suitable IP address for reaching '8.8.8.8', defaulting to '127.0.0.1': [Errno 101] Network is unreachable
  RuntimeWarning,
distributed.worker - INFO -       Start worker at:   tcp://172.30.10.91:45278
/scratch/cnt0024/hmg2840/albert7a/anaconda3/lib/python3.7/site-packages/distributed/utils.py:136: RuntimeWarning: Couldn't detect a suitable IP address for reaching '8.8.8.8', defaulting to '127.0.0.1': [Errno 101] Network is unreachable
  RuntimeWarning,
distributed.worker - INFO -       Start worker at:   tcp://172.30.10.91:44250
distributed.worker - INFO - Waiting to connect to:   tcp://172.30.100.5:35587
distributed.worker - INFO - -------------------------------------------------
/scratch/cnt0024/hmg2840/albert7a/anaconda3/lib/python3.7/site-packages/distributed/utils.py:136: RuntimeWarning: Couldn't detect a suitable IP address for reaching '8.8.8.8', defaulting to '127.0.0.1': [Errno 101] Network is unreachable
  RuntimeWarning,
distributed.worker - INFO -       Start worker at:   tcp://172.30.10.91:45645
distributed.worker - INFO -          dashboard at:         172.30.10.91:39751
distributed.worker - INFO -          Listening to:   tcp://172.30.10.91:34989
distributed.worker - INFO -          Listening to:   tcp://172.30.10.91:40156
/scratch/cnt0024/hmg2840/albert7a/anaconda3/lib/python3.7/site-packages/distributed/utils.py:136: RuntimeWarning: Couldn't detect a suitable IP address for reaching '8.8.8.8', defaulting to '127.0.0.1': [Errno 101] Network is unreachable
  RuntimeWarning,
distributed.worker - INFO -       Start worker at:   tcp://172.30.10.91:45493
distributed.worker - INFO -          Listening to:   tcp://172.30.10.91:43613
distributed.worker - INFO -               Threads:                          1
distributed.worker - INFO -               Threads:                          1
distributed.worker - INFO -          dashboard at:         172.30.10.91:33633
distributed.worker - INFO - -------------------------------------------------
distributed.worker - INFO -               Threads:                          1
distributed.worker - INFO -          Listening to:   tcp://172.30.10.91:44359
distributed.worker - INFO -          Listening to:   tcp://172.30.10.91:34406
distributed.worker - INFO - -------------------------------------------------
distributed.worker - INFO - -------------------------------------------------
distributed.worker - INFO -               Threads:                          1
distributed.worker - INFO -          Listening to:   tcp://172.30.10.91:44250
distributed.worker - INFO -          Listening to:   tcp://172.30.10.91:45278
distributed.worker - INFO -               Threads:                          1
distributed.worker - INFO -               Threads:                          1
distributed.worker - INFO -          Listening to:   tcp://172.30.10.91:45645
distributed.worker - INFO -          dashboard at:         172.30.10.91:42055
distributed.worker - INFO -          dashboard at:         172.30.10.91:43073
distributed.worker - INFO -          Listening to:   tcp://172.30.10.91:45493
distributed.worker - INFO -                Memory:                    4.29 GB
distributed.worker - INFO -          dashboard at:         172.30.10.91:34242
distributed.worker - INFO -                Memory:                    4.29 GB
distributed.worker - INFO - Waiting to connect to:   tcp://172.30.100.5:35587
distributed.worker - INFO -                Memory:                    4.29 GB
distributed.worker - INFO -          dashboard at:         172.30.10.91:41796
distributed.worker - INFO -          dashboard at:         172.30.10.91:37572
distributed.worker - INFO -                Memory:                    4.29 GB
distributed.worker - INFO -                Memory:                    4.29 GB
distributed.worker - INFO -                Memory:                    4.29 GB
distributed.worker - INFO -          dashboard at:         172.30.10.91:42936
distributed.worker - INFO -          dashboard at:         172.30.10.91:46425
distributed.worker - INFO -               Threads:                          1
distributed.worker - INFO -               Threads:                          1
distributed.worker - INFO -       Local Directory: /scratch/cnt0024/hmg2840/albert7a/worker-xy4115wd
distributed.worker - INFO - Waiting to connect to:   tcp://172.30.100.5:35587
distributed.worker - INFO - Waiting to connect to:   tcp://172.30.100.5:35587
distributed.worker - INFO - Waiting to connect to:   tcp://172.30.100.5:35587
distributed.worker - INFO -          dashboard at:         172.30.10.91:44790
distributed.worker - INFO -       Local Directory: /scratch/cnt0024/hmg2840/albert7a/worker-fd8_w0on
distributed.worker - INFO - -------------------------------------------------
distributed.worker - INFO -          dashboard at:         172.30.10.91:39065
distributed.worker - INFO -       Local Directory: /scratch/cnt0024/hmg2840/albert7a/worker-g91dq5pp
distributed.worker - INFO - Waiting to connect to:   tcp://172.30.100.5:35587
distributed.worker - INFO -       Local Directory: /scratch/cnt0024/hmg2840/albert7a/worker-pfw4skm7
distributed.worker - INFO -       Local Directory: /scratch/cnt0024/hmg2840/albert7a/worker-s6hciju8
distributed.worker - INFO -       Local Directory: /scratch/cnt0024/hmg2840/albert7a/worker-t44vpzfm
distributed.worker - INFO - Waiting to connect to:   tcp://172.30.100.5:35587
distributed.worker - INFO - Waiting to connect to:   tcp://172.30.100.5:35587
distributed.worker - INFO - Waiting to connect to:   tcp://172.30.100.5:35587
distributed.worker - INFO - Waiting to connect to:   tcp://172.30.100.5:35587
distributed.worker - INFO -                Memory:                    4.29 GB
distributed.worker - INFO - -------------------------------------------------
distributed.worker - INFO - -------------------------------------------------
distributed.worker - INFO -               Threads:                          1
distributed.worker - INFO - -------------------------------------------------
distributed.worker - INFO - Waiting to connect to:   tcp://172.30.100.5:35587
distributed.worker - INFO - Waiting to connect to:   tcp://172.30.100.5:35587
distributed.worker - INFO - -------------------------------------------------
distributed.worker - INFO -               Threads:                          1
distributed.worker - INFO - -------------------------------------------------
distributed.worker - INFO - -------------------------------------------------
distributed.worker - INFO - -------------------------------------------------
distributed.worker - INFO -       Local Directory: /scratch/cnt0024/hmg2840/albert7a/worker-bl7ath9l
distributed.worker - INFO - -------------------------------------------------
distributed.worker - INFO - -------------------------------------------------
distributed.worker - INFO - -------------------------------------------------
distributed.worker - INFO -                Memory:                    4.29 GB
distributed.worker - INFO -                Memory:                    4.29 GB
distributed.worker - INFO - -------------------------------------------------
/scratch/cnt0024/hmg2840/albert7a/anaconda3/lib/python3.7/site-packages/distributed/utils.py:136: RuntimeWarning: Couldn't detect a suitable IP address for reaching '8.8.8.8', defaulting to '127.0.0.1': [Errno 101] Network is unreachable
  RuntimeWarning,
distributed.worker - INFO -       Start worker at:   tcp://172.30.10.91:34988
distributed.worker - INFO - -------------------------------------------------
distributed.worker - INFO - -------------------------------------------------
distributed.worker - INFO - -------------------------------------------------
distributed.worker - INFO -                Memory:                    4.29 GB
distributed.worker - INFO - -------------------------------------------------
distributed.worker - INFO - -------------------------------------------------
/scratch/cnt0024/hmg2840/albert7a/anaconda3/lib/python3.7/site-packages/distributed/utils.py:136: RuntimeWarning: Couldn't detect a suitable IP address for reaching '8.8.8.8', defaulting to '127.0.0.1': [Errno 101] Network is unreachable
  RuntimeWarning,
distributed.worker - INFO -       Start worker at:   tcp://172.30.10.91:39423
distributed.worker - INFO -               Threads:                          1
distributed.worker - INFO -               Threads:                          1
distributed.worker - INFO -       Local Directory: /scratch/cnt0024/hmg2840/albert7a/worker-stwn6qon
distributed.worker - INFO -               Threads:                          1
distributed.worker - INFO -       Local Directory: /scratch/cnt0024/hmg2840/albert7a/worker-um9ityge
distributed.worker - INFO -               Threads:                          1
distributed.worker - INFO -               Threads:                          1
distributed.worker - INFO -               Threads:                          1
distributed.worker - INFO - -------------------------------------------------
distributed.worker - INFO -               Threads:                          1
distributed.worker - INFO -               Threads:                          1
distributed.worker - INFO -       Local Directory: /scratch/cnt0024/hmg2840/albert7a/worker-cl_nvgd2
distributed.worker - INFO -                Memory:                    4.29 GB
distributed.worker - INFO -                Memory:                    4.29 GB
distributed.worker - INFO -               Threads:                          1
distributed.worker - INFO -                Memory:                    4.29 GB
distributed.worker - INFO -                Memory:                    4.29 GB
distributed.worker - INFO -               Threads:                          1
distributed.worker - INFO -                Memory:                    4.29 GB
distributed.worker - INFO -                Memory:                    4.29 GB
/scratch/cnt0024/hmg2840/albert7a/anaconda3/lib/python3.7/site-packages/distributed/utils.py:136: RuntimeWarning: Couldn't detect a suitable IP address for reaching '8.8.8.8', defaulting to '127.0.0.1': [Errno 101] Network is unreachable
  RuntimeWarning,
distributed.worker - INFO -       Start worker at:   tcp://172.30.10.91:45833
distributed.worker - INFO -                Memory:                    4.29 GB
distributed.worker - INFO -                Memory:                    4.29 GB
distributed.worker - INFO - -------------------------------------------------
distributed.worker - INFO -       Local Directory: /scratch/cnt0024/hmg2840/albert7a/worker-aej2104l
distributed.worker - INFO -       Local Directory: /scratch/cnt0024/hmg2840/albert7a/worker-b9fe02gn
distributed.worker - INFO - -------------------------------------------------
distributed.worker - INFO -                Memory:                    4.29 GB
distributed.worker - INFO -       Local Directory: /scratch/cnt0024/hmg2840/albert7a/worker-nd6rnn9e
distributed.worker - INFO -       Local Directory: /scratch/cnt0024/hmg2840/albert7a/worker-a7qc952o
distributed.worker - INFO -                Memory:                    4.29 GB
distributed.worker - INFO -       Local Directory: /scratch/cnt0024/hmg2840/albert7a/worker-7wdy6ng5
distributed.worker - INFO -       Local Directory: /scratch/cnt0024/hmg2840/albert7a/worker-pug59_g9
distributed.worker - INFO -          Listening to:   tcp://172.30.10.91:34988
distributed.worker - INFO -          Listening to:   tcp://172.30.10.91:45833
distributed.worker - INFO -       Local Directory: /scratch/cnt0024/hmg2840/albert7a/worker-ys_e6yo7
distributed.worker - INFO -       Local Directory: /scratch/cnt0024/hmg2840/albert7a/worker-2mr_915j
distributed.worker - INFO -       Local Directory: /scratch/cnt0024/hmg2840/albert7a/worker-bxtfxs4n
distributed.worker - INFO -          Listening to:   tcp://172.30.10.91:39423
distributed.worker - INFO - -------------------------------------------------
distributed.worker - INFO -       Local Directory: /scratch/cnt0024/hmg2840/albert7a/worker-grboto_7
distributed.worker - INFO -          dashboard at:         172.30.10.91:43004
distributed.worker - INFO -          dashboard at:         172.30.10.91:43802
distributed.worker - INFO - -------------------------------------------------
distributed.worker - INFO - -------------------------------------------------
distributed.worker - INFO -          dashboard at:         172.30.10.91:33242
distributed.worker - INFO - -------------------------------------------------
distributed.worker - INFO - -------------------------------------------------
distributed.worker - INFO - Waiting to connect to:   tcp://172.30.100.5:35587
distributed.worker - INFO - Waiting to connect to:   tcp://172.30.100.5:35587
distributed.worker - INFO - -------------------------------------------------
distributed.worker - INFO - -------------------------------------------------
distributed.worker - INFO - -------------------------------------------------
distributed.worker - INFO - Waiting to connect to:   tcp://172.30.100.5:35587
distributed.worker - INFO - -------------------------------------------------
distributed.worker - INFO - -------------------------------------------------
distributed.worker - INFO - -------------------------------------------------
distributed.worker - INFO - -------------------------------------------------
distributed.worker - INFO - -------------------------------------------------
distributed.worker - INFO - -------------------------------------------------
distributed.worker - INFO -               Threads:                          1
/scratch/cnt0024/hmg2840/albert7a/anaconda3/lib/python3.7/site-packages/distributed/utils.py:136: RuntimeWarning: Couldn't detect a suitable IP address for reaching '8.8.8.8', defaulting to '127.0.0.1': [Errno 101] Network is unreachable
  RuntimeWarning,
distributed.worker - INFO -       Start worker at:   tcp://172.30.10.91:34817
distributed.worker - INFO -               Threads:                          1
distributed.worker - INFO -               Threads:                          1
distributed.worker - INFO -          Listening to:   tcp://172.30.10.91:34817
distributed.worker - INFO -                Memory:                    4.29 GB
/scratch/cnt0024/hmg2840/albert7a/anaconda3/lib/python3.7/site-packages/distributed/utils.py:136: RuntimeWarning: Couldn't detect a suitable IP address for reaching '8.8.8.8', defaulting to '127.0.0.1': [Errno 101] Network is unreachable
  RuntimeWarning,
distributed.worker - INFO -       Start worker at:   tcp://172.30.10.91:37396
distributed.worker - INFO -          dashboard at:         172.30.10.91:36349
distributed.worker - INFO -                Memory:                    4.29 GB
distributed.worker - INFO -       Local Directory: /scratch/cnt0024/hmg2840/albert7a/worker-kyz6qo84
distributed.worker - INFO -          Listening to:   tcp://172.30.10.91:37396
distributed.worker - INFO -                Memory:                    4.29 GB
distributed.worker - INFO - Waiting to connect to:   tcp://172.30.100.5:35587
distributed.worker - INFO -       Local Directory: /scratch/cnt0024/hmg2840/albert7a/worker-qtgyc09o
distributed.worker - INFO - -------------------------------------------------
distributed.worker - INFO -          dashboard at:         172.30.10.91:44857
distributed.worker - INFO -               Threads:                          1
distributed.worker - INFO -       Local Directory: /scratch/cnt0024/hmg2840/albert7a/worker-g7ynp5qs
distributed.worker - INFO - -------------------------------------------------
distributed.worker - INFO -                Memory:                    4.29 GB
distributed.worker - INFO - Waiting to connect to:   tcp://172.30.100.5:35587
/scratch/cnt0024/hmg2840/albert7a/anaconda3/lib/python3.7/site-packages/distributed/utils.py:136: RuntimeWarning: Couldn't detect a suitable IP address for reaching '8.8.8.8', defaulting to '127.0.0.1': [Errno 101] Network is unreachable
  RuntimeWarning,
distributed.worker - INFO -       Start worker at:   tcp://172.30.10.91:39945
distributed.worker - INFO - -------------------------------------------------
distributed.worker - INFO - -------------------------------------------------
/scratch/cnt0024/hmg2840/albert7a/anaconda3/lib/python3.7/site-packages/distributed/utils.py:136: RuntimeWarning: Couldn't detect a suitable IP address for reaching '8.8.8.8', defaulting to '127.0.0.1': [Errno 101] Network is unreachable
  RuntimeWarning,
distributed.worker - INFO -       Start worker at:   tcp://172.30.10.91:41834
distributed.worker - INFO -       Local Directory: /scratch/cnt0024/hmg2840/albert7a/worker-__qk_b54
distributed.worker - INFO - -------------------------------------------------
distributed.worker - INFO -          Listening to:   tcp://172.30.10.91:39945
distributed.worker - INFO -          Listening to:   tcp://172.30.10.91:41834
distributed.worker - INFO -          dashboard at:         172.30.10.91:41393
distributed.worker - INFO -               Threads:                          1
distributed.worker - INFO -          dashboard at:         172.30.10.91:45790
distributed.worker - INFO - Waiting to connect to:   tcp://172.30.100.5:35587
distributed.worker - INFO - Waiting to connect to:   tcp://172.30.100.5:35587
distributed.worker - INFO - -------------------------------------------------
distributed.worker - INFO -                Memory:                    4.29 GB
distributed.worker - INFO - -------------------------------------------------
distributed.worker - INFO -       Local Directory: /scratch/cnt0024/hmg2840/albert7a/worker-p8yllmug
distributed.worker - INFO - -------------------------------------------------
distributed.worker - INFO -               Threads:                          1
distributed.worker - INFO - -------------------------------------------------
distributed.worker - INFO -                Memory:                    4.29 GB
distributed.worker - INFO -               Threads:                          1
distributed.worker - INFO -       Local Directory: /scratch/cnt0024/hmg2840/albert7a/worker-k7o01ode
distributed.worker - INFO -                Memory:                    4.29 GB
distributed.worker - INFO -       Local Directory: /scratch/cnt0024/hmg2840/albert7a/worker-d2gmd363
distributed.worker - INFO - -------------------------------------------------
distributed.worker - INFO - -------------------------------------------------
/scratch/cnt0024/hmg2840/albert7a/anaconda3/lib/python3.7/site-packages/distributed/utils.py:136: RuntimeWarning: Couldn't detect a suitable IP address for reaching '8.8.8.8', defaulting to '127.0.0.1': [Errno 101] Network is unreachable
  RuntimeWarning,
distributed.worker - INFO -       Start worker at:   tcp://172.30.10.91:38909
distributed.worker - INFO -          Listening to:   tcp://172.30.10.91:38909
distributed.worker - INFO -          dashboard at:         172.30.10.91:32992
distributed.worker - INFO - Waiting to connect to:   tcp://172.30.100.5:35587
distributed.worker - INFO - -------------------------------------------------
distributed.worker - INFO -               Threads:                          1
distributed.worker - INFO -                Memory:                    4.29 GB
distributed.worker - INFO -       Local Directory: /scratch/cnt0024/hmg2840/albert7a/worker-czwo59qd
distributed.worker - INFO - -------------------------------------------------
distributed.worker - INFO - Waiting to connect to:   tcp://172.30.100.5:35587
distributed.worker - INFO - Waiting to connect to:   tcp://172.30.100.5:35587
distributed.worker - INFO - Waiting to connect to:   tcp://172.30.100.5:35587
distributed.worker - INFO - Waiting to connect to:   tcp://172.30.100.5:35587
distributed.worker - INFO - Waiting to connect to:   tcp://172.30.100.5:35587
distributed.worker - INFO - Waiting to connect to:   tcp://172.30.100.5:35587
distributed.worker - INFO - Waiting to connect to:   tcp://172.30.100.5:35587
distributed.worker - INFO - Waiting to connect to:   tcp://172.30.100.5:35587
distributed.worker - INFO - Waiting to connect to:   tcp://172.30.100.5:35587
distributed.worker - INFO - Waiting to connect to:   tcp://172.30.100.5:35587
distributed.worker - INFO - Waiting to connect to:   tcp://172.30.100.5:35587
distributed.worker - INFO - Waiting to connect to:   tcp://172.30.100.5:35587
distributed.worker - INFO - Waiting to connect to:   tcp://172.30.100.5:35587
distributed.worker - INFO - Waiting to connect to:   tcp://172.30.100.5:35587
distributed.worker - INFO - Waiting to connect to:   tcp://172.30.100.5:35587
distributed.worker - INFO - Waiting to connect to:   tcp://172.30.100.5:35587
distributed.worker - INFO - Waiting to connect to:   tcp://172.30.100.5:35587
distributed.worker - INFO - Waiting to connect to:   tcp://172.30.100.5:35587
distributed.worker - INFO - Waiting to connect to:   tcp://172.30.100.5:35587
distributed.worker - INFO - Waiting to connect to:   tcp://172.30.100.5:35587
distributed.worker - INFO - Waiting to connect to:   tcp://172.30.100.5:35587
distributed.worker - INFO - Waiting to connect to:   tcp://172.30.100.5:35587
distributed.worker - INFO - Waiting to connect to:   tcp://172.30.100.5:35587
distributed.worker - INFO - Waiting to connect to:   tcp://172.30.100.5:35587
distributed.worker - INFO - Waiting to connect to:   tcp://172.30.100.5:35587
distributed.worker - INFO - Waiting to connect to:   tcp://172.30.100.5:35587
distributed.worker - INFO - Waiting to connect to:   tcp://172.30.100.5:35587
distributed.worker - INFO - Waiting to connect to:   tcp://172.30.100.5:35587
distributed.worker - INFO - Waiting to connect to:   tcp://172.30.100.5:35587
distributed.worker - INFO - Waiting to connect to:   tcp://172.30.100.5:35587
distributed.worker - INFO - Waiting to connect to:   tcp://172.30.100.5:35587
distributed.worker - INFO - Waiting to connect to:   tcp://172.30.100.5:35587
distributed.worker - INFO - Waiting to connect to:   tcp://172.30.100.5:35587
distributed.worker - INFO - Waiting to connect to:   tcp://172.30.100.5:35587
distributed.worker - INFO - Waiting to connect to:   tcp://172.30.100.5:35587
distributed.worker - INFO - Waiting to connect to:   tcp://172.30.100.5:35587
distributed.worker - INFO - Waiting to connect to:   tcp://172.30.100.5:35587
distributed.worker - INFO - Waiting to connect to:   tcp://172.30.100.5:35587
distributed.worker - INFO - Waiting to connect to:   tcp://172.30.100.5:35587
distributed.worker - INFO - Waiting to connect to:   tcp://172.30.100.5:35587
distributed.worker - INFO - Waiting to connect to:   tcp://172.30.100.5:35587
distributed.worker - INFO - Waiting to connect to:   tcp://172.30.100.5:35587
distributed.worker - INFO - Waiting to connect to:   tcp://172.30.100.5:35587
distributed.worker - INFO - Waiting to connect to:   tcp://172.30.100.5:35587
distributed.worker - INFO - Waiting to connect to:   tcp://172.30.100.5:35587
distributed.worker - INFO - Waiting to connect to:   tcp://172.30.100.5:35587
distributed.worker - INFO - Waiting to connect to:   tcp://172.30.100.5:35587
distributed.worker - INFO - Waiting to connect to:   tcp://172.30.100.5:35587
distributed.worker - INFO - Waiting to connect to:   tcp://172.30.100.5:35587
distributed.worker - INFO - Waiting to connect to:   tcp://172.30.100.5:35587
distributed.worker - INFO - Waiting to connect to:   tcp://172.30.100.5:35587
distributed.worker - INFO - Waiting to connect to:   tcp://172.30.100.5:35587
distributed.worker - INFO - Waiting to connect to:   tcp://172.30.100.5:35587
distributed.worker - INFO - Waiting to connect to:   tcp://172.30.100.5:35587
distributed.worker - INFO - Waiting to connect to:   tcp://172.30.100.5:35587
distributed.worker - INFO - Waiting to connect to:   tcp://172.30.100.5:35587
distributed.nanny - INFO - Closing Nanny at 'tcp://172.30.10.91:42863'
distributed.worker - INFO - Stopping worker at tcp://172.30.10.91:44359
distributed.nanny - INFO - Closing Nanny at 'tcp://172.30.10.91:36123'
distributed.worker - INFO - Stopping worker at tcp://172.30.10.91:39318
distributed.nanny - INFO - Closing Nanny at 'tcp://172.30.10.91:41186'
distributed.worker - INFO - Stopping worker at tcp://172.30.10.91:43698
distributed.nanny - INFO - Closing Nanny at 'tcp://172.30.10.91:45712'
distributed.worker - INFO - Stopping worker at tcp://172.30.10.91:34282
distributed.nanny - INFO - Closing Nanny at 'tcp://172.30.10.91:46091'
distributed.worker - INFO - Stopping worker at tcp://172.30.10.91:39945
distributed.nanny - INFO - Closing Nanny at 'tcp://172.30.10.91:39577'
distributed.worker - INFO - Stopping worker at tcp://172.30.10.91:34988
distributed.nanny - INFO - Closing Nanny at 'tcp://172.30.10.91:36604'
distributed.worker - INFO - Stopping worker at tcp://172.30.10.91:34406
distributed.nanny - INFO - Closing Nanny at 'tcp://172.30.10.91:35316'
distributed.worker - INFO - Stopping worker at tcp://172.30.10.91:43708
distributed.nanny - INFO - Closing Nanny at 'tcp://172.30.10.91:37537'
distributed.nanny - INFO - Closing Nanny at 'tcp://172.30.10.91:42420'
distributed.worker - INFO - Stopping worker at tcp://172.30.10.91:41834
distributed.worker - INFO - Stopping worker at tcp://172.30.10.91:45493
distributed.nanny - INFO - Closing Nanny at 'tcp://172.30.10.91:46362'
distributed.nanny - INFO - Closing Nanny at 'tcp://172.30.10.91:34318'
distributed.worker - INFO - Stopping worker at tcp://172.30.10.91:40156
distributed.worker - INFO - Stopping worker at tcp://172.30.10.91:38909
distributed.nanny - INFO - Closing Nanny at 'tcp://172.30.10.91:41919'
distributed.worker - INFO - Stopping worker at tcp://172.30.10.91:44250
distributed.nanny - INFO - Closing Nanny at 'tcp://172.30.10.91:39524'
distributed.worker - INFO - Stopping worker at tcp://172.30.10.91:45278
distributed.nanny - INFO - Closing Nanny at 'tcp://172.30.10.91:39205'
distributed.worker - INFO - Stopping worker at tcp://172.30.10.91:38074
distributed.nanny - INFO - Closing Nanny at 'tcp://172.30.10.91:35452'
distributed.worker - INFO - Stopping worker at tcp://172.30.10.91:46723
distributed.nanny - ERROR - Timed out connecting Nanny '<Nanny: None, threads: 1>' to scheduler 'tcp://172.30.100.5:35587'
Traceback (most recent call last):
  File "/scratch/cnt0024/hmg2840/albert7a/anaconda3/lib/python3.7/site-packages/distributed/nanny.py", line 303, in instantiate
    timedelta(seconds=self.death_timeout), self.process.start()
  File "/scratch/cnt0024/hmg2840/albert7a/anaconda3/lib/python3.7/site-packages/tornado/gen.py", line 729, in run
    value = future.result()
tornado.util.TimeoutError: Timeout
distributed.nanny - ERROR - Timed out connecting Nanny '<Nanny: None, threads: 1>' to scheduler 'tcp://172.30.100.5:35587'
Traceback (most recent call last):
  File "/scratch/cnt0024/hmg2840/albert7a/anaconda3/lib/python3.7/site-packages/distributed/nanny.py", line 303, in instantiate
    timedelta(seconds=self.death_timeout), self.process.start()
  File "/scratch/cnt0024/hmg2840/albert7a/anaconda3/lib/python3.7/site-packages/tornado/gen.py", line 729, in run
    value = future.result()
tornado.util.TimeoutError: Timeout
distributed.nanny - ERROR - Timed out connecting Nanny '<Nanny: None, threads: 1>' to scheduler 'tcp://172.30.100.5:35587'
Traceback (most recent call last):
  File "/scratch/cnt0024/hmg2840/albert7a/anaconda3/lib/python3.7/site-packages/distributed/nanny.py", line 303, in instantiate
    timedelta(seconds=self.death_timeout), self.process.start()
  File "/scratch/cnt0024/hmg2840/albert7a/anaconda3/lib/python3.7/site-packages/tornado/gen.py", line 729, in run
    value = future.result()
tornado.util.TimeoutError: Timeout
distributed.nanny - ERROR - Timed out connecting Nanny '<Nanny: None, threads: 1>' to scheduler 'tcp://172.30.100.5:35587'
Traceback (most recent call last):
  File "/scratch/cnt0024/hmg2840/albert7a/anaconda3/lib/python3.7/site-packages/distributed/nanny.py", line 303, in instantiate
    timedelta(seconds=self.death_timeout), self.process.start()
  File "/scratch/cnt0024/hmg2840/albert7a/anaconda3/lib/python3.7/site-packages/tornado/gen.py", line 729, in run
    value = future.result()
tornado.util.TimeoutError: Timeout
distributed.nanny - ERROR - Timed out connecting Nanny '<Nanny: None, threads: 1>' to scheduler 'tcp://172.30.100.5:35587'
Traceback (most recent call last):
  File "/scratch/cnt0024/hmg2840/albert7a/anaconda3/lib/python3.7/site-packages/distributed/nanny.py", line 303, in instantiate
    timedelta(seconds=self.death_timeout), self.process.start()
  File "/scratch/cnt0024/hmg2840/albert7a/anaconda3/lib/python3.7/site-packages/tornado/gen.py", line 729, in run
    value = future.result()
tornado.util.TimeoutError: Timeout
distributed.nanny - ERROR - Timed out connecting Nanny '<Nanny: None, threads: 1>' to scheduler 'tcp://172.30.100.5:35587'
Traceback (most recent call last):
  File "/scratch/cnt0024/hmg2840/albert7a/anaconda3/lib/python3.7/site-packages/distributed/nanny.py", line 303, in instantiate
    timedelta(seconds=self.death_timeout), self.process.start()
  File "/scratch/cnt0024/hmg2840/albert7a/anaconda3/lib/python3.7/site-packages/tornado/gen.py", line 729, in run
    value = future.result()
tornado.util.TimeoutError: Timeout
distributed.nanny - INFO - Closing Nanny at 'tcp://172.30.10.91:35151'
distributed.worker - INFO - Stopping worker at tcp://172.30.10.91:35993
distributed.nanny - ERROR - Timed out connecting Nanny '<Nanny: None, threads: 1>' to scheduler 'tcp://172.30.100.5:35587'
Traceback (most recent call last):
  File "/scratch/cnt0024/hmg2840/albert7a/anaconda3/lib/python3.7/site-packages/distributed/nanny.py", line 303, in instantiate
    timedelta(seconds=self.death_timeout), self.process.start()
  File "/scratch/cnt0024/hmg2840/albert7a/anaconda3/lib/python3.7/site-packages/tornado/gen.py", line 729, in run
    value = future.result()
tornado.util.TimeoutError: Timeout
distributed.nanny - ERROR - Timed out connecting Nanny '<Nanny: None, threads: 1>' to scheduler 'tcp://172.30.100.5:35587'
Traceback (most recent call last):
  File "/scratch/cnt0024/hmg2840/albert7a/anaconda3/lib/python3.7/site-packages/distributed/nanny.py", line 303, in instantiate
    timedelta(seconds=self.death_timeout), self.process.start()
  File "/scratch/cnt0024/hmg2840/albert7a/anaconda3/lib/python3.7/site-packages/tornado/gen.py", line 729, in run
    value = future.result()
tornado.util.TimeoutError: Timeout
distributed.nanny - INFO - Closing Nanny at 'tcp://172.30.10.91:46858'
distributed.worker - INFO - Stopping worker at tcp://172.30.10.91:34989
distributed.nanny - ERROR - Timed out connecting Nanny '<Nanny: None, threads: 1>' to scheduler 'tcp://172.30.100.5:35587'
Traceback (most recent call last):
  File "/scratch/cnt0024/hmg2840/albert7a/anaconda3/lib/python3.7/site-packages/distributed/nanny.py", line 303, in instantiate
    timedelta(seconds=self.death_timeout), self.process.start()
  File "/scratch/cnt0024/hmg2840/albert7a/anaconda3/lib/python3.7/site-packages/tornado/gen.py", line 729, in run
    value = future.result()
tornado.util.TimeoutError: Timeout
distributed.nanny - ERROR - Timed out connecting Nanny '<Nanny: None, threads: 1>' to scheduler 'tcp://172.30.100.5:35587'
Traceback (most recent call last):
  File "/scratch/cnt0024/hmg2840/albert7a/anaconda3/lib/python3.7/site-packages/distributed/nanny.py", line 303, in instantiate
    timedelta(seconds=self.death_timeout), self.process.start()
  File "/scratch/cnt0024/hmg2840/albert7a/anaconda3/lib/python3.7/site-packages/tornado/gen.py", line 729, in run
    value = future.result()
tornado.util.TimeoutError: Timeout
distributed.nanny - INFO - Closing Nanny at 'tcp://172.30.10.91:36260'
distributed.worker - INFO - Stopping worker at tcp://172.30.10.91:46221
distributed.nanny - ERROR - Timed out connecting Nanny '<Nanny: None, threads: 1>' to scheduler 'tcp://172.30.100.5:35587'
Traceback (most recent call last):
  File "/scratch/cnt0024/hmg2840/albert7a/anaconda3/lib/python3.7/site-packages/distributed/nanny.py", line 303, in instantiate
    timedelta(seconds=self.death_timeout), self.process.start()
  File "/scratch/cnt0024/hmg2840/albert7a/anaconda3/lib/python3.7/site-packages/tornado/gen.py", line 729, in run
    value = future.result()
tornado.util.TimeoutError: Timeout
distributed.nanny - INFO - Closing Nanny at 'tcp://172.30.10.91:43001'
distributed.worker - INFO - Stopping worker at tcp://172.30.10.91:45645
distributed.nanny - ERROR - Timed out connecting Nanny '<Nanny: None, threads: 1>' to scheduler 'tcp://172.30.100.5:35587'
Traceback (most recent call last):
  File "/scratch/cnt0024/hmg2840/albert7a/anaconda3/lib/python3.7/site-packages/distributed/nanny.py", line 303, in instantiate
    timedelta(seconds=self.death_timeout), self.process.start()
  File "/scratch/cnt0024/hmg2840/albert7a/anaconda3/lib/python3.7/site-packages/tornado/gen.py", line 729, in run
    value = future.result()
tornado.util.TimeoutError: Timeout
distributed.nanny - ERROR - Timed out connecting Nanny '<Nanny: None, threads: 1>' to scheduler 'tcp://172.30.100.5:35587'
Traceback (most recent call last):
  File "/scratch/cnt0024/hmg2840/albert7a/anaconda3/lib/python3.7/site-packages/distributed/nanny.py", line 303, in instantiate
    timedelta(seconds=self.death_timeout), self.process.start()
  File "/scratch/cnt0024/hmg2840/albert7a/anaconda3/lib/python3.7/site-packages/tornado/gen.py", line 729, in run
    value = future.result()
tornado.util.TimeoutError: Timeout
distributed.nanny - INFO - Closing Nanny at 'tcp://172.30.10.91:38092'
distributed.worker - INFO - Stopping worker at tcp://172.30.10.91:38597
distributed.nanny - ERROR - Timed out connecting Nanny '<Nanny: None, threads: 1>' to scheduler 'tcp://172.30.100.5:35587'
Traceback (most recent call last):
  File "/scratch/cnt0024/hmg2840/albert7a/anaconda3/lib/python3.7/site-packages/distributed/nanny.py", line 303, in instantiate
    timedelta(seconds=self.death_timeout), self.process.start()
  File "/scratch/cnt0024/hmg2840/albert7a/anaconda3/lib/python3.7/site-packages/tornado/gen.py", line 729, in run
    value = future.result()
tornado.util.TimeoutError: Timeout
distributed.nanny - INFO - Closing Nanny at 'tcp://172.30.10.91:37912'
distributed.worker - INFO - Stopping worker at tcp://172.30.10.91:43613
distributed.nanny - INFO - Closing Nanny at 'tcp://172.30.10.91:42097'
distributed.worker - INFO - Stopping worker at tcp://172.30.10.91:33655
distributed.nanny - INFO - Closing Nanny at 'tcp://172.30.10.91:35354'
distributed.worker - INFO - Stopping worker at tcp://172.30.10.91:45833
distributed.nanny - INFO - Closing Nanny at 'tcp://172.30.10.91:43741'
distributed.nanny - ERROR - Timed out connecting Nanny '<Nanny: None, threads: 1>' to scheduler 'tcp://172.30.100.5:35587'
Traceback (most recent call last):
  File "/scratch/cnt0024/hmg2840/albert7a/anaconda3/lib/python3.7/site-packages/distributed/nanny.py", line 303, in instantiate
    timedelta(seconds=self.death_timeout), self.process.start()
  File "/scratch/cnt0024/hmg2840/albert7a/anaconda3/lib/python3.7/site-packages/tornado/gen.py", line 729, in run
    value = future.result()
tornado.util.TimeoutError: Timeout
distributed.worker - INFO - Stopping worker at tcp://172.30.10.91:34817
distributed.nanny - INFO - Closing Nanny at 'tcp://172.30.10.91:44800'
distributed.worker - INFO - Stopping worker at tcp://172.30.10.91:39423
distributed.nanny - ERROR - Timed out connecting Nanny '<Nanny: None, threads: 1>' to scheduler 'tcp://172.30.100.5:35587'
Traceback (most recent call last):
  File "/scratch/cnt0024/hmg2840/albert7a/anaconda3/lib/python3.7/site-packages/distributed/nanny.py", line 303, in instantiate
    timedelta(seconds=self.death_timeout), self.process.start()
  File "/scratch/cnt0024/hmg2840/albert7a/anaconda3/lib/python3.7/site-packages/tornado/gen.py", line 729, in run
    value = future.result()
tornado.util.TimeoutError: Timeout
distributed.nanny - INFO - Closing Nanny at 'tcp://172.30.10.91:43474'
distributed.worker - INFO - Stopping worker at tcp://172.30.10.91:39571
distributed.nanny - INFO - Closing Nanny at 'tcp://172.30.10.91:44084'
distributed.worker - INFO - Stopping worker at tcp://172.30.10.91:37396
distributed.nanny - ERROR - Timed out connecting Nanny '<Nanny: None, threads: 1>' to scheduler 'tcp://172.30.100.5:35587'
Traceback (most recent call last):
  File "/scratch/cnt0024/hmg2840/albert7a/anaconda3/lib/python3.7/site-packages/distributed/nanny.py", line 303, in instantiate
    timedelta(seconds=self.death_timeout), self.process.start()
  File "/scratch/cnt0024/hmg2840/albert7a/anaconda3/lib/python3.7/site-packages/tornado/gen.py", line 729, in run
    value = future.result()
tornado.util.TimeoutError: Timeout
distributed.nanny - ERROR - Timed out connecting Nanny '<Nanny: None, threads: 1>' to scheduler 'tcp://172.30.100.5:35587'
Traceback (most recent call last):
  File "/scratch/cnt0024/hmg2840/albert7a/anaconda3/lib/python3.7/site-packages/distributed/nanny.py", line 303, in instantiate
    timedelta(seconds=self.death_timeout), self.process.start()
  File "/scratch/cnt0024/hmg2840/albert7a/anaconda3/lib/python3.7/site-packages/tornado/gen.py", line 729, in run
    value = future.result()
tornado.util.TimeoutError: Timeout
distributed.nanny - ERROR - Timed out connecting Nanny '<Nanny: None, threads: 1>' to scheduler 'tcp://172.30.100.5:35587'
Traceback (most recent call last):
  File "/scratch/cnt0024/hmg2840/albert7a/anaconda3/lib/python3.7/site-packages/distributed/nanny.py", line 303, in instantiate
    timedelta(seconds=self.death_timeout), self.process.start()
  File "/scratch/cnt0024/hmg2840/albert7a/anaconda3/lib/python3.7/site-packages/tornado/gen.py", line 729, in run
    value = future.result()
tornado.util.TimeoutError: Timeout
distributed.nanny - ERROR - Timed out connecting Nanny '<Nanny: None, threads: 1>' to scheduler 'tcp://172.30.100.5:35587'
Traceback (most recent call last):
  File "/scratch/cnt0024/hmg2840/albert7a/anaconda3/lib/python3.7/site-packages/distributed/nanny.py", line 303, in instantiate
    timedelta(seconds=self.death_timeout), self.process.start()
  File "/scratch/cnt0024/hmg2840/albert7a/anaconda3/lib/python3.7/site-packages/tornado/gen.py", line 729, in run
    value = future.result()
tornado.util.TimeoutError: Timeout
distributed.nanny - ERROR - Timed out connecting Nanny '<Nanny: None, threads: 1>' to scheduler 'tcp://172.30.100.5:35587'
Traceback (most recent call last):
  File "/scratch/cnt0024/hmg2840/albert7a/anaconda3/lib/python3.7/site-packages/distributed/nanny.py", line 303, in instantiate
    timedelta(seconds=self.death_timeout), self.process.start()
  File "/scratch/cnt0024/hmg2840/albert7a/anaconda3/lib/python3.7/site-packages/tornado/gen.py", line 729, in run
    value = future.result()
tornado.util.TimeoutError: Timeout
distributed.nanny - ERROR - Timed out connecting Nanny '<Nanny: None, threads: 1>' to scheduler 'tcp://172.30.100.5:35587'
Traceback (most recent call last):
  File "/scratch/cnt0024/hmg2840/albert7a/anaconda3/lib/python3.7/site-packages/distributed/nanny.py", line 303, in instantiate
    timedelta(seconds=self.death_timeout), self.process.start()
  File "/scratch/cnt0024/hmg2840/albert7a/anaconda3/lib/python3.7/site-packages/tornado/gen.py", line 729, in run
    value = future.result()
tornado.util.TimeoutError: Timeout
distributed.nanny - ERROR - Timed out connecting Nanny '<Nanny: None, threads: 1>' to scheduler 'tcp://172.30.100.5:35587'
Traceback (most recent call last):
  File "/scratch/cnt0024/hmg2840/albert7a/anaconda3/lib/python3.7/site-packages/distributed/nanny.py", line 303, in instantiate
    timedelta(seconds=self.death_timeout), self.process.start()
  File "/scratch/cnt0024/hmg2840/albert7a/anaconda3/lib/python3.7/site-packages/tornado/gen.py", line 729, in run
    value = future.result()
tornado.util.TimeoutError: Timeout
distributed.nanny - ERROR - Timed out connecting Nanny '<Nanny: None, threads: 1>' to scheduler 'tcp://172.30.100.5:35587'
Traceback (most recent call last):
  File "/scratch/cnt0024/hmg2840/albert7a/anaconda3/lib/python3.7/site-packages/distributed/nanny.py", line 303, in instantiate
    timedelta(seconds=self.death_timeout), self.process.start()
  File "/scratch/cnt0024/hmg2840/albert7a/anaconda3/lib/python3.7/site-packages/tornado/gen.py", line 729, in run
    value = future.result()
tornado.util.TimeoutError: Timeout
distributed.nanny - ERROR - Timed out connecting Nanny '<Nanny: None, threads: 1>' to scheduler 'tcp://172.30.100.5:35587'
Traceback (most recent call last):
  File "/scratch/cnt0024/hmg2840/albert7a/anaconda3/lib/python3.7/site-packages/distributed/nanny.py", line 303, in instantiate
    timedelta(seconds=self.death_timeout), self.process.start()
  File "/scratch/cnt0024/hmg2840/albert7a/anaconda3/lib/python3.7/site-packages/tornado/gen.py", line 729, in run
    value = future.result()
tornado.util.TimeoutError: Timeout
distributed.nanny - ERROR - Timed out connecting Nanny '<Nanny: None, threads: 1>' to scheduler 'tcp://172.30.100.5:35587'
Traceback (most recent call last):
  File "/scratch/cnt0024/hmg2840/albert7a/anaconda3/lib/python3.7/site-packages/distributed/nanny.py", line 303, in instantiate
    timedelta(seconds=self.death_timeout), self.process.start()
  File "/scratch/cnt0024/hmg2840/albert7a/anaconda3/lib/python3.7/site-packages/tornado/gen.py", line 729, in run
    value = future.result()
tornado.util.TimeoutError: Timeout
distributed.nanny - ERROR - Timed out connecting Nanny '<Nanny: None, threads: 1>' to scheduler 'tcp://172.30.100.5:35587'
Traceback (most recent call last):
  File "/scratch/cnt0024/hmg2840/albert7a/anaconda3/lib/python3.7/site-packages/distributed/nanny.py", line 303, in instantiate
    timedelta(seconds=self.death_timeout), self.process.start()
  File "/scratch/cnt0024/hmg2840/albert7a/anaconda3/lib/python3.7/site-packages/tornado/gen.py", line 729, in run
    value = future.result()
tornado.util.TimeoutError: Timeout
distributed.nanny - ERROR - Timed out connecting Nanny '<Nanny: None, threads: 1>' to scheduler 'tcp://172.30.100.5:35587'
Traceback (most recent call last):
  File "/scratch/cnt0024/hmg2840/albert7a/anaconda3/lib/python3.7/site-packages/distributed/nanny.py", line 303, in instantiate
    timedelta(seconds=self.death_timeout), self.process.start()
  File "/scratch/cnt0024/hmg2840/albert7a/anaconda3/lib/python3.7/site-packages/tornado/gen.py", line 729, in run
    value = future.result()
tornado.util.TimeoutError: Timeout
tornado.application - ERROR - Multiple exceptions in yield list
Traceback (most recent call last):
  File "/scratch/cnt0024/hmg2840/albert7a/anaconda3/lib/python3.7/site-packages/tornado/gen.py", line 501, in callback
    result_list.append(f.result())
  File "/scratch/cnt0024/hmg2840/albert7a/anaconda3/lib/python3.7/asyncio/tasks.py", line 603, in _wrap_awaitable
    return (yield from awaitable.__await__())
  File "/scratch/cnt0024/hmg2840/albert7a/anaconda3/lib/python3.7/site-packages/tornado/gen.py", line 736, in run
    yielded = self.gen.throw(*exc_info)  # type: ignore
  File "/scratch/cnt0024/hmg2840/albert7a/anaconda3/lib/python3.7/site-packages/distributed/nanny.py", line 224, in _start
    response = yield self.instantiate()
  File "/scratch/cnt0024/hmg2840/albert7a/anaconda3/lib/python3.7/site-packages/tornado/gen.py", line 729, in run
    value = future.result()
  File "/scratch/cnt0024/hmg2840/albert7a/anaconda3/lib/python3.7/site-packages/tornado/gen.py", line 742, in run
    yielded = self.gen.send(value)
  File "/scratch/cnt0024/hmg2840/albert7a/anaconda3/lib/python3.7/site-packages/distributed/nanny.py", line 303, in instantiate
    timedelta(seconds=self.death_timeout), self.process.start()
  File "/scratch/cnt0024/hmg2840/albert7a/anaconda3/lib/python3.7/site-packages/tornado/gen.py", line 729, in run
    value = future.result()
tornado.util.TimeoutError: Timeout
tornado.application - ERROR - Multiple exceptions in yield list
Traceback (most recent call last):
  File "/scratch/cnt0024/hmg2840/albert7a/anaconda3/lib/python3.7/site-packages/tornado/gen.py", line 501, in callback
    result_list.append(f.result())
  File "/scratch/cnt0024/hmg2840/albert7a/anaconda3/lib/python3.7/asyncio/tasks.py", line 603, in _wrap_awaitable
    return (yield from awaitable.__await__())
  File "/scratch/cnt0024/hmg2840/albert7a/anaconda3/lib/python3.7/site-packages/tornado/gen.py", line 736, in run
    yielded = self.gen.throw(*exc_info)  # type: ignore
  File "/scratch/cnt0024/hmg2840/albert7a/anaconda3/lib/python3.7/site-packages/distributed/nanny.py", line 224, in _start
    response = yield self.instantiate()
  File "/scratch/cnt0024/hmg2840/albert7a/anaconda3/lib/python3.7/site-packages/tornado/gen.py", line 729, in run
    value = future.result()
  File "/scratch/cnt0024/hmg2840/albert7a/anaconda3/lib/python3.7/site-packages/tornado/gen.py", line 742, in run
    yielded = self.gen.send(value)
  File "/scratch/cnt0024/hmg2840/albert7a/anaconda3/lib/python3.7/site-packages/distributed/nanny.py", line 303, in instantiate
    timedelta(seconds=self.death_timeout), self.process.start()
  File "/scratch/cnt0024/hmg2840/albert7a/anaconda3/lib/python3.7/site-packages/tornado/gen.py", line 729, in run
    value = future.result()
tornado.util.TimeoutError: Timeout
tornado.application - ERROR - Multiple exceptions in yield list
Traceback (most recent call last):
  File "/scratch/cnt0024/hmg2840/albert7a/anaconda3/lib/python3.7/site-packages/tornado/gen.py", line 501, in callback
    result_list.append(f.result())
  File "/scratch/cnt0024/hmg2840/albert7a/anaconda3/lib/python3.7/asyncio/tasks.py", line 603, in _wrap_awaitable
    return (yield from awaitable.__await__())
  File "/scratch/cnt0024/hmg2840/albert7a/anaconda3/lib/python3.7/site-packages/tornado/gen.py", line 736, in run
    yielded = self.gen.throw(*exc_info)  # type: ignore
  File "/scratch/cnt0024/hmg2840/albert7a/anaconda3/lib/python3.7/site-packages/distributed/nanny.py", line 224, in _start
    response = yield self.instantiate()
  File "/scratch/cnt0024/hmg2840/albert7a/anaconda3/lib/python3.7/site-packages/tornado/gen.py", line 729, in run
    value = future.result()
  File "/scratch/cnt0024/hmg2840/albert7a/anaconda3/lib/python3.7/site-packages/tornado/gen.py", line 742, in run
    yielded = self.gen.send(value)
  File "/scratch/cnt0024/hmg2840/albert7a/anaconda3/lib/python3.7/site-packages/distributed/nanny.py", line 303, in instantiate
    timedelta(seconds=self.death_timeout), self.process.start()
  File "/scratch/cnt0024/hmg2840/albert7a/anaconda3/lib/python3.7/site-packages/tornado/gen.py", line 729, in run
    value = future.result()
tornado.util.TimeoutError: Timeout
tornado.application - ERROR - Multiple exceptions in yield list
Traceback (most recent call last):
  File "/scratch/cnt0024/hmg2840/albert7a/anaconda3/lib/python3.7/site-packages/tornado/gen.py", line 501, in callback
    result_list.append(f.result())
  File "/scratch/cnt0024/hmg2840/albert7a/anaconda3/lib/python3.7/asyncio/tasks.py", line 603, in _wrap_awaitable
    return (yield from awaitable.__await__())
  File "/scratch/cnt0024/hmg2840/albert7a/anaconda3/lib/python3.7/site-packages/tornado/gen.py", line 736, in run
    yielded = self.gen.throw(*exc_info)  # type: ignore
  File "/scratch/cnt0024/hmg2840/albert7a/anaconda3/lib/python3.7/site-packages/distributed/nanny.py", line 224, in _start
    response = yield self.instantiate()
  File "/scratch/cnt0024/hmg2840/albert7a/anaconda3/lib/python3.7/site-packages/tornado/gen.py", line 729, in run
    value = future.result()
  File "/scratch/cnt0024/hmg2840/albert7a/anaconda3/lib/python3.7/site-packages/tornado/gen.py", line 742, in run
    yielded = self.gen.send(value)
  File "/scratch/cnt0024/hmg2840/albert7a/anaconda3/lib/python3.7/site-packages/distributed/nanny.py", line 303, in instantiate
    timedelta(seconds=self.death_timeout), self.process.start()
  File "/scratch/cnt0024/hmg2840/albert7a/anaconda3/lib/python3.7/site-packages/tornado/gen.py", line 729, in run
    value = future.result()
tornado.util.TimeoutError: Timeout
tornado.application - ERROR - Multiple exceptions in yield list
Traceback (most recent call last):
  File "/scratch/cnt0024/hmg2840/albert7a/anaconda3/lib/python3.7/site-packages/tornado/gen.py", line 501, in callback
    result_list.append(f.result())
  File "/scratch/cnt0024/hmg2840/albert7a/anaconda3/lib/python3.7/asyncio/tasks.py", line 603, in _wrap_awaitable
    return (yield from awaitable.__await__())
  File "/scratch/cnt0024/hmg2840/albert7a/anaconda3/lib/python3.7/site-packages/tornado/gen.py", line 736, in run
    yielded = self.gen.throw(*exc_info)  # type: ignore
  File "/scratch/cnt0024/hmg2840/albert7a/anaconda3/lib/python3.7/site-packages/distributed/nanny.py", line 224, in _start
    response = yield self.instantiate()
  File "/scratch/cnt0024/hmg2840/albert7a/anaconda3/lib/python3.7/site-packages/tornado/gen.py", line 729, in run
    value = future.result()
  File "/scratch/cnt0024/hmg2840/albert7a/anaconda3/lib/python3.7/site-packages/tornado/gen.py", line 742, in run
    yielded = self.gen.send(value)
  File "/scratch/cnt0024/hmg2840/albert7a/anaconda3/lib/python3.7/site-packages/distributed/nanny.py", line 303, in instantiate
    timedelta(seconds=self.death_timeout), self.process.start()
  File "/scratch/cnt0024/hmg2840/albert7a/anaconda3/lib/python3.7/site-packages/tornado/gen.py", line 729, in run
    value = future.result()
tornado.util.TimeoutError: Timeout
tornado.application - ERROR - Multiple exceptions in yield list
Traceback (most recent call last):
  File "/scratch/cnt0024/hmg2840/albert7a/anaconda3/lib/python3.7/site-packages/tornado/gen.py", line 501, in callback
    result_list.append(f.result())
  File "/scratch/cnt0024/hmg2840/albert7a/anaconda3/lib/python3.7/asyncio/tasks.py", line 603, in _wrap_awaitable
    return (yield from awaitable.__await__())
  File "/scratch/cnt0024/hmg2840/albert7a/anaconda3/lib/python3.7/site-packages/tornado/gen.py", line 736, in run
    yielded = self.gen.throw(*exc_info)  # type: ignore
  File "/scratch/cnt0024/hmg2840/albert7a/anaconda3/lib/python3.7/site-packages/distributed/nanny.py", line 224, in _start
    response = yield self.instantiate()
  File "/scratch/cnt0024/hmg2840/albert7a/anaconda3/lib/python3.7/site-packages/tornado/gen.py", line 729, in run
    value = future.result()
  File "/scratch/cnt0024/hmg2840/albert7a/anaconda3/lib/python3.7/site-packages/tornado/gen.py", line 742, in run
    yielded = self.gen.send(value)
  File "/scratch/cnt0024/hmg2840/albert7a/anaconda3/lib/python3.7/site-packages/distributed/nanny.py", line 303, in instantiate
    timedelta(seconds=self.death_timeout), self.process.start()
  File "/scratch/cnt0024/hmg2840/albert7a/anaconda3/lib/python3.7/site-packages/tornado/gen.py", line 729, in run
    value = future.result()
tornado.util.TimeoutError: Timeout
tornado.application - ERROR - Multiple exceptions in yield list
Traceback (most recent call last):
  File "/scratch/cnt0024/hmg2840/albert7a/anaconda3/lib/python3.7/site-packages/tornado/gen.py", line 501, in callback
    result_list.append(f.result())
  File "/scratch/cnt0024/hmg2840/albert7a/anaconda3/lib/python3.7/asyncio/tasks.py", line 603, in _wrap_awaitable
    return (yield from awaitable.__await__())
  File "/scratch/cnt0024/hmg2840/albert7a/anaconda3/lib/python3.7/site-packages/tornado/gen.py", line 736, in run
    yielded = self.gen.throw(*exc_info)  # type: ignore
  File "/scratch/cnt0024/hmg2840/albert7a/anaconda3/lib/python3.7/site-packages/distributed/nanny.py", line 224, in _start
    response = yield self.instantiate()
  File "/scratch/cnt0024/hmg2840/albert7a/anaconda3/lib/python3.7/site-packages/tornado/gen.py", line 729, in run
    value = future.result()
  File "/scratch/cnt0024/hmg2840/albert7a/anaconda3/lib/python3.7/site-packages/tornado/gen.py", line 742, in run
    yielded = self.gen.send(value)
  File "/scratch/cnt0024/hmg2840/albert7a/anaconda3/lib/python3.7/site-packages/distributed/nanny.py", line 303, in instantiate
    timedelta(seconds=self.death_timeout), self.process.start()
  File "/scratch/cnt0024/hmg2840/albert7a/anaconda3/lib/python3.7/site-packages/tornado/gen.py", line 729, in run
    value = future.result()
tornado.util.TimeoutError: Timeout
tornado.application - ERROR - Multiple exceptions in yield list
Traceback (most recent call last):
  File "/scratch/cnt0024/hmg2840/albert7a/anaconda3/lib/python3.7/site-packages/tornado/gen.py", line 501, in callback
    result_list.append(f.result())
  File "/scratch/cnt0024/hmg2840/albert7a/anaconda3/lib/python3.7/asyncio/tasks.py", line 603, in _wrap_awaitable
    return (yield from awaitable.__await__())
  File "/scratch/cnt0024/hmg2840/albert7a/anaconda3/lib/python3.7/site-packages/tornado/gen.py", line 736, in run
    yielded = self.gen.throw(*exc_info)  # type: ignore
  File "/scratch/cnt0024/hmg2840/albert7a/anaconda3/lib/python3.7/site-packages/distributed/nanny.py", line 224, in _start
    response = yield self.instantiate()
  File "/scratch/cnt0024/hmg2840/albert7a/anaconda3/lib/python3.7/site-packages/tornado/gen.py", line 729, in run
    value = future.result()
  File "/scratch/cnt0024/hmg2840/albert7a/anaconda3/lib/python3.7/site-packages/tornado/gen.py", line 742, in run
    yielded = self.gen.send(value)
  File "/scratch/cnt0024/hmg2840/albert7a/anaconda3/lib/python3.7/site-packages/distributed/nanny.py", line 303, in instantiate
    timedelta(seconds=self.death_timeout), self.process.start()
  File "/scratch/cnt0024/hmg2840/albert7a/anaconda3/lib/python3.7/site-packages/tornado/gen.py", line 729, in run
    value = future.result()
tornado.util.TimeoutError: Timeout
tornado.application - ERROR - Multiple exceptions in yield list
Traceback (most recent call last):
  File "/scratch/cnt0024/hmg2840/albert7a/anaconda3/lib/python3.7/site-packages/tornado/gen.py", line 501, in callback
    result_list.append(f.result())
  File "/scratch/cnt0024/hmg2840/albert7a/anaconda3/lib/python3.7/asyncio/tasks.py", line 603, in _wrap_awaitable
    return (yield from awaitable.__await__())
  File "/scratch/cnt0024/hmg2840/albert7a/anaconda3/lib/python3.7/site-packages/tornado/gen.py", line 736, in run
    yielded = self.gen.throw(*exc_info)  # type: ignore
  File "/scratch/cnt0024/hmg2840/albert7a/anaconda3/lib/python3.7/site-packages/distributed/nanny.py", line 224, in _start
    response = yield self.instantiate()
  File "/scratch/cnt0024/hmg2840/albert7a/anaconda3/lib/python3.7/site-packages/tornado/gen.py", line 729, in run
    value = future.result()
  File "/scratch/cnt0024/hmg2840/albert7a/anaconda3/lib/python3.7/site-packages/tornado/gen.py", line 742, in run
    yielded = self.gen.send(value)
  File "/scratch/cnt0024/hmg2840/albert7a/anaconda3/lib/python3.7/site-packages/distributed/nanny.py", line 303, in instantiate
    timedelta(seconds=self.death_timeout), self.process.start()
  File "/scratch/cnt0024/hmg2840/albert7a/anaconda3/lib/python3.7/site-packages/tornado/gen.py", line 729, in run
    value = future.result()
tornado.util.TimeoutError: Timeout
tornado.application - ERROR - Multiple exceptions in yield list
Traceback (most recent call last):
  File "/scratch/cnt0024/hmg2840/albert7a/anaconda3/lib/python3.7/site-packages/tornado/gen.py", line 501, in callback
    result_list.append(f.result())
  File "/scratch/cnt0024/hmg2840/albert7a/anaconda3/lib/python3.7/asyncio/tasks.py", line 603, in _wrap_awaitable
    return (yield from awaitable.__await__())
  File "/scratch/cnt0024/hmg2840/albert7a/anaconda3/lib/python3.7/site-packages/tornado/gen.py", line 736, in run
    yielded = self.gen.throw(*exc_info)  # type: ignore
  File "/scratch/cnt0024/hmg2840/albert7a/anaconda3/lib/python3.7/site-packages/distributed/nanny.py", line 224, in _start
    response = yield self.instantiate()
  File "/scratch/cnt0024/hmg2840/albert7a/anaconda3/lib/python3.7/site-packages/tornado/gen.py", line 729, in run
    value = future.result()
  File "/scratch/cnt0024/hmg2840/albert7a/anaconda3/lib/python3.7/site-packages/tornado/gen.py", line 742, in run
    yielded = self.gen.send(value)
  File "/scratch/cnt0024/hmg2840/albert7a/anaconda3/lib/python3.7/site-packages/distributed/nanny.py", line 303, in instantiate
    timedelta(seconds=self.death_timeout), self.process.start()
  File "/scratch/cnt0024/hmg2840/albert7a/anaconda3/lib/python3.7/site-packages/tornado/gen.py", line 729, in run
    value = future.result()
tornado.util.TimeoutError: Timeout
tornado.application - ERROR - Multiple exceptions in yield list
Traceback (most recent call last):
  File "/scratch/cnt0024/hmg2840/albert7a/anaconda3/lib/python3.7/site-packages/tornado/gen.py", line 501, in callback
    result_list.append(f.result())
  File "/scratch/cnt0024/hmg2840/albert7a/anaconda3/lib/python3.7/asyncio/tasks.py", line 603, in _wrap_awaitable
    return (yield from awaitable.__await__())
  File "/scratch/cnt0024/hmg2840/albert7a/anaconda3/lib/python3.7/site-packages/tornado/gen.py", line 736, in run
    yielded = self.gen.throw(*exc_info)  # type: ignore
  File "/scratch/cnt0024/hmg2840/albert7a/anaconda3/lib/python3.7/site-packages/distributed/nanny.py", line 224, in _start
    response = yield self.instantiate()
  File "/scratch/cnt0024/hmg2840/albert7a/anaconda3/lib/python3.7/site-packages/tornado/gen.py", line 729, in run
    value = future.result()
  File "/scratch/cnt0024/hmg2840/albert7a/anaconda3/lib/python3.7/site-packages/tornado/gen.py", line 742, in run
    yielded = self.gen.send(value)
  File "/scratch/cnt0024/hmg2840/albert7a/anaconda3/lib/python3.7/site-packages/distributed/nanny.py", line 303, in instantiate
    timedelta(seconds=self.death_timeout), self.process.start()
  File "/scratch/cnt0024/hmg2840/albert7a/anaconda3/lib/python3.7/site-packages/tornado/gen.py", line 729, in run
    value = future.result()
tornado.util.TimeoutError: Timeout
tornado.application - ERROR - Multiple exceptions in yield list
Traceback (most recent call last):
  File "/scratch/cnt0024/hmg2840/albert7a/anaconda3/lib/python3.7/site-packages/tornado/gen.py", line 501, in callback
    result_list.append(f.result())
  File "/scratch/cnt0024/hmg2840/albert7a/anaconda3/lib/python3.7/asyncio/tasks.py", line 603, in _wrap_awaitable
    return (yield from awaitable.__await__())
  File "/scratch/cnt0024/hmg2840/albert7a/anaconda3/lib/python3.7/site-packages/tornado/gen.py", line 736, in run
    yielded = self.gen.throw(*exc_info)  # type: ignore
  File "/scratch/cnt0024/hmg2840/albert7a/anaconda3/lib/python3.7/site-packages/distributed/nanny.py", line 224, in _start
    response = yield self.instantiate()
  File "/scratch/cnt0024/hmg2840/albert7a/anaconda3/lib/python3.7/site-packages/tornado/gen.py", line 729, in run
    value = future.result()
  File "/scratch/cnt0024/hmg2840/albert7a/anaconda3/lib/python3.7/site-packages/tornado/gen.py", line 742, in run
    yielded = self.gen.send(value)
  File "/scratch/cnt0024/hmg2840/albert7a/anaconda3/lib/python3.7/site-packages/distributed/nanny.py", line 303, in instantiate
    timedelta(seconds=self.death_timeout), self.process.start()
  File "/scratch/cnt0024/hmg2840/albert7a/anaconda3/lib/python3.7/site-packages/tornado/gen.py", line 729, in run
    value = future.result()
tornado.util.TimeoutError: Timeout
tornado.application - ERROR - Multiple exceptions in yield list
Traceback (most recent call last):
  File "/scratch/cnt0024/hmg2840/albert7a/anaconda3/lib/python3.7/site-packages/tornado/gen.py", line 501, in callback
    result_list.append(f.result())
  File "/scratch/cnt0024/hmg2840/albert7a/anaconda3/lib/python3.7/asyncio/tasks.py", line 603, in _wrap_awaitable
    return (yield from awaitable.__await__())
  File "/scratch/cnt0024/hmg2840/albert7a/anaconda3/lib/python3.7/site-packages/tornado/gen.py", line 736, in run
    yielded = self.gen.throw(*exc_info)  # type: ignore
  File "/scratch/cnt0024/hmg2840/albert7a/anaconda3/lib/python3.7/site-packages/distributed/nanny.py", line 224, in _start
    response = yield self.instantiate()
  File "/scratch/cnt0024/hmg2840/albert7a/anaconda3/lib/python3.7/site-packages/tornado/gen.py", line 729, in run
    value = future.result()
  File "/scratch/cnt0024/hmg2840/albert7a/anaconda3/lib/python3.7/site-packages/tornado/gen.py", line 742, in run
    yielded = self.gen.send(value)
  File "/scratch/cnt0024/hmg2840/albert7a/anaconda3/lib/python3.7/site-packages/distributed/nanny.py", line 303, in instantiate
    timedelta(seconds=self.death_timeout), self.process.start()
  File "/scratch/cnt0024/hmg2840/albert7a/anaconda3/lib/python3.7/site-packages/tornado/gen.py", line 729, in run
    value = future.result()
tornado.util.TimeoutError: Timeout
tornado.application - ERROR - Multiple exceptions in yield list
Traceback (most recent call last):
  File "/scratch/cnt0024/hmg2840/albert7a/anaconda3/lib/python3.7/site-packages/tornado/gen.py", line 501, in callback
    result_list.append(f.result())
  File "/scratch/cnt0024/hmg2840/albert7a/anaconda3/lib/python3.7/asyncio/tasks.py", line 603, in _wrap_awaitable
    return (yield from awaitable.__await__())
  File "/scratch/cnt0024/hmg2840/albert7a/anaconda3/lib/python3.7/site-packages/tornado/gen.py", line 736, in run
    yielded = self.gen.throw(*exc_info)  # type: ignore
  File "/scratch/cnt0024/hmg2840/albert7a/anaconda3/lib/python3.7/site-packages/distributed/nanny.py", line 224, in _start
    response = yield self.instantiate()
  File "/scratch/cnt0024/hmg2840/albert7a/anaconda3/lib/python3.7/site-packages/tornado/gen.py", line 729, in run
    value = future.result()
  File "/scratch/cnt0024/hmg2840/albert7a/anaconda3/lib/python3.7/site-packages/tornado/gen.py", line 742, in run
    yielded = self.gen.send(value)
  File "/scratch/cnt0024/hmg2840/albert7a/anaconda3/lib/python3.7/site-packages/distributed/nanny.py", line 303, in instantiate
    timedelta(seconds=self.death_timeout), self.process.start()
  File "/scratch/cnt0024/hmg2840/albert7a/anaconda3/lib/python3.7/site-packages/tornado/gen.py", line 729, in run
    value = future.result()
tornado.util.TimeoutError: Timeout
tornado.application - ERROR - Multiple exceptions in yield list
Traceback (most recent call last):
  File "/scratch/cnt0024/hmg2840/albert7a/anaconda3/lib/python3.7/site-packages/tornado/gen.py", line 501, in callback
    result_list.append(f.result())
  File "/scratch/cnt0024/hmg2840/albert7a/anaconda3/lib/python3.7/asyncio/tasks.py", line 603, in _wrap_awaitable
    return (yield from awaitable.__await__())
  File "/scratch/cnt0024/hmg2840/albert7a/anaconda3/lib/python3.7/site-packages/tornado/gen.py", line 736, in run
    yielded = self.gen.throw(*exc_info)  # type: ignore
  File "/scratch/cnt0024/hmg2840/albert7a/anaconda3/lib/python3.7/site-packages/distributed/nanny.py", line 224, in _start
    response = yield self.instantiate()
  File "/scratch/cnt0024/hmg2840/albert7a/anaconda3/lib/python3.7/site-packages/tornado/gen.py", line 729, in run
    value = future.result()
  File "/scratch/cnt0024/hmg2840/albert7a/anaconda3/lib/python3.7/site-packages/tornado/gen.py", line 742, in run
    yielded = self.gen.send(value)
  File "/scratch/cnt0024/hmg2840/albert7a/anaconda3/lib/python3.7/site-packages/distributed/nanny.py", line 303, in instantiate
    timedelta(seconds=self.death_timeout), self.process.start()
  File "/scratch/cnt0024/hmg2840/albert7a/anaconda3/lib/python3.7/site-packages/tornado/gen.py", line 729, in run
    value = future.result()
tornado.util.TimeoutError: Timeout
tornado.application - ERROR - Multiple exceptions in yield list
Traceback (most recent call last):
  File "/scratch/cnt0024/hmg2840/albert7a/anaconda3/lib/python3.7/site-packages/tornado/gen.py", line 501, in callback
    result_list.append(f.result())
  File "/scratch/cnt0024/hmg2840/albert7a/anaconda3/lib/python3.7/asyncio/tasks.py", line 603, in _wrap_awaitable
    return (yield from awaitable.__await__())
  File "/scratch/cnt0024/hmg2840/albert7a/anaconda3/lib/python3.7/site-packages/tornado/gen.py", line 736, in run
    yielded = self.gen.throw(*exc_info)  # type: ignore
  File "/scratch/cnt0024/hmg2840/albert7a/anaconda3/lib/python3.7/site-packages/distributed/nanny.py", line 224, in _start
    response = yield self.instantiate()
  File "/scratch/cnt0024/hmg2840/albert7a/anaconda3/lib/python3.7/site-packages/tornado/gen.py", line 729, in run
    value = future.result()
  File "/scratch/cnt0024/hmg2840/albert7a/anaconda3/lib/python3.7/site-packages/tornado/gen.py", line 742, in run
    yielded = self.gen.send(value)
  File "/scratch/cnt0024/hmg2840/albert7a/anaconda3/lib/python3.7/site-packages/distributed/nanny.py", line 303, in instantiate
    timedelta(seconds=self.death_timeout), self.process.start()
  File "/scratch/cnt0024/hmg2840/albert7a/anaconda3/lib/python3.7/site-packages/tornado/gen.py", line 729, in run
    value = future.result()
tornado.util.TimeoutError: Timeout
tornado.application - ERROR - Multiple exceptions in yield list
Traceback (most recent call last):
  File "/scratch/cnt0024/hmg2840/albert7a/anaconda3/lib/python3.7/site-packages/tornado/gen.py", line 501, in callback
    result_list.append(f.result())
  File "/scratch/cnt0024/hmg2840/albert7a/anaconda3/lib/python3.7/asyncio/tasks.py", line 603, in _wrap_awaitable
    return (yield from awaitable.__await__())
  File "/scratch/cnt0024/hmg2840/albert7a/anaconda3/lib/python3.7/site-packages/tornado/gen.py", line 736, in run
    yielded = self.gen.throw(*exc_info)  # type: ignore
  File "/scratch/cnt0024/hmg2840/albert7a/anaconda3/lib/python3.7/site-packages/distributed/nanny.py", line 224, in _start
    response = yield self.instantiate()
  File "/scratch/cnt0024/hmg2840/albert7a/anaconda3/lib/python3.7/site-packages/tornado/gen.py", line 729, in run
    value = future.result()
  File "/scratch/cnt0024/hmg2840/albert7a/anaconda3/lib/python3.7/site-packages/tornado/gen.py", line 742, in run
    yielded = self.gen.send(value)
  File "/scratch/cnt0024/hmg2840/albert7a/anaconda3/lib/python3.7/site-packages/distributed/nanny.py", line 303, in instantiate
    timedelta(seconds=self.death_timeout), self.process.start()
  File "/scratch/cnt0024/hmg2840/albert7a/anaconda3/lib/python3.7/site-packages/tornado/gen.py", line 729, in run
    value = future.result()
tornado.util.TimeoutError: Timeout
tornado.application - ERROR - Multiple exceptions in yield list
Traceback (most recent call last):
  File "/scratch/cnt0024/hmg2840/albert7a/anaconda3/lib/python3.7/site-packages/tornado/gen.py", line 501, in callback
    result_list.append(f.result())
  File "/scratch/cnt0024/hmg2840/albert7a/anaconda3/lib/python3.7/asyncio/tasks.py", line 603, in _wrap_awaitable
    return (yield from awaitable.__await__())
  File "/scratch/cnt0024/hmg2840/albert7a/anaconda3/lib/python3.7/site-packages/tornado/gen.py", line 736, in run
    yielded = self.gen.throw(*exc_info)  # type: ignore
  File "/scratch/cnt0024/hmg2840/albert7a/anaconda3/lib/python3.7/site-packages/distributed/nanny.py", line 224, in _start
    response = yield self.instantiate()
  File "/scratch/cnt0024/hmg2840/albert7a/anaconda3/lib/python3.7/site-packages/tornado/gen.py", line 729, in run
    value = future.result()
  File "/scratch/cnt0024/hmg2840/albert7a/anaconda3/lib/python3.7/site-packages/tornado/gen.py", line 742, in run
    yielded = self.gen.send(value)
  File "/scratch/cnt0024/hmg2840/albert7a/anaconda3/lib/python3.7/site-packages/distributed/nanny.py", line 303, in instantiate
    timedelta(seconds=self.death_timeout), self.process.start()
  File "/scratch/cnt0024/hmg2840/albert7a/anaconda3/lib/python3.7/site-packages/tornado/gen.py", line 729, in run
    value = future.result()
tornado.util.TimeoutError: Timeout
tornado.application - ERROR - Multiple exceptions in yield list
Traceback (most recent call last):
  File "/scratch/cnt0024/hmg2840/albert7a/anaconda3/lib/python3.7/site-packages/tornado/gen.py", line 501, in callback
    result_list.append(f.result())
  File "/scratch/cnt0024/hmg2840/albert7a/anaconda3/lib/python3.7/asyncio/tasks.py", line 603, in _wrap_awaitable
    return (yield from awaitable.__await__())
  File "/scratch/cnt0024/hmg2840/albert7a/anaconda3/lib/python3.7/site-packages/tornado/gen.py", line 736, in run
    yielded = self.gen.throw(*exc_info)  # type: ignore
  File "/scratch/cnt0024/hmg2840/albert7a/anaconda3/lib/python3.7/site-packages/distributed/nanny.py", line 224, in _start
    response = yield self.instantiate()
  File "/scratch/cnt0024/hmg2840/albert7a/anaconda3/lib/python3.7/site-packages/tornado/gen.py", line 729, in run
    value = future.result()
  File "/scratch/cnt0024/hmg2840/albert7a/anaconda3/lib/python3.7/site-packages/tornado/gen.py", line 742, in run
    yielded = self.gen.send(value)
  File "/scratch/cnt0024/hmg2840/albert7a/anaconda3/lib/python3.7/site-packages/distributed/nanny.py", line 303, in instantiate
    timedelta(seconds=self.death_timeout), self.process.start()
  File "/scratch/cnt0024/hmg2840/albert7a/anaconda3/lib/python3.7/site-packages/tornado/gen.py", line 729, in run
    value = future.result()
tornado.util.TimeoutError: Timeout
tornado.application - ERROR - Multiple exceptions in yield list
Traceback (most recent call last):
  File "/scratch/cnt0024/hmg2840/albert7a/anaconda3/lib/python3.7/site-packages/tornado/gen.py", line 501, in callback
    result_list.append(f.result())
  File "/scratch/cnt0024/hmg2840/albert7a/anaconda3/lib/python3.7/asyncio/tasks.py", line 603, in _wrap_awaitable
    return (yield from awaitable.__await__())
  File "/scratch/cnt0024/hmg2840/albert7a/anaconda3/lib/python3.7/site-packages/tornado/gen.py", line 736, in run
    yielded = self.gen.throw(*exc_info)  # type: ignore
  File "/scratch/cnt0024/hmg2840/albert7a/anaconda3/lib/python3.7/site-packages/distributed/nanny.py", line 224, in _start
    response = yield self.instantiate()
  File "/scratch/cnt0024/hmg2840/albert7a/anaconda3/lib/python3.7/site-packages/tornado/gen.py", line 729, in run
    value = future.result()
  File "/scratch/cnt0024/hmg2840/albert7a/anaconda3/lib/python3.7/site-packages/tornado/gen.py", line 742, in run
    yielded = self.gen.send(value)
  File "/scratch/cnt0024/hmg2840/albert7a/anaconda3/lib/python3.7/site-packages/distributed/nanny.py", line 303, in instantiate
    timedelta(seconds=self.death_timeout), self.process.start()
  File "/scratch/cnt0024/hmg2840/albert7a/anaconda3/lib/python3.7/site-packages/tornado/gen.py", line 729, in run
    value = future.result()
tornado.util.TimeoutError: Timeout
tornado.application - ERROR - Multiple exceptions in yield list
Traceback (most recent call last):
  File "/scratch/cnt0024/hmg2840/albert7a/anaconda3/lib/python3.7/site-packages/tornado/gen.py", line 501, in callback
    result_list.append(f.result())
  File "/scratch/cnt0024/hmg2840/albert7a/anaconda3/lib/python3.7/asyncio/tasks.py", line 603, in _wrap_awaitable
    return (yield from awaitable.__await__())
  File "/scratch/cnt0024/hmg2840/albert7a/anaconda3/lib/python3.7/site-packages/tornado/gen.py", line 736, in run
    yielded = self.gen.throw(*exc_info)  # type: ignore
  File "/scratch/cnt0024/hmg2840/albert7a/anaconda3/lib/python3.7/site-packages/distributed/nanny.py", line 224, in _start
    response = yield self.instantiate()
  File "/scratch/cnt0024/hmg2840/albert7a/anaconda3/lib/python3.7/site-packages/tornado/gen.py", line 729, in run
    value = future.result()
  File "/scratch/cnt0024/hmg2840/albert7a/anaconda3/lib/python3.7/site-packages/tornado/gen.py", line 742, in run
    yielded = self.gen.send(value)
  File "/scratch/cnt0024/hmg2840/albert7a/anaconda3/lib/python3.7/site-packages/distributed/nanny.py", line 303, in instantiate
    timedelta(seconds=self.death_timeout), self.process.start()
  File "/scratch/cnt0024/hmg2840/albert7a/anaconda3/lib/python3.7/site-packages/tornado/gen.py", line 729, in run
    value = future.result()
tornado.util.TimeoutError: Timeout
tornado.application - ERROR - Multiple exceptions in yield list
Traceback (most recent call last):
  File "/scratch/cnt0024/hmg2840/albert7a/anaconda3/lib/python3.7/site-packages/tornado/gen.py", line 501, in callback
    result_list.append(f.result())
  File "/scratch/cnt0024/hmg2840/albert7a/anaconda3/lib/python3.7/asyncio/tasks.py", line 603, in _wrap_awaitable
    return (yield from awaitable.__await__())
  File "/scratch/cnt0024/hmg2840/albert7a/anaconda3/lib/python3.7/site-packages/tornado/gen.py", line 736, in run
    yielded = self.gen.throw(*exc_info)  # type: ignore
  File "/scratch/cnt0024/hmg2840/albert7a/anaconda3/lib/python3.7/site-packages/distributed/nanny.py", line 224, in _start
    response = yield self.instantiate()
  File "/scratch/cnt0024/hmg2840/albert7a/anaconda3/lib/python3.7/site-packages/tornado/gen.py", line 729, in run
    value = future.result()
  File "/scratch/cnt0024/hmg2840/albert7a/anaconda3/lib/python3.7/site-packages/tornado/gen.py", line 742, in run
    yielded = self.gen.send(value)
  File "/scratch/cnt0024/hmg2840/albert7a/anaconda3/lib/python3.7/site-packages/distributed/nanny.py", line 303, in instantiate
    timedelta(seconds=self.death_timeout), self.process.start()
  File "/scratch/cnt0024/hmg2840/albert7a/anaconda3/lib/python3.7/site-packages/tornado/gen.py", line 729, in run
    value = future.result()
tornado.util.TimeoutError: Timeout
tornado.application - ERROR - Multiple exceptions in yield list
Traceback (most recent call last):
  File "/scratch/cnt0024/hmg2840/albert7a/anaconda3/lib/python3.7/site-packages/tornado/gen.py", line 501, in callback
    result_list.append(f.result())
  File "/scratch/cnt0024/hmg2840/albert7a/anaconda3/lib/python3.7/asyncio/tasks.py", line 603, in _wrap_awaitable
    return (yield from awaitable.__await__())
  File "/scratch/cnt0024/hmg2840/albert7a/anaconda3/lib/python3.7/site-packages/tornado/gen.py", line 736, in run
    yielded = self.gen.throw(*exc_info)  # type: ignore
  File "/scratch/cnt0024/hmg2840/albert7a/anaconda3/lib/python3.7/site-packages/distributed/nanny.py", line 224, in _start
    response = yield self.instantiate()
  File "/scratch/cnt0024/hmg2840/albert7a/anaconda3/lib/python3.7/site-packages/tornado/gen.py", line 729, in run
    value = future.result()
  File "/scratch/cnt0024/hmg2840/albert7a/anaconda3/lib/python3.7/site-packages/tornado/gen.py", line 742, in run
    yielded = self.gen.send(value)
  File "/scratch/cnt0024/hmg2840/albert7a/anaconda3/lib/python3.7/site-packages/distributed/nanny.py", line 303, in instantiate
    timedelta(seconds=self.death_timeout), self.process.start()
  File "/scratch/cnt0024/hmg2840/albert7a/anaconda3/lib/python3.7/site-packages/tornado/gen.py", line 729, in run
    value = future.result()
tornado.util.TimeoutError: Timeout
tornado.application - ERROR - Multiple exceptions in yield list
Traceback (most recent call last):
  File "/scratch/cnt0024/hmg2840/albert7a/anaconda3/lib/python3.7/site-packages/tornado/gen.py", line 501, in callback
    result_list.append(f.result())
  File "/scratch/cnt0024/hmg2840/albert7a/anaconda3/lib/python3.7/asyncio/tasks.py", line 603, in _wrap_awaitable
    return (yield from awaitable.__await__())
  File "/scratch/cnt0024/hmg2840/albert7a/anaconda3/lib/python3.7/site-packages/tornado/gen.py", line 736, in run
    yielded = self.gen.throw(*exc_info)  # type: ignore
  File "/scratch/cnt0024/hmg2840/albert7a/anaconda3/lib/python3.7/site-packages/distributed/nanny.py", line 224, in _start
    response = yield self.instantiate()
  File "/scratch/cnt0024/hmg2840/albert7a/anaconda3/lib/python3.7/site-packages/tornado/gen.py", line 729, in run
    value = future.result()
  File "/scratch/cnt0024/hmg2840/albert7a/anaconda3/lib/python3.7/site-packages/tornado/gen.py", line 742, in run
    yielded = self.gen.send(value)
  File "/scratch/cnt0024/hmg2840/albert7a/anaconda3/lib/python3.7/site-packages/distributed/nanny.py", line 303, in instantiate
    timedelta(seconds=self.death_timeout), self.process.start()
  File "/scratch/cnt0024/hmg2840/albert7a/anaconda3/lib/python3.7/site-packages/tornado/gen.py", line 729, in run
    value = future.result()
tornado.util.TimeoutError: Timeout
tornado.application - ERROR - Multiple exceptions in yield list
Traceback (most recent call last):
  File "/scratch/cnt0024/hmg2840/albert7a/anaconda3/lib/python3.7/site-packages/tornado/gen.py", line 501, in callback
    result_list.append(f.result())
  File "/scratch/cnt0024/hmg2840/albert7a/anaconda3/lib/python3.7/asyncio/tasks.py", line 603, in _wrap_awaitable
    return (yield from awaitable.__await__())
  File "/scratch/cnt0024/hmg2840/albert7a/anaconda3/lib/python3.7/site-packages/tornado/gen.py", line 736, in run
    yielded = self.gen.throw(*exc_info)  # type: ignore
  File "/scratch/cnt0024/hmg2840/albert7a/anaconda3/lib/python3.7/site-packages/distributed/nanny.py", line 224, in _start
    response = yield self.instantiate()
  File "/scratch/cnt0024/hmg2840/albert7a/anaconda3/lib/python3.7/site-packages/tornado/gen.py", line 729, in run
    value = future.result()
  File "/scratch/cnt0024/hmg2840/albert7a/anaconda3/lib/python3.7/site-packages/tornado/gen.py", line 742, in run
    yielded = self.gen.send(value)
  File "/scratch/cnt0024/hmg2840/albert7a/anaconda3/lib/python3.7/site-packages/distributed/nanny.py", line 303, in instantiate
    timedelta(seconds=self.death_timeout), self.process.start()
  File "/scratch/cnt0024/hmg2840/albert7a/anaconda3/lib/python3.7/site-packages/tornado/gen.py", line 729, in run
    value = future.result()
tornado.util.TimeoutError: Timeout
tornado.application - ERROR - Multiple exceptions in yield list
Traceback (most recent call last):
  File "/scratch/cnt0024/hmg2840/albert7a/anaconda3/lib/python3.7/site-packages/tornado/gen.py", line 501, in callback
    result_list.append(f.result())
  File "/scratch/cnt0024/hmg2840/albert7a/anaconda3/lib/python3.7/asyncio/tasks.py", line 603, in _wrap_awaitable
    return (yield from awaitable.__await__())
  File "/scratch/cnt0024/hmg2840/albert7a/anaconda3/lib/python3.7/site-packages/tornado/gen.py", line 736, in run
    yielded = self.gen.throw(*exc_info)  # type: ignore
  File "/scratch/cnt0024/hmg2840/albert7a/anaconda3/lib/python3.7/site-packages/distributed/nanny.py", line 224, in _start
    response = yield self.instantiate()
  File "/scratch/cnt0024/hmg2840/albert7a/anaconda3/lib/python3.7/site-packages/tornado/gen.py", line 729, in run
    value = future.result()
  File "/scratch/cnt0024/hmg2840/albert7a/anaconda3/lib/python3.7/site-packages/tornado/gen.py", line 742, in run
    yielded = self.gen.send(value)
  File "/scratch/cnt0024/hmg2840/albert7a/anaconda3/lib/python3.7/site-packages/distributed/nanny.py", line 303, in instantiate
    timedelta(seconds=self.death_timeout), self.process.start()
  File "/scratch/cnt0024/hmg2840/albert7a/anaconda3/lib/python3.7/site-packages/tornado/gen.py", line 729, in run
    value = future.result()
tornado.util.TimeoutError: Timeout
tornado.application - ERROR - Multiple exceptions in yield list
Traceback (most recent call last):
  File "/scratch/cnt0024/hmg2840/albert7a/anaconda3/lib/python3.7/site-packages/tornado/gen.py", line 501, in callback
    result_list.append(f.result())
  File "/scratch/cnt0024/hmg2840/albert7a/anaconda3/lib/python3.7/asyncio/tasks.py", line 603, in _wrap_awaitable
    return (yield from awaitable.__await__())
  File "/scratch/cnt0024/hmg2840/albert7a/anaconda3/lib/python3.7/site-packages/tornado/gen.py", line 736, in run
    yielded = self.gen.throw(*exc_info)  # type: ignore
  File "/scratch/cnt0024/hmg2840/albert7a/anaconda3/lib/python3.7/site-packages/distributed/nanny.py", line 224, in _start
    response = yield self.instantiate()
  File "/scratch/cnt0024/hmg2840/albert7a/anaconda3/lib/python3.7/site-packages/tornado/gen.py", line 729, in run
    value = future.result()
  File "/scratch/cnt0024/hmg2840/albert7a/anaconda3/lib/python3.7/site-packages/tornado/gen.py", line 742, in run
    yielded = self.gen.send(value)
  File "/scratch/cnt0024/hmg2840/albert7a/anaconda3/lib/python3.7/site-packages/distributed/nanny.py", line 303, in instantiate
    timedelta(seconds=self.death_timeout), self.process.start()
  File "/scratch/cnt0024/hmg2840/albert7a/anaconda3/lib/python3.7/site-packages/tornado/gen.py", line 729, in run
    value = future.result()
tornado.util.TimeoutError: Timeout
distributed.dask_worker - INFO - End worker
Traceback (most recent call last):
  File "/scratch/cnt0024/hmg2840/albert7a/anaconda3/lib/python3.7/runpy.py", line 193, in _run_module_as_main
    "__main__", mod_spec)
  File "/scratch/cnt0024/hmg2840/albert7a/anaconda3/lib/python3.7/runpy.py", line 85, in _run_code
    exec(code, run_globals)
  File "/scratch/cnt0024/hmg2840/albert7a/anaconda3/lib/python3.7/site-packages/distributed/cli/dask_worker.py", line 405, in <module>
    go()
  File "/scratch/cnt0024/hmg2840/albert7a/anaconda3/lib/python3.7/site-packages/distributed/cli/dask_worker.py", line 401, in go
    main()
  File "/scratch/cnt0024/hmg2840/albert7a/anaconda3/lib/python3.7/site-packages/click/core.py", line 764, in __call__
    return self.main(*args, **kwargs)
  File "/scratch/cnt0024/hmg2840/albert7a/anaconda3/lib/python3.7/site-packages/click/core.py", line 717, in main
    rv = self.invoke(ctx)
  File "/scratch/cnt0024/hmg2840/albert7a/anaconda3/lib/python3.7/site-packages/click/core.py", line 956, in invoke
    return ctx.invoke(self.callback, **ctx.params)
  File "/scratch/cnt0024/hmg2840/albert7a/anaconda3/lib/python3.7/site-packages/click/core.py", line 555, in invoke
    return callback(*args, **kwargs)
  File "/scratch/cnt0024/hmg2840/albert7a/anaconda3/lib/python3.7/site-packages/distributed/cli/dask_worker.py", line 392, in main
    raise TimeoutError("Timed out starting worker.") from None
tornado.util.TimeoutError: Timed out starting worker.
/scratch/cnt0024/hmg2840/albert7a/anaconda3/lib/python3.7/site-packages/distributed/utils.py:136: RuntimeWarning: Couldn't detect a suitable IP address for reaching '8.8.8.8', defaulting to '127.0.0.1': [Errno 101] Network is unreachable
  RuntimeWarning,
