/scratch/cnt0024/hmg2840/albert7a/anaconda3/lib/python3.7/site-packages/distributed/utils.py:136: RuntimeWarning: Couldn't detect a suitable IP address for reaching '8.8.8.8', defaulting to '127.0.0.1': [Errno 101] Network is unreachable
  RuntimeWarning,
distributed.nanny - INFO -         Start Nanny at: 'tcp://172.30.5.103:43025'
distributed.nanny - INFO -         Start Nanny at: 'tcp://172.30.5.103:40404'
distributed.nanny - INFO -         Start Nanny at: 'tcp://172.30.5.103:43130'
distributed.nanny - INFO -         Start Nanny at: 'tcp://172.30.5.103:35989'
distributed.nanny - INFO -         Start Nanny at: 'tcp://172.30.5.103:32882'
distributed.nanny - INFO -         Start Nanny at: 'tcp://172.30.5.103:37858'
distributed.nanny - INFO -         Start Nanny at: 'tcp://172.30.5.103:42758'
distributed.nanny - INFO -         Start Nanny at: 'tcp://172.30.5.103:33081'
distributed.nanny - INFO -         Start Nanny at: 'tcp://172.30.5.103:33215'
distributed.nanny - INFO -         Start Nanny at: 'tcp://172.30.5.103:33427'
distributed.nanny - INFO -         Start Nanny at: 'tcp://172.30.5.103:36484'
distributed.nanny - INFO -         Start Nanny at: 'tcp://172.30.5.103:44218'
distributed.nanny - INFO -         Start Nanny at: 'tcp://172.30.5.103:46768'
distributed.nanny - INFO -         Start Nanny at: 'tcp://172.30.5.103:39460'
distributed.nanny - INFO -         Start Nanny at: 'tcp://172.30.5.103:41832'
distributed.nanny - INFO -         Start Nanny at: 'tcp://172.30.5.103:46284'
distributed.nanny - INFO -         Start Nanny at: 'tcp://172.30.5.103:41414'
distributed.nanny - INFO -         Start Nanny at: 'tcp://172.30.5.103:39887'
distributed.nanny - INFO -         Start Nanny at: 'tcp://172.30.5.103:39078'
distributed.nanny - INFO -         Start Nanny at: 'tcp://172.30.5.103:33182'
distributed.nanny - INFO -         Start Nanny at: 'tcp://172.30.5.103:44127'
distributed.nanny - INFO -         Start Nanny at: 'tcp://172.30.5.103:45612'
distributed.nanny - INFO -         Start Nanny at: 'tcp://172.30.5.103:41857'
distributed.nanny - INFO -         Start Nanny at: 'tcp://172.30.5.103:42732'
distributed.nanny - INFO -         Start Nanny at: 'tcp://172.30.5.103:39872'
distributed.nanny - INFO -         Start Nanny at: 'tcp://172.30.5.103:46155'
distributed.nanny - INFO -         Start Nanny at: 'tcp://172.30.5.103:38487'
distributed.nanny - INFO -         Start Nanny at: 'tcp://172.30.5.103:45406'
distributed.nanny - INFO - Closing Nanny at 'tcp://172.30.5.103:43025'
distributed.nanny - INFO - Closing Nanny at 'tcp://172.30.5.103:40404'
distributed.nanny - INFO - Closing Nanny at 'tcp://172.30.5.103:43130'
distributed.nanny - INFO - Closing Nanny at 'tcp://172.30.5.103:35989'
distributed.nanny - INFO - Closing Nanny at 'tcp://172.30.5.103:32882'
distributed.nanny - INFO - Closing Nanny at 'tcp://172.30.5.103:37858'
distributed.nanny - INFO - Closing Nanny at 'tcp://172.30.5.103:42758'
distributed.nanny - INFO - Closing Nanny at 'tcp://172.30.5.103:33081'
distributed.nanny - INFO - Closing Nanny at 'tcp://172.30.5.103:33215'
distributed.nanny - INFO - Closing Nanny at 'tcp://172.30.5.103:33427'
distributed.nanny - INFO - Closing Nanny at 'tcp://172.30.5.103:36484'
distributed.nanny - INFO - Closing Nanny at 'tcp://172.30.5.103:44218'
distributed.nanny - INFO - Closing Nanny at 'tcp://172.30.5.103:46768'
distributed.nanny - INFO - Closing Nanny at 'tcp://172.30.5.103:39460'
distributed.nanny - INFO - Closing Nanny at 'tcp://172.30.5.103:41832'
distributed.nanny - INFO - Closing Nanny at 'tcp://172.30.5.103:46284'
distributed.nanny - INFO - Closing Nanny at 'tcp://172.30.5.103:41414'
distributed.nanny - INFO - Closing Nanny at 'tcp://172.30.5.103:39887'
distributed.nanny - INFO - Closing Nanny at 'tcp://172.30.5.103:39078'
distributed.nanny - INFO - Closing Nanny at 'tcp://172.30.5.103:33182'
distributed.nanny - INFO - Closing Nanny at 'tcp://172.30.5.103:44127'
distributed.nanny - INFO - Closing Nanny at 'tcp://172.30.5.103:45612'
distributed.nanny - INFO - Closing Nanny at 'tcp://172.30.5.103:41857'
distributed.nanny - INFO - Closing Nanny at 'tcp://172.30.5.103:42732'
distributed.nanny - INFO - Closing Nanny at 'tcp://172.30.5.103:39872'
distributed.nanny - INFO - Closing Nanny at 'tcp://172.30.5.103:46155'
distributed.nanny - INFO - Closing Nanny at 'tcp://172.30.5.103:38487'
distributed.nanny - INFO - Closing Nanny at 'tcp://172.30.5.103:45406'
/scratch/cnt0024/hmg2840/albert7a/anaconda3/lib/python3.7/site-packages/distributed/utils.py:136: RuntimeWarning: Couldn't detect a suitable IP address for reaching '8.8.8.8', defaulting to '127.0.0.1': [Errno 101] Network is unreachable
  RuntimeWarning,
/scratch/cnt0024/hmg2840/albert7a/anaconda3/lib/python3.7/contextlib.py:119: UserWarning: Creating scratch directories is taking a surprisingly long time. This is often due to running workers on a network file system. Consider specifying a local-directory to point workers to write scratch data to a local disk.
  next(self.gen)
distributed.worker - INFO - Stopping worker
/scratch/cnt0024/hmg2840/albert7a/anaconda3/lib/python3.7/site-packages/distributed/utils.py:136: RuntimeWarning: Couldn't detect a suitable IP address for reaching '8.8.8.8', defaulting to '127.0.0.1': [Errno 101] Network is unreachable
  RuntimeWarning,
distributed.worker - INFO - Stopping worker
/scratch/cnt0024/hmg2840/albert7a/anaconda3/lib/python3.7/site-packages/distributed/utils.py:136: RuntimeWarning: Couldn't detect a suitable IP address for reaching '8.8.8.8', defaulting to '127.0.0.1': [Errno 101] Network is unreachable
  RuntimeWarning,
distributed.worker - INFO - Stopping worker
/scratch/cnt0024/hmg2840/albert7a/anaconda3/lib/python3.7/site-packages/distributed/utils.py:136: RuntimeWarning: Couldn't detect a suitable IP address for reaching '8.8.8.8', defaulting to '127.0.0.1': [Errno 101] Network is unreachable
  RuntimeWarning,
distributed.worker - INFO - Stopping worker
distributed.nanny - ERROR - Failed to start worker
Traceback (most recent call last):
  File "/scratch/cnt0024/hmg2840/albert7a/anaconda3/lib/python3.7/site-packages/distributed/nanny.py", line 674, in run
    yield worker._start(*worker_start_args)
  File "/scratch/cnt0024/hmg2840/albert7a/anaconda3/lib/python3.7/site-packages/tornado/gen.py", line 729, in run
    value = future.result()
  File "/scratch/cnt0024/hmg2840/albert7a/anaconda3/lib/python3.7/site-packages/tornado/gen.py", line 209, in wrapper
    yielded = next(result)
  File "/scratch/cnt0024/hmg2840/albert7a/anaconda3/lib/python3.7/site-packages/distributed/worker.py", line 896, in _start
    assert self.status is None
AssertionError
distributed.nanny - ERROR - Failed to start worker
Traceback (most recent call last):
  File "/scratch/cnt0024/hmg2840/albert7a/anaconda3/lib/python3.7/site-packages/distributed/nanny.py", line 674, in run
    yield worker._start(*worker_start_args)
  File "/scratch/cnt0024/hmg2840/albert7a/anaconda3/lib/python3.7/site-packages/tornado/gen.py", line 729, in run
    value = future.result()
  File "/scratch/cnt0024/hmg2840/albert7a/anaconda3/lib/python3.7/site-packages/tornado/gen.py", line 209, in wrapper
    yielded = next(result)
  File "/scratch/cnt0024/hmg2840/albert7a/anaconda3/lib/python3.7/site-packages/distributed/worker.py", line 896, in _start
    assert self.status is None
AssertionError
distributed.nanny - ERROR - Failed to start worker
Traceback (most recent call last):
  File "/scratch/cnt0024/hmg2840/albert7a/anaconda3/lib/python3.7/site-packages/distributed/nanny.py", line 674, in run
    yield worker._start(*worker_start_args)
  File "/scratch/cnt0024/hmg2840/albert7a/anaconda3/lib/python3.7/site-packages/tornado/gen.py", line 729, in run
    value = future.result()
  File "/scratch/cnt0024/hmg2840/albert7a/anaconda3/lib/python3.7/site-packages/tornado/gen.py", line 209, in wrapper
    yielded = next(result)
  File "/scratch/cnt0024/hmg2840/albert7a/anaconda3/lib/python3.7/site-packages/distributed/worker.py", line 896, in _start
    assert self.status is None
AssertionError
distributed.nanny - ERROR - Failed to start worker
Traceback (most recent call last):
  File "/scratch/cnt0024/hmg2840/albert7a/anaconda3/lib/python3.7/site-packages/distributed/nanny.py", line 674, in run
    yield worker._start(*worker_start_args)
  File "/scratch/cnt0024/hmg2840/albert7a/anaconda3/lib/python3.7/site-packages/tornado/gen.py", line 729, in run
    value = future.result()
  File "/scratch/cnt0024/hmg2840/albert7a/anaconda3/lib/python3.7/site-packages/tornado/gen.py", line 209, in wrapper
    yielded = next(result)
  File "/scratch/cnt0024/hmg2840/albert7a/anaconda3/lib/python3.7/site-packages/distributed/worker.py", line 896, in _start
    assert self.status is None
AssertionError
distributed.nanny - ERROR - Timed out connecting Nanny '<Nanny: None, threads: 1>' to scheduler 'tcp://172.30.100.4:44236'
Traceback (most recent call last):
  File "/scratch/cnt0024/hmg2840/albert7a/anaconda3/lib/python3.7/site-packages/distributed/nanny.py", line 303, in instantiate
    timedelta(seconds=self.death_timeout), self.process.start()
  File "/scratch/cnt0024/hmg2840/albert7a/anaconda3/lib/python3.7/site-packages/tornado/gen.py", line 729, in run
    value = future.result()
tornado.util.TimeoutError: Timeout
distributed.nanny - ERROR - Timed out connecting Nanny '<Nanny: None, threads: 1>' to scheduler 'tcp://172.30.100.4:44236'
Traceback (most recent call last):
  File "/scratch/cnt0024/hmg2840/albert7a/anaconda3/lib/python3.7/site-packages/distributed/nanny.py", line 303, in instantiate
    timedelta(seconds=self.death_timeout), self.process.start()
  File "/scratch/cnt0024/hmg2840/albert7a/anaconda3/lib/python3.7/site-packages/tornado/gen.py", line 729, in run
    value = future.result()
tornado.util.TimeoutError: Timeout
distributed.nanny - ERROR - Timed out connecting Nanny '<Nanny: None, threads: 1>' to scheduler 'tcp://172.30.100.4:44236'
Traceback (most recent call last):
  File "/scratch/cnt0024/hmg2840/albert7a/anaconda3/lib/python3.7/site-packages/distributed/nanny.py", line 303, in instantiate
    timedelta(seconds=self.death_timeout), self.process.start()
  File "/scratch/cnt0024/hmg2840/albert7a/anaconda3/lib/python3.7/site-packages/tornado/gen.py", line 729, in run
    value = future.result()
tornado.util.TimeoutError: Timeout
distributed.nanny - ERROR - Timed out connecting Nanny '<Nanny: None, threads: 1>' to scheduler 'tcp://172.30.100.4:44236'
Traceback (most recent call last):
  File "/scratch/cnt0024/hmg2840/albert7a/anaconda3/lib/python3.7/site-packages/distributed/nanny.py", line 303, in instantiate
    timedelta(seconds=self.death_timeout), self.process.start()
  File "/scratch/cnt0024/hmg2840/albert7a/anaconda3/lib/python3.7/site-packages/tornado/gen.py", line 729, in run
    value = future.result()
tornado.util.TimeoutError: Timeout
/scratch/cnt0024/hmg2840/albert7a/anaconda3/lib/python3.7/site-packages/distributed/utils.py:136: RuntimeWarning: Couldn't detect a suitable IP address for reaching '8.8.8.8', defaulting to '127.0.0.1': [Errno 101] Network is unreachable
  RuntimeWarning,
distributed.worker - INFO -       Start worker at:   tcp://172.30.5.103:36244
/scratch/cnt0024/hmg2840/albert7a/anaconda3/lib/python3.7/site-packages/distributed/utils.py:136: RuntimeWarning: Couldn't detect a suitable IP address for reaching '8.8.8.8', defaulting to '127.0.0.1': [Errno 101] Network is unreachable
  RuntimeWarning,
distributed.worker - INFO -       Start worker at:   tcp://172.30.5.103:46556
distributed.worker - INFO -          Listening to:   tcp://172.30.5.103:36244
/scratch/cnt0024/hmg2840/albert7a/anaconda3/lib/python3.7/site-packages/distributed/utils.py:136: RuntimeWarning: Couldn't detect a suitable IP address for reaching '8.8.8.8', defaulting to '127.0.0.1': [Errno 101] Network is unreachable
  RuntimeWarning,
distributed.worker - INFO -       Start worker at:   tcp://172.30.5.103:33607
distributed.worker - INFO -          Listening to:   tcp://172.30.5.103:46556
/scratch/cnt0024/hmg2840/albert7a/anaconda3/lib/python3.7/site-packages/distributed/utils.py:136: RuntimeWarning: Couldn't detect a suitable IP address for reaching '8.8.8.8', defaulting to '127.0.0.1': [Errno 101] Network is unreachable
  RuntimeWarning,
distributed.worker - INFO -       Start worker at:   tcp://172.30.5.103:42181
/scratch/cnt0024/hmg2840/albert7a/anaconda3/lib/python3.7/site-packages/distributed/utils.py:136: RuntimeWarning: Couldn't detect a suitable IP address for reaching '8.8.8.8', defaulting to '127.0.0.1': [Errno 101] Network is unreachable
  RuntimeWarning,
distributed.worker - INFO -       Start worker at:   tcp://172.30.5.103:39262
/scratch/cnt0024/hmg2840/albert7a/anaconda3/lib/python3.7/site-packages/distributed/utils.py:136: RuntimeWarning: Couldn't detect a suitable IP address for reaching '8.8.8.8', defaulting to '127.0.0.1': [Errno 101] Network is unreachable
  RuntimeWarning,
distributed.worker - INFO -       Start worker at:   tcp://172.30.5.103:44879
distributed.worker - INFO -          dashboard at:         172.30.5.103:43157
/scratch/cnt0024/hmg2840/albert7a/anaconda3/lib/python3.7/site-packages/distributed/utils.py:136: RuntimeWarning: Couldn't detect a suitable IP address for reaching '8.8.8.8', defaulting to '127.0.0.1': [Errno 101] Network is unreachable
  RuntimeWarning,
distributed.worker - INFO -       Start worker at:   tcp://172.30.5.103:36794
distributed.worker - INFO -          Listening to:   tcp://172.30.5.103:33607
/scratch/cnt0024/hmg2840/albert7a/anaconda3/lib/python3.7/site-packages/distributed/utils.py:136: RuntimeWarning: Couldn't detect a suitable IP address for reaching '8.8.8.8', defaulting to '127.0.0.1': [Errno 101] Network is unreachable
  RuntimeWarning,
distributed.worker - INFO -       Start worker at:   tcp://172.30.5.103:44993
distributed.worker - INFO -          dashboard at:         172.30.5.103:38394
/scratch/cnt0024/hmg2840/albert7a/anaconda3/lib/python3.7/site-packages/distributed/utils.py:136: RuntimeWarning: Couldn't detect a suitable IP address for reaching '8.8.8.8', defaulting to '127.0.0.1': [Errno 101] Network is unreachable
  RuntimeWarning,
distributed.worker - INFO -       Start worker at:   tcp://172.30.5.103:39184
/scratch/cnt0024/hmg2840/albert7a/anaconda3/lib/python3.7/site-packages/distributed/utils.py:136: RuntimeWarning: Couldn't detect a suitable IP address for reaching '8.8.8.8', defaulting to '127.0.0.1': [Errno 101] Network is unreachable
  RuntimeWarning,
distributed.worker - INFO -       Start worker at:   tcp://172.30.5.103:42741
distributed.worker - INFO -          Listening to:   tcp://172.30.5.103:42181
/scratch/cnt0024/hmg2840/albert7a/anaconda3/lib/python3.7/site-packages/distributed/utils.py:136: RuntimeWarning: Couldn't detect a suitable IP address for reaching '8.8.8.8', defaulting to '127.0.0.1': [Errno 101] Network is unreachable
  RuntimeWarning,
distributed.worker - INFO -       Start worker at:   tcp://172.30.5.103:34310
distributed.worker - INFO -          Listening to:   tcp://172.30.5.103:39262
/scratch/cnt0024/hmg2840/albert7a/anaconda3/lib/python3.7/site-packages/distributed/utils.py:136: RuntimeWarning: Couldn't detect a suitable IP address for reaching '8.8.8.8', defaulting to '127.0.0.1': [Errno 101] Network is unreachable
  RuntimeWarning,
distributed.worker - INFO -       Start worker at:   tcp://172.30.5.103:35099
distributed.worker - INFO -          Listening to:   tcp://172.30.5.103:44879
/scratch/cnt0024/hmg2840/albert7a/anaconda3/lib/python3.7/site-packages/distributed/utils.py:136: RuntimeWarning: Couldn't detect a suitable IP address for reaching '8.8.8.8', defaulting to '127.0.0.1': [Errno 101] Network is unreachable
  RuntimeWarning,
distributed.worker - INFO -       Start worker at:   tcp://172.30.5.103:44772
distributed.worker - INFO -          Listening to:   tcp://172.30.5.103:36794
distributed.worker - INFO -          dashboard at:         172.30.5.103:34276
distributed.worker - INFO - Waiting to connect to:   tcp://172.30.100.4:44236
distributed.worker - INFO -          Listening to:   tcp://172.30.5.103:44993
/scratch/cnt0024/hmg2840/albert7a/anaconda3/lib/python3.7/site-packages/distributed/utils.py:136: RuntimeWarning: Couldn't detect a suitable IP address for reaching '8.8.8.8', defaulting to '127.0.0.1': [Errno 101] Network is unreachable
  RuntimeWarning,
distributed.worker - INFO -       Start worker at:   tcp://172.30.5.103:44258
distributed.worker - INFO -          Listening to:   tcp://172.30.5.103:39184
distributed.worker - INFO -          Listening to:   tcp://172.30.5.103:42741
distributed.worker - INFO - Waiting to connect to:   tcp://172.30.100.4:44236
distributed.worker - INFO -          dashboard at:         172.30.5.103:32869
distributed.worker - INFO -          Listening to:   tcp://172.30.5.103:34310
distributed.worker - INFO -          dashboard at:         172.30.5.103:40949
distributed.worker - INFO -          Listening to:   tcp://172.30.5.103:35099
distributed.worker - INFO -          dashboard at:         172.30.5.103:34573
distributed.worker - INFO -          Listening to:   tcp://172.30.5.103:44772
distributed.worker - INFO - Waiting to connect to:   tcp://172.30.100.4:44236
distributed.worker - INFO - -------------------------------------------------
distributed.worker - INFO -          dashboard at:         172.30.5.103:45338
distributed.worker - INFO -          dashboard at:         172.30.5.103:39676
distributed.worker - INFO -          Listening to:   tcp://172.30.5.103:44258
distributed.worker - INFO - -------------------------------------------------
distributed.worker - INFO -          dashboard at:         172.30.5.103:37797
distributed.worker - INFO - Waiting to connect to:   tcp://172.30.100.4:44236
distributed.worker - INFO -          dashboard at:         172.30.5.103:42620
distributed.worker - INFO -          dashboard at:         172.30.5.103:37872
distributed.worker - INFO -          dashboard at:         172.30.5.103:36851
distributed.worker - INFO - -------------------------------------------------
/scratch/cnt0024/hmg2840/albert7a/anaconda3/lib/python3.7/site-packages/distributed/utils.py:136: RuntimeWarning: Couldn't detect a suitable IP address for reaching '8.8.8.8', defaulting to '127.0.0.1': [Errno 101] Network is unreachable
  RuntimeWarning,
distributed.worker - INFO -       Start worker at:   tcp://172.30.5.103:41127
/scratch/cnt0024/hmg2840/albert7a/anaconda3/lib/python3.7/site-packages/distributed/utils.py:136: RuntimeWarning: Couldn't detect a suitable IP address for reaching '8.8.8.8', defaulting to '127.0.0.1': [Errno 101] Network is unreachable
  RuntimeWarning,
distributed.worker - INFO -       Start worker at:   tcp://172.30.5.103:44652
distributed.worker - INFO -          dashboard at:         172.30.5.103:32838
distributed.worker - INFO - Waiting to connect to:   tcp://172.30.100.4:44236
distributed.worker - INFO - Waiting to connect to:   tcp://172.30.100.4:44236
distributed.worker - INFO -          dashboard at:         172.30.5.103:33913
distributed.worker - INFO - Waiting to connect to:   tcp://172.30.100.4:44236
/scratch/cnt0024/hmg2840/albert7a/anaconda3/lib/python3.7/site-packages/distributed/utils.py:136: RuntimeWarning: Couldn't detect a suitable IP address for reaching '8.8.8.8', defaulting to '127.0.0.1': [Errno 101] Network is unreachable
  RuntimeWarning,
distributed.worker - INFO -       Start worker at:   tcp://172.30.5.103:36881
distributed.worker - INFO - Waiting to connect to:   tcp://172.30.100.4:44236
/scratch/cnt0024/hmg2840/albert7a/anaconda3/lib/python3.7/site-packages/distributed/utils.py:136: RuntimeWarning: Couldn't detect a suitable IP address for reaching '8.8.8.8', defaulting to '127.0.0.1': [Errno 101] Network is unreachable
  RuntimeWarning,
distributed.worker - INFO -       Start worker at:   tcp://172.30.5.103:39627
distributed.worker - INFO - Waiting to connect to:   tcp://172.30.100.4:44236
distributed.worker - INFO - Waiting to connect to:   tcp://172.30.100.4:44236
/scratch/cnt0024/hmg2840/albert7a/anaconda3/lib/python3.7/site-packages/distributed/utils.py:136: RuntimeWarning: Couldn't detect a suitable IP address for reaching '8.8.8.8', defaulting to '127.0.0.1': [Errno 101] Network is unreachable
  RuntimeWarning,
distributed.worker - INFO -       Start worker at:   tcp://172.30.5.103:34028
/scratch/cnt0024/hmg2840/albert7a/anaconda3/lib/python3.7/site-packages/distributed/utils.py:136: RuntimeWarning: Couldn't detect a suitable IP address for reaching '8.8.8.8', defaulting to '127.0.0.1': [Errno 101] Network is unreachable
  RuntimeWarning,
distributed.worker - INFO -       Start worker at:   tcp://172.30.5.103:43957
distributed.worker - INFO -               Threads:                          1
distributed.worker - INFO - Waiting to connect to:   tcp://172.30.100.4:44236
/scratch/cnt0024/hmg2840/albert7a/anaconda3/lib/python3.7/site-packages/distributed/utils.py:136: RuntimeWarning: Couldn't detect a suitable IP address for reaching '8.8.8.8', defaulting to '127.0.0.1': [Errno 101] Network is unreachable
  RuntimeWarning,
distributed.worker - INFO -       Start worker at:   tcp://172.30.5.103:46039
/scratch/cnt0024/hmg2840/albert7a/anaconda3/lib/python3.7/site-packages/distributed/utils.py:136: RuntimeWarning: Couldn't detect a suitable IP address for reaching '8.8.8.8', defaulting to '127.0.0.1': [Errno 101] Network is unreachable
  RuntimeWarning,
distributed.worker - INFO -       Start worker at:   tcp://172.30.5.103:45962
distributed.worker - INFO -               Threads:                          1
distributed.worker - INFO - Waiting to connect to:   tcp://172.30.100.4:44236
distributed.worker - INFO - Waiting to connect to:   tcp://172.30.100.4:44236
distributed.worker - INFO - -------------------------------------------------
distributed.worker - INFO - -------------------------------------------------
distributed.worker - INFO -               Threads:                          1
distributed.worker - INFO - -------------------------------------------------
distributed.worker - INFO -          Listening to:   tcp://172.30.5.103:41127
distributed.worker - INFO -          Listening to:   tcp://172.30.5.103:44652
distributed.worker - INFO - Waiting to connect to:   tcp://172.30.100.4:44236
distributed.worker - INFO - -------------------------------------------------
distributed.worker - INFO - -------------------------------------------------
distributed.worker - INFO - -------------------------------------------------
distributed.worker - INFO -          Listening to:   tcp://172.30.5.103:36881
distributed.worker - INFO -          Listening to:   tcp://172.30.5.103:39627
distributed.worker - INFO -                Memory:                    4.29 GB
/scratch/cnt0024/hmg2840/albert7a/anaconda3/lib/python3.7/site-packages/distributed/utils.py:136: RuntimeWarning: Couldn't detect a suitable IP address for reaching '8.8.8.8', defaulting to '127.0.0.1': [Errno 101] Network is unreachable
  RuntimeWarning,
distributed.worker - INFO -       Start worker at:   tcp://172.30.5.103:39538
/scratch/cnt0024/hmg2840/albert7a/anaconda3/lib/python3.7/site-packages/distributed/utils.py:136: RuntimeWarning: Couldn't detect a suitable IP address for reaching '8.8.8.8', defaulting to '127.0.0.1': [Errno 101] Network is unreachable
  RuntimeWarning,
distributed.worker - INFO -       Start worker at:   tcp://172.30.5.103:46259
distributed.worker - INFO -          Listening to:   tcp://172.30.5.103:43957
distributed.worker - INFO -          Listening to:   tcp://172.30.5.103:34028
distributed.worker - INFO -                Memory:                    4.29 GB
distributed.worker - INFO - -------------------------------------------------
distributed.worker - INFO - -------------------------------------------------
distributed.worker - INFO -          Listening to:   tcp://172.30.5.103:46039
distributed.worker - INFO -          Listening to:   tcp://172.30.5.103:45962
distributed.worker - INFO - -------------------------------------------------
distributed.worker - INFO - -------------------------------------------------
distributed.worker - INFO - -------------------------------------------------
distributed.worker - INFO -                Memory:                    4.29 GB
distributed.worker - INFO -               Threads:                          1
distributed.worker - INFO -               Threads:                          1
distributed.worker - INFO -               Threads:                          1
distributed.worker - INFO -          dashboard at:         172.30.5.103:35604
distributed.worker - INFO -          dashboard at:         172.30.5.103:45482
distributed.worker - INFO -       Local Directory: /scratch/cnt0024/hmg2840/albert7a/worker-5mzv7ebn
distributed.worker - INFO -               Threads:                          1
distributed.worker - INFO -               Threads:                          1
distributed.worker - INFO -          dashboard at:         172.30.5.103:37132
distributed.worker - INFO -          dashboard at:         172.30.5.103:45191
distributed.worker - INFO -               Threads:                          1
distributed.worker - INFO -          Listening to:   tcp://172.30.5.103:39538
distributed.worker - INFO -       Local Directory: /scratch/cnt0024/hmg2840/albert7a/worker-qd9b24nz
distributed.worker - INFO -          dashboard at:         172.30.5.103:43483
distributed.worker - INFO -          dashboard at:         172.30.5.103:45402
distributed.worker - INFO -               Threads:                          1
distributed.worker - INFO -          dashboard at:         172.30.5.103:34637
distributed.worker - INFO -          dashboard at:         172.30.5.103:35249
distributed.worker - INFO -               Threads:                          1
distributed.worker - INFO -                Memory:                    4.29 GB
distributed.worker - INFO -       Local Directory: /scratch/cnt0024/hmg2840/albert7a/worker-14fnuryh
distributed.worker - INFO -                Memory:                    4.29 GB
distributed.worker - INFO -               Threads:                          1
distributed.worker - INFO -               Threads:                          1
distributed.worker - INFO -                Memory:                    4.29 GB
distributed.worker - INFO -                Memory:                    4.29 GB
distributed.worker - INFO - Waiting to connect to:   tcp://172.30.100.4:44236
distributed.worker - INFO - Waiting to connect to:   tcp://172.30.100.4:44236
distributed.worker - INFO -               Threads:                          1
distributed.worker - INFO -                Memory:                    4.29 GB
distributed.worker - INFO -                Memory:                    4.29 GB
distributed.worker - INFO -          dashboard at:         172.30.5.103:46019
distributed.worker - INFO -          Listening to:   tcp://172.30.5.103:46259
distributed.worker - INFO -                Memory:                    4.29 GB
distributed.worker - INFO - Waiting to connect to:   tcp://172.30.100.4:44236
distributed.worker - INFO - Waiting to connect to:   tcp://172.30.100.4:44236
distributed.worker - INFO -       Local Directory: /scratch/cnt0024/hmg2840/albert7a/worker-1_4l39c0
distributed.worker - INFO -                Memory:                    4.29 GB
distributed.worker - INFO - Waiting to connect to:   tcp://172.30.100.4:44236
distributed.worker - INFO - Waiting to connect to:   tcp://172.30.100.4:44236
distributed.worker - INFO -       Local Directory: /scratch/cnt0024/hmg2840/albert7a/worker-rcl_1lkj
distributed.worker - INFO -       Local Directory: /scratch/cnt0024/hmg2840/albert7a/worker-r99z7it6
distributed.worker - INFO -       Local Directory: /scratch/cnt0024/hmg2840/albert7a/worker-6mx1gzeu
distributed.worker - INFO -                Memory:                    4.29 GB
distributed.worker - INFO - Waiting to connect to:   tcp://172.30.100.4:44236
distributed.worker - INFO - -------------------------------------------------
distributed.worker - INFO -       Local Directory: /scratch/cnt0024/hmg2840/albert7a/worker-los20g34
distributed.worker - INFO - -------------------------------------------------
distributed.worker - INFO - -------------------------------------------------
distributed.worker - INFO -       Local Directory: /scratch/cnt0024/hmg2840/albert7a/worker-17hw72mp
distributed.worker - INFO -                Memory:                    4.29 GB
distributed.worker - INFO -       Local Directory: /scratch/cnt0024/hmg2840/albert7a/worker-vwrw5f0q
distributed.worker - INFO - Waiting to connect to:   tcp://172.30.100.4:44236
distributed.worker - INFO -          dashboard at:         172.30.5.103:43016
distributed.worker - INFO - Waiting to connect to:   tcp://172.30.100.4:44236
distributed.worker - INFO -       Local Directory: /scratch/cnt0024/hmg2840/albert7a/worker-6nivxgo0
distributed.worker - INFO - -------------------------------------------------
distributed.worker - INFO - -------------------------------------------------
distributed.worker - INFO - -------------------------------------------------
distributed.worker - INFO - -------------------------------------------------
distributed.worker - INFO - -------------------------------------------------
distributed.worker - INFO -       Local Directory: /scratch/cnt0024/hmg2840/albert7a/worker-e712xdce
distributed.worker - INFO - -------------------------------------------------
distributed.worker - INFO -                Memory:                    4.29 GB
distributed.worker - INFO - -------------------------------------------------
distributed.worker - INFO -       Local Directory: /scratch/cnt0024/hmg2840/albert7a/worker-gus_iizc
distributed.worker - INFO - -------------------------------------------------
distributed.worker - INFO - -------------------------------------------------
distributed.worker - INFO - -------------------------------------------------
distributed.worker - INFO - Waiting to connect to:   tcp://172.30.100.4:44236
distributed.worker - INFO - -------------------------------------------------
distributed.worker - INFO - -------------------------------------------------
distributed.worker - INFO - -------------------------------------------------
distributed.worker - INFO -               Threads:                          1
distributed.worker - INFO -               Threads:                          1
distributed.worker - INFO - -------------------------------------------------
distributed.worker - INFO - -------------------------------------------------
distributed.worker - INFO - -------------------------------------------------
distributed.worker - INFO -       Local Directory: /scratch/cnt0024/hmg2840/albert7a/worker-59vy_tmp
distributed.worker - INFO - -------------------------------------------------
distributed.worker - INFO -               Threads:                          1
distributed.worker - INFO -               Threads:                          1
distributed.worker - INFO -               Threads:                          1
distributed.worker - INFO -               Threads:                          1
distributed.worker - INFO - -------------------------------------------------
distributed.worker - INFO -               Threads:                          1
distributed.worker - INFO - -------------------------------------------------
distributed.worker - INFO -                Memory:                    4.29 GB
distributed.worker - INFO -                Memory:                    4.29 GB
distributed.worker - INFO - -------------------------------------------------
distributed.worker - INFO -               Threads:                          1
distributed.worker - INFO -               Threads:                          1
distributed.worker - INFO -                Memory:                    4.29 GB
distributed.worker - INFO -                Memory:                    4.29 GB
distributed.worker - INFO -                Memory:                    4.29 GB
distributed.worker - INFO -                Memory:                    4.29 GB
distributed.worker - INFO -       Local Directory: /scratch/cnt0024/hmg2840/albert7a/worker-6m8hwfpj
distributed.worker - INFO -       Local Directory: /scratch/cnt0024/hmg2840/albert7a/worker-6xmyd5yx
distributed.worker - INFO -                Memory:                    4.29 GB
distributed.worker - INFO -                Memory:                    4.29 GB
distributed.worker - INFO -                Memory:                    4.29 GB
distributed.worker - INFO -       Local Directory: /scratch/cnt0024/hmg2840/albert7a/worker-rsvg3afh
distributed.worker - INFO -       Local Directory: /scratch/cnt0024/hmg2840/albert7a/worker-fky17ht9
distributed.worker - INFO -       Local Directory: /scratch/cnt0024/hmg2840/albert7a/worker-kx96x1n0
distributed.worker - INFO -       Local Directory: /scratch/cnt0024/hmg2840/albert7a/worker-bf8va5o4
distributed.worker - INFO -               Threads:                          1
distributed.worker - INFO - -------------------------------------------------
distributed.worker - INFO -       Local Directory: /scratch/cnt0024/hmg2840/albert7a/worker-cdeis9q6
distributed.worker - INFO -       Local Directory: /scratch/cnt0024/hmg2840/albert7a/worker-ms0dtotx
distributed.worker - INFO -       Local Directory: /scratch/cnt0024/hmg2840/albert7a/worker-fmwezdu9
distributed.worker - INFO -                Memory:                    4.29 GB
distributed.worker - INFO - -------------------------------------------------
distributed.worker - INFO - -------------------------------------------------
distributed.worker - INFO - Stopping worker at tcp://172.30.5.103:46556
distributed.worker - INFO - -------------------------------------------------
distributed.worker - INFO - -------------------------------------------------
distributed.worker - INFO - -------------------------------------------------
distributed.worker - INFO - -------------------------------------------------
distributed.worker - INFO - -------------------------------------------------
distributed.worker - INFO - -------------------------------------------------
distributed.worker - INFO - Stopping worker at tcp://172.30.5.103:42181
distributed.worker - INFO -       Local Directory: /scratch/cnt0024/hmg2840/albert7a/worker-yrcc6_v1
distributed.worker - INFO - -------------------------------------------------
distributed.worker - INFO - Stopping worker at tcp://172.30.5.103:35099
distributed.worker - INFO - Stopping worker at tcp://172.30.5.103:33607
distributed.worker - INFO - Stopping worker at tcp://172.30.5.103:44993
distributed.worker - INFO - Stopping worker at tcp://172.30.5.103:36794
distributed.worker - INFO - Stopping worker at tcp://172.30.5.103:34310
distributed.worker - INFO - Stopping worker at tcp://172.30.5.103:42741
distributed.worker - INFO - -------------------------------------------------
distributed.worker - INFO - Stopping worker at tcp://172.30.5.103:39262
distributed.worker - INFO - Stopping worker at tcp://172.30.5.103:44258
distributed.worker - INFO - Stopping worker at tcp://172.30.5.103:44879
distributed.worker - INFO - Stopping worker at tcp://172.30.5.103:44772
distributed.worker - INFO - Stopping worker at tcp://172.30.5.103:36244
distributed.worker - INFO - Stopping worker at tcp://172.30.5.103:43957
distributed.worker - INFO - Stopping worker at tcp://172.30.5.103:44652
distributed.worker - INFO - Stopping worker at tcp://172.30.5.103:41127
distributed.worker - INFO - Stopping worker at tcp://172.30.5.103:39184
distributed.worker - INFO - Stopping worker at tcp://172.30.5.103:45962
distributed.worker - INFO - Stopping worker at tcp://172.30.5.103:36881
distributed.worker - INFO - Stopping worker at tcp://172.30.5.103:39538
distributed.worker - INFO - Stopping worker at tcp://172.30.5.103:39627
distributed.worker - INFO - Stopping worker at tcp://172.30.5.103:34028
distributed.worker - INFO - Stopping worker at tcp://172.30.5.103:46039
distributed.worker - INFO - Stopping worker at tcp://172.30.5.103:46259
distributed.nanny - ERROR - Timed out connecting Nanny '<Nanny: None, threads: 1>' to scheduler 'tcp://172.30.100.4:44236'
Traceback (most recent call last):
  File "/scratch/cnt0024/hmg2840/albert7a/anaconda3/lib/python3.7/site-packages/distributed/nanny.py", line 303, in instantiate
    timedelta(seconds=self.death_timeout), self.process.start()
  File "/scratch/cnt0024/hmg2840/albert7a/anaconda3/lib/python3.7/site-packages/tornado/gen.py", line 729, in run
    value = future.result()
tornado.util.TimeoutError: Timeout
distributed.nanny - ERROR - Timed out connecting Nanny '<Nanny: None, threads: 1>' to scheduler 'tcp://172.30.100.4:44236'
Traceback (most recent call last):
  File "/scratch/cnt0024/hmg2840/albert7a/anaconda3/lib/python3.7/site-packages/distributed/nanny.py", line 303, in instantiate
    timedelta(seconds=self.death_timeout), self.process.start()
  File "/scratch/cnt0024/hmg2840/albert7a/anaconda3/lib/python3.7/site-packages/tornado/gen.py", line 729, in run
    value = future.result()
tornado.util.TimeoutError: Timeout
distributed.nanny - ERROR - Timed out connecting Nanny '<Nanny: None, threads: 1>' to scheduler 'tcp://172.30.100.4:44236'
Traceback (most recent call last):
  File "/scratch/cnt0024/hmg2840/albert7a/anaconda3/lib/python3.7/site-packages/distributed/nanny.py", line 303, in instantiate
    timedelta(seconds=self.death_timeout), self.process.start()
  File "/scratch/cnt0024/hmg2840/albert7a/anaconda3/lib/python3.7/site-packages/tornado/gen.py", line 729, in run
    value = future.result()
tornado.util.TimeoutError: Timeout
distributed.nanny - ERROR - Timed out connecting Nanny '<Nanny: None, threads: 1>' to scheduler 'tcp://172.30.100.4:44236'
Traceback (most recent call last):
  File "/scratch/cnt0024/hmg2840/albert7a/anaconda3/lib/python3.7/site-packages/distributed/nanny.py", line 303, in instantiate
    timedelta(seconds=self.death_timeout), self.process.start()
  File "/scratch/cnt0024/hmg2840/albert7a/anaconda3/lib/python3.7/site-packages/tornado/gen.py", line 729, in run
    value = future.result()
tornado.util.TimeoutError: Timeout
distributed.nanny - ERROR - Timed out connecting Nanny '<Nanny: None, threads: 1>' to scheduler 'tcp://172.30.100.4:44236'
Traceback (most recent call last):
  File "/scratch/cnt0024/hmg2840/albert7a/anaconda3/lib/python3.7/site-packages/distributed/nanny.py", line 303, in instantiate
    timedelta(seconds=self.death_timeout), self.process.start()
  File "/scratch/cnt0024/hmg2840/albert7a/anaconda3/lib/python3.7/site-packages/tornado/gen.py", line 729, in run
    value = future.result()
tornado.util.TimeoutError: Timeout
distributed.nanny - ERROR - Timed out connecting Nanny '<Nanny: None, threads: 1>' to scheduler 'tcp://172.30.100.4:44236'
Traceback (most recent call last):
  File "/scratch/cnt0024/hmg2840/albert7a/anaconda3/lib/python3.7/site-packages/distributed/nanny.py", line 303, in instantiate
    timedelta(seconds=self.death_timeout), self.process.start()
  File "/scratch/cnt0024/hmg2840/albert7a/anaconda3/lib/python3.7/site-packages/tornado/gen.py", line 729, in run
    value = future.result()
tornado.util.TimeoutError: Timeout
distributed.nanny - ERROR - Timed out connecting Nanny '<Nanny: None, threads: 1>' to scheduler 'tcp://172.30.100.4:44236'
Traceback (most recent call last):
  File "/scratch/cnt0024/hmg2840/albert7a/anaconda3/lib/python3.7/site-packages/distributed/nanny.py", line 303, in instantiate
    timedelta(seconds=self.death_timeout), self.process.start()
  File "/scratch/cnt0024/hmg2840/albert7a/anaconda3/lib/python3.7/site-packages/tornado/gen.py", line 729, in run
    value = future.result()
tornado.util.TimeoutError: Timeout
distributed.nanny - ERROR - Timed out connecting Nanny '<Nanny: None, threads: 1>' to scheduler 'tcp://172.30.100.4:44236'
Traceback (most recent call last):
  File "/scratch/cnt0024/hmg2840/albert7a/anaconda3/lib/python3.7/site-packages/distributed/nanny.py", line 303, in instantiate
    timedelta(seconds=self.death_timeout), self.process.start()
  File "/scratch/cnt0024/hmg2840/albert7a/anaconda3/lib/python3.7/site-packages/tornado/gen.py", line 729, in run
    value = future.result()
tornado.util.TimeoutError: Timeout
distributed.nanny - ERROR - Timed out connecting Nanny '<Nanny: None, threads: 1>' to scheduler 'tcp://172.30.100.4:44236'
Traceback (most recent call last):
  File "/scratch/cnt0024/hmg2840/albert7a/anaconda3/lib/python3.7/site-packages/distributed/nanny.py", line 303, in instantiate
    timedelta(seconds=self.death_timeout), self.process.start()
  File "/scratch/cnt0024/hmg2840/albert7a/anaconda3/lib/python3.7/site-packages/tornado/gen.py", line 729, in run
    value = future.result()
tornado.util.TimeoutError: Timeout
distributed.nanny - ERROR - Timed out connecting Nanny '<Nanny: None, threads: 1>' to scheduler 'tcp://172.30.100.4:44236'
Traceback (most recent call last):
  File "/scratch/cnt0024/hmg2840/albert7a/anaconda3/lib/python3.7/site-packages/distributed/nanny.py", line 303, in instantiate
    timedelta(seconds=self.death_timeout), self.process.start()
  File "/scratch/cnt0024/hmg2840/albert7a/anaconda3/lib/python3.7/site-packages/tornado/gen.py", line 729, in run
    value = future.result()
tornado.util.TimeoutError: Timeout
distributed.nanny - ERROR - Timed out connecting Nanny '<Nanny: None, threads: 1>' to scheduler 'tcp://172.30.100.4:44236'
Traceback (most recent call last):
  File "/scratch/cnt0024/hmg2840/albert7a/anaconda3/lib/python3.7/site-packages/distributed/nanny.py", line 303, in instantiate
    timedelta(seconds=self.death_timeout), self.process.start()
  File "/scratch/cnt0024/hmg2840/albert7a/anaconda3/lib/python3.7/site-packages/tornado/gen.py", line 729, in run
    value = future.result()
tornado.util.TimeoutError: Timeout
distributed.nanny - ERROR - Timed out connecting Nanny '<Nanny: None, threads: 1>' to scheduler 'tcp://172.30.100.4:44236'
Traceback (most recent call last):
  File "/scratch/cnt0024/hmg2840/albert7a/anaconda3/lib/python3.7/site-packages/distributed/nanny.py", line 303, in instantiate
    timedelta(seconds=self.death_timeout), self.process.start()
  File "/scratch/cnt0024/hmg2840/albert7a/anaconda3/lib/python3.7/site-packages/tornado/gen.py", line 729, in run
    value = future.result()
tornado.util.TimeoutError: Timeout
distributed.nanny - ERROR - Timed out connecting Nanny '<Nanny: None, threads: 1>' to scheduler 'tcp://172.30.100.4:44236'
Traceback (most recent call last):
  File "/scratch/cnt0024/hmg2840/albert7a/anaconda3/lib/python3.7/site-packages/distributed/nanny.py", line 303, in instantiate
    timedelta(seconds=self.death_timeout), self.process.start()
  File "/scratch/cnt0024/hmg2840/albert7a/anaconda3/lib/python3.7/site-packages/tornado/gen.py", line 729, in run
    value = future.result()
tornado.util.TimeoutError: Timeout
distributed.nanny - ERROR - Timed out connecting Nanny '<Nanny: None, threads: 1>' to scheduler 'tcp://172.30.100.4:44236'
Traceback (most recent call last):
  File "/scratch/cnt0024/hmg2840/albert7a/anaconda3/lib/python3.7/site-packages/distributed/nanny.py", line 303, in instantiate
    timedelta(seconds=self.death_timeout), self.process.start()
  File "/scratch/cnt0024/hmg2840/albert7a/anaconda3/lib/python3.7/site-packages/tornado/gen.py", line 729, in run
    value = future.result()
tornado.util.TimeoutError: Timeout
distributed.nanny - ERROR - Timed out connecting Nanny '<Nanny: None, threads: 1>' to scheduler 'tcp://172.30.100.4:44236'
Traceback (most recent call last):
  File "/scratch/cnt0024/hmg2840/albert7a/anaconda3/lib/python3.7/site-packages/distributed/nanny.py", line 303, in instantiate
    timedelta(seconds=self.death_timeout), self.process.start()
  File "/scratch/cnt0024/hmg2840/albert7a/anaconda3/lib/python3.7/site-packages/tornado/gen.py", line 729, in run
    value = future.result()
tornado.util.TimeoutError: Timeout
distributed.nanny - ERROR - Timed out connecting Nanny '<Nanny: None, threads: 1>' to scheduler 'tcp://172.30.100.4:44236'
Traceback (most recent call last):
  File "/scratch/cnt0024/hmg2840/albert7a/anaconda3/lib/python3.7/site-packages/distributed/nanny.py", line 303, in instantiate
    timedelta(seconds=self.death_timeout), self.process.start()
  File "/scratch/cnt0024/hmg2840/albert7a/anaconda3/lib/python3.7/site-packages/tornado/gen.py", line 729, in run
    value = future.result()
tornado.util.TimeoutError: Timeout
distributed.nanny - ERROR - Timed out connecting Nanny '<Nanny: None, threads: 1>' to scheduler 'tcp://172.30.100.4:44236'
Traceback (most recent call last):
  File "/scratch/cnt0024/hmg2840/albert7a/anaconda3/lib/python3.7/site-packages/distributed/nanny.py", line 303, in instantiate
    timedelta(seconds=self.death_timeout), self.process.start()
  File "/scratch/cnt0024/hmg2840/albert7a/anaconda3/lib/python3.7/site-packages/tornado/gen.py", line 729, in run
    value = future.result()
tornado.util.TimeoutError: Timeout
distributed.nanny - ERROR - Timed out connecting Nanny '<Nanny: None, threads: 1>' to scheduler 'tcp://172.30.100.4:44236'
Traceback (most recent call last):
  File "/scratch/cnt0024/hmg2840/albert7a/anaconda3/lib/python3.7/site-packages/distributed/nanny.py", line 303, in instantiate
    timedelta(seconds=self.death_timeout), self.process.start()
  File "/scratch/cnt0024/hmg2840/albert7a/anaconda3/lib/python3.7/site-packages/tornado/gen.py", line 729, in run
    value = future.result()
tornado.util.TimeoutError: Timeout
distributed.nanny - ERROR - Timed out connecting Nanny '<Nanny: None, threads: 1>' to scheduler 'tcp://172.30.100.4:44236'
Traceback (most recent call last):
  File "/scratch/cnt0024/hmg2840/albert7a/anaconda3/lib/python3.7/site-packages/distributed/nanny.py", line 303, in instantiate
    timedelta(seconds=self.death_timeout), self.process.start()
  File "/scratch/cnt0024/hmg2840/albert7a/anaconda3/lib/python3.7/site-packages/tornado/gen.py", line 729, in run
    value = future.result()
tornado.util.TimeoutError: Timeout
distributed.nanny - ERROR - Timed out connecting Nanny '<Nanny: None, threads: 1>' to scheduler 'tcp://172.30.100.4:44236'
Traceback (most recent call last):
  File "/scratch/cnt0024/hmg2840/albert7a/anaconda3/lib/python3.7/site-packages/distributed/nanny.py", line 303, in instantiate
    timedelta(seconds=self.death_timeout), self.process.start()
  File "/scratch/cnt0024/hmg2840/albert7a/anaconda3/lib/python3.7/site-packages/tornado/gen.py", line 729, in run
    value = future.result()
tornado.util.TimeoutError: Timeout
distributed.nanny - ERROR - Timed out connecting Nanny '<Nanny: None, threads: 1>' to scheduler 'tcp://172.30.100.4:44236'
Traceback (most recent call last):
  File "/scratch/cnt0024/hmg2840/albert7a/anaconda3/lib/python3.7/site-packages/distributed/nanny.py", line 303, in instantiate
    timedelta(seconds=self.death_timeout), self.process.start()
  File "/scratch/cnt0024/hmg2840/albert7a/anaconda3/lib/python3.7/site-packages/tornado/gen.py", line 729, in run
    value = future.result()
tornado.util.TimeoutError: Timeout
distributed.nanny - ERROR - Timed out connecting Nanny '<Nanny: None, threads: 1>' to scheduler 'tcp://172.30.100.4:44236'
Traceback (most recent call last):
  File "/scratch/cnt0024/hmg2840/albert7a/anaconda3/lib/python3.7/site-packages/distributed/nanny.py", line 303, in instantiate
    timedelta(seconds=self.death_timeout), self.process.start()
  File "/scratch/cnt0024/hmg2840/albert7a/anaconda3/lib/python3.7/site-packages/tornado/gen.py", line 729, in run
    value = future.result()
tornado.util.TimeoutError: Timeout
distributed.nanny - ERROR - Timed out connecting Nanny '<Nanny: None, threads: 1>' to scheduler 'tcp://172.30.100.4:44236'
Traceback (most recent call last):
  File "/scratch/cnt0024/hmg2840/albert7a/anaconda3/lib/python3.7/site-packages/distributed/nanny.py", line 303, in instantiate
    timedelta(seconds=self.death_timeout), self.process.start()
  File "/scratch/cnt0024/hmg2840/albert7a/anaconda3/lib/python3.7/site-packages/tornado/gen.py", line 729, in run
    value = future.result()
tornado.util.TimeoutError: Timeout
distributed.nanny - ERROR - Timed out connecting Nanny '<Nanny: None, threads: 1>' to scheduler 'tcp://172.30.100.4:44236'
Traceback (most recent call last):
  File "/scratch/cnt0024/hmg2840/albert7a/anaconda3/lib/python3.7/site-packages/distributed/nanny.py", line 303, in instantiate
    timedelta(seconds=self.death_timeout), self.process.start()
  File "/scratch/cnt0024/hmg2840/albert7a/anaconda3/lib/python3.7/site-packages/tornado/gen.py", line 729, in run
    value = future.result()
tornado.util.TimeoutError: Timeout
tornado.application - ERROR - Multiple exceptions in yield list
Traceback (most recent call last):
  File "/scratch/cnt0024/hmg2840/albert7a/anaconda3/lib/python3.7/site-packages/tornado/gen.py", line 501, in callback
    result_list.append(f.result())
  File "/scratch/cnt0024/hmg2840/albert7a/anaconda3/lib/python3.7/asyncio/tasks.py", line 603, in _wrap_awaitable
    return (yield from awaitable.__await__())
  File "/scratch/cnt0024/hmg2840/albert7a/anaconda3/lib/python3.7/site-packages/tornado/gen.py", line 736, in run
    yielded = self.gen.throw(*exc_info)  # type: ignore
  File "/scratch/cnt0024/hmg2840/albert7a/anaconda3/lib/python3.7/site-packages/distributed/nanny.py", line 224, in _start
    response = yield self.instantiate()
  File "/scratch/cnt0024/hmg2840/albert7a/anaconda3/lib/python3.7/site-packages/tornado/gen.py", line 729, in run
    value = future.result()
  File "/scratch/cnt0024/hmg2840/albert7a/anaconda3/lib/python3.7/site-packages/tornado/gen.py", line 742, in run
    yielded = self.gen.send(value)
  File "/scratch/cnt0024/hmg2840/albert7a/anaconda3/lib/python3.7/site-packages/distributed/nanny.py", line 303, in instantiate
    timedelta(seconds=self.death_timeout), self.process.start()
  File "/scratch/cnt0024/hmg2840/albert7a/anaconda3/lib/python3.7/site-packages/tornado/gen.py", line 729, in run
    value = future.result()
tornado.util.TimeoutError: Timeout
tornado.application - ERROR - Multiple exceptions in yield list
Traceback (most recent call last):
  File "/scratch/cnt0024/hmg2840/albert7a/anaconda3/lib/python3.7/site-packages/tornado/gen.py", line 501, in callback
    result_list.append(f.result())
  File "/scratch/cnt0024/hmg2840/albert7a/anaconda3/lib/python3.7/asyncio/tasks.py", line 603, in _wrap_awaitable
    return (yield from awaitable.__await__())
  File "/scratch/cnt0024/hmg2840/albert7a/anaconda3/lib/python3.7/site-packages/tornado/gen.py", line 736, in run
    yielded = self.gen.throw(*exc_info)  # type: ignore
  File "/scratch/cnt0024/hmg2840/albert7a/anaconda3/lib/python3.7/site-packages/distributed/nanny.py", line 224, in _start
    response = yield self.instantiate()
  File "/scratch/cnt0024/hmg2840/albert7a/anaconda3/lib/python3.7/site-packages/tornado/gen.py", line 729, in run
    value = future.result()
  File "/scratch/cnt0024/hmg2840/albert7a/anaconda3/lib/python3.7/site-packages/tornado/gen.py", line 742, in run
    yielded = self.gen.send(value)
  File "/scratch/cnt0024/hmg2840/albert7a/anaconda3/lib/python3.7/site-packages/distributed/nanny.py", line 303, in instantiate
    timedelta(seconds=self.death_timeout), self.process.start()
  File "/scratch/cnt0024/hmg2840/albert7a/anaconda3/lib/python3.7/site-packages/tornado/gen.py", line 729, in run
    value = future.result()
tornado.util.TimeoutError: Timeout
tornado.application - ERROR - Multiple exceptions in yield list
Traceback (most recent call last):
  File "/scratch/cnt0024/hmg2840/albert7a/anaconda3/lib/python3.7/site-packages/tornado/gen.py", line 501, in callback
    result_list.append(f.result())
  File "/scratch/cnt0024/hmg2840/albert7a/anaconda3/lib/python3.7/asyncio/tasks.py", line 603, in _wrap_awaitable
    return (yield from awaitable.__await__())
  File "/scratch/cnt0024/hmg2840/albert7a/anaconda3/lib/python3.7/site-packages/tornado/gen.py", line 736, in run
    yielded = self.gen.throw(*exc_info)  # type: ignore
  File "/scratch/cnt0024/hmg2840/albert7a/anaconda3/lib/python3.7/site-packages/distributed/nanny.py", line 224, in _start
    response = yield self.instantiate()
  File "/scratch/cnt0024/hmg2840/albert7a/anaconda3/lib/python3.7/site-packages/tornado/gen.py", line 729, in run
    value = future.result()
  File "/scratch/cnt0024/hmg2840/albert7a/anaconda3/lib/python3.7/site-packages/tornado/gen.py", line 742, in run
    yielded = self.gen.send(value)
  File "/scratch/cnt0024/hmg2840/albert7a/anaconda3/lib/python3.7/site-packages/distributed/nanny.py", line 303, in instantiate
    timedelta(seconds=self.death_timeout), self.process.start()
  File "/scratch/cnt0024/hmg2840/albert7a/anaconda3/lib/python3.7/site-packages/tornado/gen.py", line 729, in run
    value = future.result()
tornado.util.TimeoutError: Timeout
tornado.application - ERROR - Multiple exceptions in yield list
Traceback (most recent call last):
  File "/scratch/cnt0024/hmg2840/albert7a/anaconda3/lib/python3.7/site-packages/tornado/gen.py", line 501, in callback
    result_list.append(f.result())
  File "/scratch/cnt0024/hmg2840/albert7a/anaconda3/lib/python3.7/asyncio/tasks.py", line 603, in _wrap_awaitable
    return (yield from awaitable.__await__())
  File "/scratch/cnt0024/hmg2840/albert7a/anaconda3/lib/python3.7/site-packages/tornado/gen.py", line 736, in run
    yielded = self.gen.throw(*exc_info)  # type: ignore
  File "/scratch/cnt0024/hmg2840/albert7a/anaconda3/lib/python3.7/site-packages/distributed/nanny.py", line 224, in _start
    response = yield self.instantiate()
  File "/scratch/cnt0024/hmg2840/albert7a/anaconda3/lib/python3.7/site-packages/tornado/gen.py", line 729, in run
    value = future.result()
  File "/scratch/cnt0024/hmg2840/albert7a/anaconda3/lib/python3.7/site-packages/tornado/gen.py", line 742, in run
    yielded = self.gen.send(value)
  File "/scratch/cnt0024/hmg2840/albert7a/anaconda3/lib/python3.7/site-packages/distributed/nanny.py", line 303, in instantiate
    timedelta(seconds=self.death_timeout), self.process.start()
  File "/scratch/cnt0024/hmg2840/albert7a/anaconda3/lib/python3.7/site-packages/tornado/gen.py", line 729, in run
    value = future.result()
tornado.util.TimeoutError: Timeout
tornado.application - ERROR - Multiple exceptions in yield list
Traceback (most recent call last):
  File "/scratch/cnt0024/hmg2840/albert7a/anaconda3/lib/python3.7/site-packages/tornado/gen.py", line 501, in callback
    result_list.append(f.result())
  File "/scratch/cnt0024/hmg2840/albert7a/anaconda3/lib/python3.7/asyncio/tasks.py", line 603, in _wrap_awaitable
    return (yield from awaitable.__await__())
  File "/scratch/cnt0024/hmg2840/albert7a/anaconda3/lib/python3.7/site-packages/tornado/gen.py", line 736, in run
    yielded = self.gen.throw(*exc_info)  # type: ignore
  File "/scratch/cnt0024/hmg2840/albert7a/anaconda3/lib/python3.7/site-packages/distributed/nanny.py", line 224, in _start
    response = yield self.instantiate()
  File "/scratch/cnt0024/hmg2840/albert7a/anaconda3/lib/python3.7/site-packages/tornado/gen.py", line 729, in run
    value = future.result()
  File "/scratch/cnt0024/hmg2840/albert7a/anaconda3/lib/python3.7/site-packages/tornado/gen.py", line 742, in run
    yielded = self.gen.send(value)
  File "/scratch/cnt0024/hmg2840/albert7a/anaconda3/lib/python3.7/site-packages/distributed/nanny.py", line 303, in instantiate
    timedelta(seconds=self.death_timeout), self.process.start()
  File "/scratch/cnt0024/hmg2840/albert7a/anaconda3/lib/python3.7/site-packages/tornado/gen.py", line 729, in run
    value = future.result()
tornado.util.TimeoutError: Timeout
tornado.application - ERROR - Multiple exceptions in yield list
Traceback (most recent call last):
  File "/scratch/cnt0024/hmg2840/albert7a/anaconda3/lib/python3.7/site-packages/tornado/gen.py", line 501, in callback
    result_list.append(f.result())
  File "/scratch/cnt0024/hmg2840/albert7a/anaconda3/lib/python3.7/asyncio/tasks.py", line 603, in _wrap_awaitable
    return (yield from awaitable.__await__())
  File "/scratch/cnt0024/hmg2840/albert7a/anaconda3/lib/python3.7/site-packages/tornado/gen.py", line 736, in run
    yielded = self.gen.throw(*exc_info)  # type: ignore
  File "/scratch/cnt0024/hmg2840/albert7a/anaconda3/lib/python3.7/site-packages/distributed/nanny.py", line 224, in _start
    response = yield self.instantiate()
  File "/scratch/cnt0024/hmg2840/albert7a/anaconda3/lib/python3.7/site-packages/tornado/gen.py", line 729, in run
    value = future.result()
  File "/scratch/cnt0024/hmg2840/albert7a/anaconda3/lib/python3.7/site-packages/tornado/gen.py", line 742, in run
    yielded = self.gen.send(value)
  File "/scratch/cnt0024/hmg2840/albert7a/anaconda3/lib/python3.7/site-packages/distributed/nanny.py", line 303, in instantiate
    timedelta(seconds=self.death_timeout), self.process.start()
  File "/scratch/cnt0024/hmg2840/albert7a/anaconda3/lib/python3.7/site-packages/tornado/gen.py", line 729, in run
    value = future.result()
tornado.util.TimeoutError: Timeout
tornado.application - ERROR - Multiple exceptions in yield list
Traceback (most recent call last):
  File "/scratch/cnt0024/hmg2840/albert7a/anaconda3/lib/python3.7/site-packages/tornado/gen.py", line 501, in callback
    result_list.append(f.result())
  File "/scratch/cnt0024/hmg2840/albert7a/anaconda3/lib/python3.7/asyncio/tasks.py", line 603, in _wrap_awaitable
    return (yield from awaitable.__await__())
  File "/scratch/cnt0024/hmg2840/albert7a/anaconda3/lib/python3.7/site-packages/tornado/gen.py", line 736, in run
    yielded = self.gen.throw(*exc_info)  # type: ignore
  File "/scratch/cnt0024/hmg2840/albert7a/anaconda3/lib/python3.7/site-packages/distributed/nanny.py", line 224, in _start
    response = yield self.instantiate()
  File "/scratch/cnt0024/hmg2840/albert7a/anaconda3/lib/python3.7/site-packages/tornado/gen.py", line 729, in run
    value = future.result()
  File "/scratch/cnt0024/hmg2840/albert7a/anaconda3/lib/python3.7/site-packages/tornado/gen.py", line 742, in run
    yielded = self.gen.send(value)
  File "/scratch/cnt0024/hmg2840/albert7a/anaconda3/lib/python3.7/site-packages/distributed/nanny.py", line 303, in instantiate
    timedelta(seconds=self.death_timeout), self.process.start()
  File "/scratch/cnt0024/hmg2840/albert7a/anaconda3/lib/python3.7/site-packages/tornado/gen.py", line 729, in run
    value = future.result()
tornado.util.TimeoutError: Timeout
tornado.application - ERROR - Multiple exceptions in yield list
Traceback (most recent call last):
  File "/scratch/cnt0024/hmg2840/albert7a/anaconda3/lib/python3.7/site-packages/tornado/gen.py", line 501, in callback
    result_list.append(f.result())
  File "/scratch/cnt0024/hmg2840/albert7a/anaconda3/lib/python3.7/asyncio/tasks.py", line 603, in _wrap_awaitable
    return (yield from awaitable.__await__())
  File "/scratch/cnt0024/hmg2840/albert7a/anaconda3/lib/python3.7/site-packages/tornado/gen.py", line 736, in run
    yielded = self.gen.throw(*exc_info)  # type: ignore
  File "/scratch/cnt0024/hmg2840/albert7a/anaconda3/lib/python3.7/site-packages/distributed/nanny.py", line 224, in _start
    response = yield self.instantiate()
  File "/scratch/cnt0024/hmg2840/albert7a/anaconda3/lib/python3.7/site-packages/tornado/gen.py", line 729, in run
    value = future.result()
  File "/scratch/cnt0024/hmg2840/albert7a/anaconda3/lib/python3.7/site-packages/tornado/gen.py", line 742, in run
    yielded = self.gen.send(value)
  File "/scratch/cnt0024/hmg2840/albert7a/anaconda3/lib/python3.7/site-packages/distributed/nanny.py", line 303, in instantiate
    timedelta(seconds=self.death_timeout), self.process.start()
  File "/scratch/cnt0024/hmg2840/albert7a/anaconda3/lib/python3.7/site-packages/tornado/gen.py", line 729, in run
    value = future.result()
tornado.util.TimeoutError: Timeout
tornado.application - ERROR - Multiple exceptions in yield list
Traceback (most recent call last):
  File "/scratch/cnt0024/hmg2840/albert7a/anaconda3/lib/python3.7/site-packages/tornado/gen.py", line 501, in callback
    result_list.append(f.result())
  File "/scratch/cnt0024/hmg2840/albert7a/anaconda3/lib/python3.7/asyncio/tasks.py", line 603, in _wrap_awaitable
    return (yield from awaitable.__await__())
  File "/scratch/cnt0024/hmg2840/albert7a/anaconda3/lib/python3.7/site-packages/tornado/gen.py", line 736, in run
    yielded = self.gen.throw(*exc_info)  # type: ignore
  File "/scratch/cnt0024/hmg2840/albert7a/anaconda3/lib/python3.7/site-packages/distributed/nanny.py", line 224, in _start
    response = yield self.instantiate()
  File "/scratch/cnt0024/hmg2840/albert7a/anaconda3/lib/python3.7/site-packages/tornado/gen.py", line 729, in run
    value = future.result()
  File "/scratch/cnt0024/hmg2840/albert7a/anaconda3/lib/python3.7/site-packages/tornado/gen.py", line 742, in run
    yielded = self.gen.send(value)
  File "/scratch/cnt0024/hmg2840/albert7a/anaconda3/lib/python3.7/site-packages/distributed/nanny.py", line 303, in instantiate
    timedelta(seconds=self.death_timeout), self.process.start()
  File "/scratch/cnt0024/hmg2840/albert7a/anaconda3/lib/python3.7/site-packages/tornado/gen.py", line 729, in run
    value = future.result()
tornado.util.TimeoutError: Timeout
tornado.application - ERROR - Multiple exceptions in yield list
Traceback (most recent call last):
  File "/scratch/cnt0024/hmg2840/albert7a/anaconda3/lib/python3.7/site-packages/tornado/gen.py", line 501, in callback
    result_list.append(f.result())
  File "/scratch/cnt0024/hmg2840/albert7a/anaconda3/lib/python3.7/asyncio/tasks.py", line 603, in _wrap_awaitable
    return (yield from awaitable.__await__())
  File "/scratch/cnt0024/hmg2840/albert7a/anaconda3/lib/python3.7/site-packages/tornado/gen.py", line 736, in run
    yielded = self.gen.throw(*exc_info)  # type: ignore
  File "/scratch/cnt0024/hmg2840/albert7a/anaconda3/lib/python3.7/site-packages/distributed/nanny.py", line 224, in _start
    response = yield self.instantiate()
  File "/scratch/cnt0024/hmg2840/albert7a/anaconda3/lib/python3.7/site-packages/tornado/gen.py", line 729, in run
    value = future.result()
  File "/scratch/cnt0024/hmg2840/albert7a/anaconda3/lib/python3.7/site-packages/tornado/gen.py", line 742, in run
    yielded = self.gen.send(value)
  File "/scratch/cnt0024/hmg2840/albert7a/anaconda3/lib/python3.7/site-packages/distributed/nanny.py", line 303, in instantiate
    timedelta(seconds=self.death_timeout), self.process.start()
  File "/scratch/cnt0024/hmg2840/albert7a/anaconda3/lib/python3.7/site-packages/tornado/gen.py", line 729, in run
    value = future.result()
tornado.util.TimeoutError: Timeout
tornado.application - ERROR - Multiple exceptions in yield list
Traceback (most recent call last):
  File "/scratch/cnt0024/hmg2840/albert7a/anaconda3/lib/python3.7/site-packages/tornado/gen.py", line 501, in callback
    result_list.append(f.result())
  File "/scratch/cnt0024/hmg2840/albert7a/anaconda3/lib/python3.7/asyncio/tasks.py", line 603, in _wrap_awaitable
    return (yield from awaitable.__await__())
  File "/scratch/cnt0024/hmg2840/albert7a/anaconda3/lib/python3.7/site-packages/tornado/gen.py", line 736, in run
    yielded = self.gen.throw(*exc_info)  # type: ignore
  File "/scratch/cnt0024/hmg2840/albert7a/anaconda3/lib/python3.7/site-packages/distributed/nanny.py", line 224, in _start
    response = yield self.instantiate()
  File "/scratch/cnt0024/hmg2840/albert7a/anaconda3/lib/python3.7/site-packages/tornado/gen.py", line 729, in run
    value = future.result()
  File "/scratch/cnt0024/hmg2840/albert7a/anaconda3/lib/python3.7/site-packages/tornado/gen.py", line 742, in run
    yielded = self.gen.send(value)
  File "/scratch/cnt0024/hmg2840/albert7a/anaconda3/lib/python3.7/site-packages/distributed/nanny.py", line 303, in instantiate
    timedelta(seconds=self.death_timeout), self.process.start()
  File "/scratch/cnt0024/hmg2840/albert7a/anaconda3/lib/python3.7/site-packages/tornado/gen.py", line 729, in run
    value = future.result()
tornado.util.TimeoutError: Timeout
tornado.application - ERROR - Multiple exceptions in yield list
Traceback (most recent call last):
  File "/scratch/cnt0024/hmg2840/albert7a/anaconda3/lib/python3.7/site-packages/tornado/gen.py", line 501, in callback
    result_list.append(f.result())
  File "/scratch/cnt0024/hmg2840/albert7a/anaconda3/lib/python3.7/asyncio/tasks.py", line 603, in _wrap_awaitable
    return (yield from awaitable.__await__())
  File "/scratch/cnt0024/hmg2840/albert7a/anaconda3/lib/python3.7/site-packages/tornado/gen.py", line 736, in run
    yielded = self.gen.throw(*exc_info)  # type: ignore
  File "/scratch/cnt0024/hmg2840/albert7a/anaconda3/lib/python3.7/site-packages/distributed/nanny.py", line 224, in _start
    response = yield self.instantiate()
  File "/scratch/cnt0024/hmg2840/albert7a/anaconda3/lib/python3.7/site-packages/tornado/gen.py", line 729, in run
    value = future.result()
  File "/scratch/cnt0024/hmg2840/albert7a/anaconda3/lib/python3.7/site-packages/tornado/gen.py", line 742, in run
    yielded = self.gen.send(value)
  File "/scratch/cnt0024/hmg2840/albert7a/anaconda3/lib/python3.7/site-packages/distributed/nanny.py", line 303, in instantiate
    timedelta(seconds=self.death_timeout), self.process.start()
  File "/scratch/cnt0024/hmg2840/albert7a/anaconda3/lib/python3.7/site-packages/tornado/gen.py", line 729, in run
    value = future.result()
tornado.util.TimeoutError: Timeout
tornado.application - ERROR - Multiple exceptions in yield list
Traceback (most recent call last):
  File "/scratch/cnt0024/hmg2840/albert7a/anaconda3/lib/python3.7/site-packages/tornado/gen.py", line 501, in callback
    result_list.append(f.result())
  File "/scratch/cnt0024/hmg2840/albert7a/anaconda3/lib/python3.7/asyncio/tasks.py", line 603, in _wrap_awaitable
    return (yield from awaitable.__await__())
  File "/scratch/cnt0024/hmg2840/albert7a/anaconda3/lib/python3.7/site-packages/tornado/gen.py", line 736, in run
    yielded = self.gen.throw(*exc_info)  # type: ignore
  File "/scratch/cnt0024/hmg2840/albert7a/anaconda3/lib/python3.7/site-packages/distributed/nanny.py", line 224, in _start
    response = yield self.instantiate()
  File "/scratch/cnt0024/hmg2840/albert7a/anaconda3/lib/python3.7/site-packages/tornado/gen.py", line 729, in run
    value = future.result()
  File "/scratch/cnt0024/hmg2840/albert7a/anaconda3/lib/python3.7/site-packages/tornado/gen.py", line 742, in run
    yielded = self.gen.send(value)
  File "/scratch/cnt0024/hmg2840/albert7a/anaconda3/lib/python3.7/site-packages/distributed/nanny.py", line 303, in instantiate
    timedelta(seconds=self.death_timeout), self.process.start()
  File "/scratch/cnt0024/hmg2840/albert7a/anaconda3/lib/python3.7/site-packages/tornado/gen.py", line 729, in run
    value = future.result()
tornado.util.TimeoutError: Timeout
tornado.application - ERROR - Multiple exceptions in yield list
Traceback (most recent call last):
  File "/scratch/cnt0024/hmg2840/albert7a/anaconda3/lib/python3.7/site-packages/tornado/gen.py", line 501, in callback
    result_list.append(f.result())
  File "/scratch/cnt0024/hmg2840/albert7a/anaconda3/lib/python3.7/asyncio/tasks.py", line 603, in _wrap_awaitable
    return (yield from awaitable.__await__())
  File "/scratch/cnt0024/hmg2840/albert7a/anaconda3/lib/python3.7/site-packages/tornado/gen.py", line 736, in run
    yielded = self.gen.throw(*exc_info)  # type: ignore
  File "/scratch/cnt0024/hmg2840/albert7a/anaconda3/lib/python3.7/site-packages/distributed/nanny.py", line 224, in _start
    response = yield self.instantiate()
  File "/scratch/cnt0024/hmg2840/albert7a/anaconda3/lib/python3.7/site-packages/tornado/gen.py", line 729, in run
    value = future.result()
  File "/scratch/cnt0024/hmg2840/albert7a/anaconda3/lib/python3.7/site-packages/tornado/gen.py", line 742, in run
    yielded = self.gen.send(value)
  File "/scratch/cnt0024/hmg2840/albert7a/anaconda3/lib/python3.7/site-packages/distributed/nanny.py", line 303, in instantiate
    timedelta(seconds=self.death_timeout), self.process.start()
  File "/scratch/cnt0024/hmg2840/albert7a/anaconda3/lib/python3.7/site-packages/tornado/gen.py", line 729, in run
    value = future.result()
tornado.util.TimeoutError: Timeout
tornado.application - ERROR - Multiple exceptions in yield list
Traceback (most recent call last):
  File "/scratch/cnt0024/hmg2840/albert7a/anaconda3/lib/python3.7/site-packages/tornado/gen.py", line 501, in callback
    result_list.append(f.result())
  File "/scratch/cnt0024/hmg2840/albert7a/anaconda3/lib/python3.7/asyncio/tasks.py", line 603, in _wrap_awaitable
    return (yield from awaitable.__await__())
  File "/scratch/cnt0024/hmg2840/albert7a/anaconda3/lib/python3.7/site-packages/tornado/gen.py", line 736, in run
    yielded = self.gen.throw(*exc_info)  # type: ignore
  File "/scratch/cnt0024/hmg2840/albert7a/anaconda3/lib/python3.7/site-packages/distributed/nanny.py", line 224, in _start
    response = yield self.instantiate()
  File "/scratch/cnt0024/hmg2840/albert7a/anaconda3/lib/python3.7/site-packages/tornado/gen.py", line 729, in run
    value = future.result()
  File "/scratch/cnt0024/hmg2840/albert7a/anaconda3/lib/python3.7/site-packages/tornado/gen.py", line 742, in run
    yielded = self.gen.send(value)
  File "/scratch/cnt0024/hmg2840/albert7a/anaconda3/lib/python3.7/site-packages/distributed/nanny.py", line 303, in instantiate
    timedelta(seconds=self.death_timeout), self.process.start()
  File "/scratch/cnt0024/hmg2840/albert7a/anaconda3/lib/python3.7/site-packages/tornado/gen.py", line 729, in run
    value = future.result()
tornado.util.TimeoutError: Timeout
tornado.application - ERROR - Multiple exceptions in yield list
Traceback (most recent call last):
  File "/scratch/cnt0024/hmg2840/albert7a/anaconda3/lib/python3.7/site-packages/tornado/gen.py", line 501, in callback
    result_list.append(f.result())
  File "/scratch/cnt0024/hmg2840/albert7a/anaconda3/lib/python3.7/asyncio/tasks.py", line 603, in _wrap_awaitable
    return (yield from awaitable.__await__())
  File "/scratch/cnt0024/hmg2840/albert7a/anaconda3/lib/python3.7/site-packages/tornado/gen.py", line 736, in run
    yielded = self.gen.throw(*exc_info)  # type: ignore
  File "/scratch/cnt0024/hmg2840/albert7a/anaconda3/lib/python3.7/site-packages/distributed/nanny.py", line 224, in _start
    response = yield self.instantiate()
  File "/scratch/cnt0024/hmg2840/albert7a/anaconda3/lib/python3.7/site-packages/tornado/gen.py", line 729, in run
    value = future.result()
  File "/scratch/cnt0024/hmg2840/albert7a/anaconda3/lib/python3.7/site-packages/tornado/gen.py", line 742, in run
    yielded = self.gen.send(value)
  File "/scratch/cnt0024/hmg2840/albert7a/anaconda3/lib/python3.7/site-packages/distributed/nanny.py", line 303, in instantiate
    timedelta(seconds=self.death_timeout), self.process.start()
  File "/scratch/cnt0024/hmg2840/albert7a/anaconda3/lib/python3.7/site-packages/tornado/gen.py", line 729, in run
    value = future.result()
tornado.util.TimeoutError: Timeout
tornado.application - ERROR - Multiple exceptions in yield list
Traceback (most recent call last):
  File "/scratch/cnt0024/hmg2840/albert7a/anaconda3/lib/python3.7/site-packages/tornado/gen.py", line 501, in callback
    result_list.append(f.result())
  File "/scratch/cnt0024/hmg2840/albert7a/anaconda3/lib/python3.7/asyncio/tasks.py", line 603, in _wrap_awaitable
    return (yield from awaitable.__await__())
  File "/scratch/cnt0024/hmg2840/albert7a/anaconda3/lib/python3.7/site-packages/tornado/gen.py", line 736, in run
    yielded = self.gen.throw(*exc_info)  # type: ignore
  File "/scratch/cnt0024/hmg2840/albert7a/anaconda3/lib/python3.7/site-packages/distributed/nanny.py", line 224, in _start
    response = yield self.instantiate()
  File "/scratch/cnt0024/hmg2840/albert7a/anaconda3/lib/python3.7/site-packages/tornado/gen.py", line 729, in run
    value = future.result()
  File "/scratch/cnt0024/hmg2840/albert7a/anaconda3/lib/python3.7/site-packages/tornado/gen.py", line 742, in run
    yielded = self.gen.send(value)
  File "/scratch/cnt0024/hmg2840/albert7a/anaconda3/lib/python3.7/site-packages/distributed/nanny.py", line 303, in instantiate
    timedelta(seconds=self.death_timeout), self.process.start()
  File "/scratch/cnt0024/hmg2840/albert7a/anaconda3/lib/python3.7/site-packages/tornado/gen.py", line 729, in run
    value = future.result()
tornado.util.TimeoutError: Timeout
tornado.application - ERROR - Multiple exceptions in yield list
Traceback (most recent call last):
  File "/scratch/cnt0024/hmg2840/albert7a/anaconda3/lib/python3.7/site-packages/tornado/gen.py", line 501, in callback
    result_list.append(f.result())
  File "/scratch/cnt0024/hmg2840/albert7a/anaconda3/lib/python3.7/asyncio/tasks.py", line 603, in _wrap_awaitable
    return (yield from awaitable.__await__())
  File "/scratch/cnt0024/hmg2840/albert7a/anaconda3/lib/python3.7/site-packages/tornado/gen.py", line 736, in run
    yielded = self.gen.throw(*exc_info)  # type: ignore
  File "/scratch/cnt0024/hmg2840/albert7a/anaconda3/lib/python3.7/site-packages/distributed/nanny.py", line 224, in _start
    response = yield self.instantiate()
  File "/scratch/cnt0024/hmg2840/albert7a/anaconda3/lib/python3.7/site-packages/tornado/gen.py", line 729, in run
    value = future.result()
  File "/scratch/cnt0024/hmg2840/albert7a/anaconda3/lib/python3.7/site-packages/tornado/gen.py", line 742, in run
    yielded = self.gen.send(value)
  File "/scratch/cnt0024/hmg2840/albert7a/anaconda3/lib/python3.7/site-packages/distributed/nanny.py", line 303, in instantiate
    timedelta(seconds=self.death_timeout), self.process.start()
  File "/scratch/cnt0024/hmg2840/albert7a/anaconda3/lib/python3.7/site-packages/tornado/gen.py", line 729, in run
    value = future.result()
tornado.util.TimeoutError: Timeout
tornado.application - ERROR - Multiple exceptions in yield list
Traceback (most recent call last):
  File "/scratch/cnt0024/hmg2840/albert7a/anaconda3/lib/python3.7/site-packages/tornado/gen.py", line 501, in callback
    result_list.append(f.result())
  File "/scratch/cnt0024/hmg2840/albert7a/anaconda3/lib/python3.7/asyncio/tasks.py", line 603, in _wrap_awaitable
    return (yield from awaitable.__await__())
  File "/scratch/cnt0024/hmg2840/albert7a/anaconda3/lib/python3.7/site-packages/tornado/gen.py", line 736, in run
    yielded = self.gen.throw(*exc_info)  # type: ignore
  File "/scratch/cnt0024/hmg2840/albert7a/anaconda3/lib/python3.7/site-packages/distributed/nanny.py", line 224, in _start
    response = yield self.instantiate()
  File "/scratch/cnt0024/hmg2840/albert7a/anaconda3/lib/python3.7/site-packages/tornado/gen.py", line 729, in run
    value = future.result()
  File "/scratch/cnt0024/hmg2840/albert7a/anaconda3/lib/python3.7/site-packages/tornado/gen.py", line 742, in run
    yielded = self.gen.send(value)
  File "/scratch/cnt0024/hmg2840/albert7a/anaconda3/lib/python3.7/site-packages/distributed/nanny.py", line 303, in instantiate
    timedelta(seconds=self.death_timeout), self.process.start()
  File "/scratch/cnt0024/hmg2840/albert7a/anaconda3/lib/python3.7/site-packages/tornado/gen.py", line 729, in run
    value = future.result()
tornado.util.TimeoutError: Timeout
tornado.application - ERROR - Multiple exceptions in yield list
Traceback (most recent call last):
  File "/scratch/cnt0024/hmg2840/albert7a/anaconda3/lib/python3.7/site-packages/tornado/gen.py", line 501, in callback
    result_list.append(f.result())
  File "/scratch/cnt0024/hmg2840/albert7a/anaconda3/lib/python3.7/asyncio/tasks.py", line 603, in _wrap_awaitable
    return (yield from awaitable.__await__())
  File "/scratch/cnt0024/hmg2840/albert7a/anaconda3/lib/python3.7/site-packages/tornado/gen.py", line 736, in run
    yielded = self.gen.throw(*exc_info)  # type: ignore
  File "/scratch/cnt0024/hmg2840/albert7a/anaconda3/lib/python3.7/site-packages/distributed/nanny.py", line 224, in _start
    response = yield self.instantiate()
  File "/scratch/cnt0024/hmg2840/albert7a/anaconda3/lib/python3.7/site-packages/tornado/gen.py", line 729, in run
    value = future.result()
  File "/scratch/cnt0024/hmg2840/albert7a/anaconda3/lib/python3.7/site-packages/tornado/gen.py", line 742, in run
    yielded = self.gen.send(value)
  File "/scratch/cnt0024/hmg2840/albert7a/anaconda3/lib/python3.7/site-packages/distributed/nanny.py", line 303, in instantiate
    timedelta(seconds=self.death_timeout), self.process.start()
  File "/scratch/cnt0024/hmg2840/albert7a/anaconda3/lib/python3.7/site-packages/tornado/gen.py", line 729, in run
    value = future.result()
tornado.util.TimeoutError: Timeout
tornado.application - ERROR - Multiple exceptions in yield list
Traceback (most recent call last):
  File "/scratch/cnt0024/hmg2840/albert7a/anaconda3/lib/python3.7/site-packages/tornado/gen.py", line 501, in callback
    result_list.append(f.result())
  File "/scratch/cnt0024/hmg2840/albert7a/anaconda3/lib/python3.7/asyncio/tasks.py", line 603, in _wrap_awaitable
    return (yield from awaitable.__await__())
  File "/scratch/cnt0024/hmg2840/albert7a/anaconda3/lib/python3.7/site-packages/tornado/gen.py", line 736, in run
    yielded = self.gen.throw(*exc_info)  # type: ignore
  File "/scratch/cnt0024/hmg2840/albert7a/anaconda3/lib/python3.7/site-packages/distributed/nanny.py", line 224, in _start
    response = yield self.instantiate()
  File "/scratch/cnt0024/hmg2840/albert7a/anaconda3/lib/python3.7/site-packages/tornado/gen.py", line 729, in run
    value = future.result()
  File "/scratch/cnt0024/hmg2840/albert7a/anaconda3/lib/python3.7/site-packages/tornado/gen.py", line 742, in run
    yielded = self.gen.send(value)
  File "/scratch/cnt0024/hmg2840/albert7a/anaconda3/lib/python3.7/site-packages/distributed/nanny.py", line 303, in instantiate
    timedelta(seconds=self.death_timeout), self.process.start()
  File "/scratch/cnt0024/hmg2840/albert7a/anaconda3/lib/python3.7/site-packages/tornado/gen.py", line 729, in run
    value = future.result()
tornado.util.TimeoutError: Timeout
tornado.application - ERROR - Multiple exceptions in yield list
Traceback (most recent call last):
  File "/scratch/cnt0024/hmg2840/albert7a/anaconda3/lib/python3.7/site-packages/tornado/gen.py", line 501, in callback
    result_list.append(f.result())
  File "/scratch/cnt0024/hmg2840/albert7a/anaconda3/lib/python3.7/asyncio/tasks.py", line 603, in _wrap_awaitable
    return (yield from awaitable.__await__())
  File "/scratch/cnt0024/hmg2840/albert7a/anaconda3/lib/python3.7/site-packages/tornado/gen.py", line 736, in run
    yielded = self.gen.throw(*exc_info)  # type: ignore
  File "/scratch/cnt0024/hmg2840/albert7a/anaconda3/lib/python3.7/site-packages/distributed/nanny.py", line 224, in _start
    response = yield self.instantiate()
  File "/scratch/cnt0024/hmg2840/albert7a/anaconda3/lib/python3.7/site-packages/tornado/gen.py", line 729, in run
    value = future.result()
  File "/scratch/cnt0024/hmg2840/albert7a/anaconda3/lib/python3.7/site-packages/tornado/gen.py", line 742, in run
    yielded = self.gen.send(value)
  File "/scratch/cnt0024/hmg2840/albert7a/anaconda3/lib/python3.7/site-packages/distributed/nanny.py", line 303, in instantiate
    timedelta(seconds=self.death_timeout), self.process.start()
  File "/scratch/cnt0024/hmg2840/albert7a/anaconda3/lib/python3.7/site-packages/tornado/gen.py", line 729, in run
    value = future.result()
tornado.util.TimeoutError: Timeout
tornado.application - ERROR - Multiple exceptions in yield list
Traceback (most recent call last):
  File "/scratch/cnt0024/hmg2840/albert7a/anaconda3/lib/python3.7/site-packages/tornado/gen.py", line 501, in callback
    result_list.append(f.result())
  File "/scratch/cnt0024/hmg2840/albert7a/anaconda3/lib/python3.7/asyncio/tasks.py", line 603, in _wrap_awaitable
    return (yield from awaitable.__await__())
  File "/scratch/cnt0024/hmg2840/albert7a/anaconda3/lib/python3.7/site-packages/tornado/gen.py", line 736, in run
    yielded = self.gen.throw(*exc_info)  # type: ignore
  File "/scratch/cnt0024/hmg2840/albert7a/anaconda3/lib/python3.7/site-packages/distributed/nanny.py", line 224, in _start
    response = yield self.instantiate()
  File "/scratch/cnt0024/hmg2840/albert7a/anaconda3/lib/python3.7/site-packages/tornado/gen.py", line 729, in run
    value = future.result()
  File "/scratch/cnt0024/hmg2840/albert7a/anaconda3/lib/python3.7/site-packages/tornado/gen.py", line 742, in run
    yielded = self.gen.send(value)
  File "/scratch/cnt0024/hmg2840/albert7a/anaconda3/lib/python3.7/site-packages/distributed/nanny.py", line 303, in instantiate
    timedelta(seconds=self.death_timeout), self.process.start()
  File "/scratch/cnt0024/hmg2840/albert7a/anaconda3/lib/python3.7/site-packages/tornado/gen.py", line 729, in run
    value = future.result()
tornado.util.TimeoutError: Timeout
tornado.application - ERROR - Multiple exceptions in yield list
Traceback (most recent call last):
  File "/scratch/cnt0024/hmg2840/albert7a/anaconda3/lib/python3.7/site-packages/tornado/gen.py", line 501, in callback
    result_list.append(f.result())
  File "/scratch/cnt0024/hmg2840/albert7a/anaconda3/lib/python3.7/asyncio/tasks.py", line 603, in _wrap_awaitable
    return (yield from awaitable.__await__())
  File "/scratch/cnt0024/hmg2840/albert7a/anaconda3/lib/python3.7/site-packages/tornado/gen.py", line 736, in run
    yielded = self.gen.throw(*exc_info)  # type: ignore
  File "/scratch/cnt0024/hmg2840/albert7a/anaconda3/lib/python3.7/site-packages/distributed/nanny.py", line 224, in _start
    response = yield self.instantiate()
  File "/scratch/cnt0024/hmg2840/albert7a/anaconda3/lib/python3.7/site-packages/tornado/gen.py", line 729, in run
    value = future.result()
  File "/scratch/cnt0024/hmg2840/albert7a/anaconda3/lib/python3.7/site-packages/tornado/gen.py", line 742, in run
    yielded = self.gen.send(value)
  File "/scratch/cnt0024/hmg2840/albert7a/anaconda3/lib/python3.7/site-packages/distributed/nanny.py", line 303, in instantiate
    timedelta(seconds=self.death_timeout), self.process.start()
  File "/scratch/cnt0024/hmg2840/albert7a/anaconda3/lib/python3.7/site-packages/tornado/gen.py", line 729, in run
    value = future.result()
tornado.util.TimeoutError: Timeout
tornado.application - ERROR - Multiple exceptions in yield list
Traceback (most recent call last):
  File "/scratch/cnt0024/hmg2840/albert7a/anaconda3/lib/python3.7/site-packages/tornado/gen.py", line 501, in callback
    result_list.append(f.result())
  File "/scratch/cnt0024/hmg2840/albert7a/anaconda3/lib/python3.7/asyncio/tasks.py", line 603, in _wrap_awaitable
    return (yield from awaitable.__await__())
  File "/scratch/cnt0024/hmg2840/albert7a/anaconda3/lib/python3.7/site-packages/tornado/gen.py", line 736, in run
    yielded = self.gen.throw(*exc_info)  # type: ignore
  File "/scratch/cnt0024/hmg2840/albert7a/anaconda3/lib/python3.7/site-packages/distributed/nanny.py", line 224, in _start
    response = yield self.instantiate()
  File "/scratch/cnt0024/hmg2840/albert7a/anaconda3/lib/python3.7/site-packages/tornado/gen.py", line 729, in run
    value = future.result()
  File "/scratch/cnt0024/hmg2840/albert7a/anaconda3/lib/python3.7/site-packages/tornado/gen.py", line 742, in run
    yielded = self.gen.send(value)
  File "/scratch/cnt0024/hmg2840/albert7a/anaconda3/lib/python3.7/site-packages/distributed/nanny.py", line 303, in instantiate
    timedelta(seconds=self.death_timeout), self.process.start()
  File "/scratch/cnt0024/hmg2840/albert7a/anaconda3/lib/python3.7/site-packages/tornado/gen.py", line 729, in run
    value = future.result()
tornado.util.TimeoutError: Timeout
tornado.application - ERROR - Multiple exceptions in yield list
Traceback (most recent call last):
  File "/scratch/cnt0024/hmg2840/albert7a/anaconda3/lib/python3.7/site-packages/tornado/gen.py", line 501, in callback
    result_list.append(f.result())
  File "/scratch/cnt0024/hmg2840/albert7a/anaconda3/lib/python3.7/asyncio/tasks.py", line 603, in _wrap_awaitable
    return (yield from awaitable.__await__())
  File "/scratch/cnt0024/hmg2840/albert7a/anaconda3/lib/python3.7/site-packages/tornado/gen.py", line 736, in run
    yielded = self.gen.throw(*exc_info)  # type: ignore
  File "/scratch/cnt0024/hmg2840/albert7a/anaconda3/lib/python3.7/site-packages/distributed/nanny.py", line 224, in _start
    response = yield self.instantiate()
  File "/scratch/cnt0024/hmg2840/albert7a/anaconda3/lib/python3.7/site-packages/tornado/gen.py", line 729, in run
    value = future.result()
  File "/scratch/cnt0024/hmg2840/albert7a/anaconda3/lib/python3.7/site-packages/tornado/gen.py", line 742, in run
    yielded = self.gen.send(value)
  File "/scratch/cnt0024/hmg2840/albert7a/anaconda3/lib/python3.7/site-packages/distributed/nanny.py", line 303, in instantiate
    timedelta(seconds=self.death_timeout), self.process.start()
  File "/scratch/cnt0024/hmg2840/albert7a/anaconda3/lib/python3.7/site-packages/tornado/gen.py", line 729, in run
    value = future.result()
tornado.util.TimeoutError: Timeout
tornado.application - ERROR - Multiple exceptions in yield list
Traceback (most recent call last):
  File "/scratch/cnt0024/hmg2840/albert7a/anaconda3/lib/python3.7/site-packages/tornado/gen.py", line 501, in callback
    result_list.append(f.result())
  File "/scratch/cnt0024/hmg2840/albert7a/anaconda3/lib/python3.7/asyncio/tasks.py", line 603, in _wrap_awaitable
    return (yield from awaitable.__await__())
  File "/scratch/cnt0024/hmg2840/albert7a/anaconda3/lib/python3.7/site-packages/tornado/gen.py", line 736, in run
    yielded = self.gen.throw(*exc_info)  # type: ignore
  File "/scratch/cnt0024/hmg2840/albert7a/anaconda3/lib/python3.7/site-packages/distributed/nanny.py", line 224, in _start
    response = yield self.instantiate()
  File "/scratch/cnt0024/hmg2840/albert7a/anaconda3/lib/python3.7/site-packages/tornado/gen.py", line 729, in run
    value = future.result()
  File "/scratch/cnt0024/hmg2840/albert7a/anaconda3/lib/python3.7/site-packages/tornado/gen.py", line 742, in run
    yielded = self.gen.send(value)
  File "/scratch/cnt0024/hmg2840/albert7a/anaconda3/lib/python3.7/site-packages/distributed/nanny.py", line 303, in instantiate
    timedelta(seconds=self.death_timeout), self.process.start()
  File "/scratch/cnt0024/hmg2840/albert7a/anaconda3/lib/python3.7/site-packages/tornado/gen.py", line 729, in run
    value = future.result()
tornado.util.TimeoutError: Timeout
distributed.dask_worker - INFO - End worker
Traceback (most recent call last):
  File "/scratch/cnt0024/hmg2840/albert7a/anaconda3/lib/python3.7/runpy.py", line 193, in _run_module_as_main
    "__main__", mod_spec)
  File "/scratch/cnt0024/hmg2840/albert7a/anaconda3/lib/python3.7/runpy.py", line 85, in _run_code
    exec(code, run_globals)
  File "/scratch/cnt0024/hmg2840/albert7a/anaconda3/lib/python3.7/site-packages/distributed/cli/dask_worker.py", line 405, in <module>
    go()
  File "/scratch/cnt0024/hmg2840/albert7a/anaconda3/lib/python3.7/site-packages/distributed/cli/dask_worker.py", line 401, in go
    main()
  File "/scratch/cnt0024/hmg2840/albert7a/anaconda3/lib/python3.7/site-packages/click/core.py", line 764, in __call__
    return self.main(*args, **kwargs)
  File "/scratch/cnt0024/hmg2840/albert7a/anaconda3/lib/python3.7/site-packages/click/core.py", line 717, in main
    rv = self.invoke(ctx)
  File "/scratch/cnt0024/hmg2840/albert7a/anaconda3/lib/python3.7/site-packages/click/core.py", line 956, in invoke
    return ctx.invoke(self.callback, **ctx.params)
  File "/scratch/cnt0024/hmg2840/albert7a/anaconda3/lib/python3.7/site-packages/click/core.py", line 555, in invoke
    return callback(*args, **kwargs)
  File "/scratch/cnt0024/hmg2840/albert7a/anaconda3/lib/python3.7/site-packages/distributed/cli/dask_worker.py", line 392, in main
    raise TimeoutError("Timed out starting worker.") from None
tornado.util.TimeoutError: Timed out starting worker.
/scratch/cnt0024/hmg2840/albert7a/anaconda3/lib/python3.7/site-packages/distributed/utils.py:136: RuntimeWarning: Couldn't detect a suitable IP address for reaching '8.8.8.8', defaulting to '127.0.0.1': [Errno 101] Network is unreachable
  RuntimeWarning,
