/scratch/cnt0024/hmg2840/albert7a/anaconda3/lib/python3.7/site-packages/distributed/utils.py:136: RuntimeWarning: Couldn't detect a suitable IP address for reaching '8.8.8.8', defaulting to '127.0.0.1': [Errno 101] Network is unreachable
  RuntimeWarning,
distributed.nanny - INFO -         Start Nanny at: 'tcp://172.30.8.62:45974'
distributed.nanny - INFO -         Start Nanny at: 'tcp://172.30.8.62:39474'
distributed.nanny - INFO -         Start Nanny at: 'tcp://172.30.8.62:34087'
distributed.nanny - INFO -         Start Nanny at: 'tcp://172.30.8.62:37616'
distributed.nanny - INFO -         Start Nanny at: 'tcp://172.30.8.62:36530'
distributed.nanny - INFO -         Start Nanny at: 'tcp://172.30.8.62:42362'
distributed.nanny - INFO -         Start Nanny at: 'tcp://172.30.8.62:41923'
distributed.nanny - INFO -         Start Nanny at: 'tcp://172.30.8.62:34027'
distributed.nanny - INFO -         Start Nanny at: 'tcp://172.30.8.62:36943'
distributed.nanny - INFO -         Start Nanny at: 'tcp://172.30.8.62:33467'
distributed.nanny - INFO -         Start Nanny at: 'tcp://172.30.8.62:41516'
distributed.nanny - INFO -         Start Nanny at: 'tcp://172.30.8.62:39270'
distributed.nanny - INFO -         Start Nanny at: 'tcp://172.30.8.62:36064'
distributed.nanny - INFO -         Start Nanny at: 'tcp://172.30.8.62:38771'
distributed.nanny - INFO -         Start Nanny at: 'tcp://172.30.8.62:40745'
distributed.nanny - INFO -         Start Nanny at: 'tcp://172.30.8.62:33179'
distributed.nanny - INFO -         Start Nanny at: 'tcp://172.30.8.62:43039'
distributed.nanny - INFO -         Start Nanny at: 'tcp://172.30.8.62:34297'
distributed.nanny - INFO -         Start Nanny at: 'tcp://172.30.8.62:33307'
distributed.nanny - INFO -         Start Nanny at: 'tcp://172.30.8.62:42512'
distributed.nanny - INFO -         Start Nanny at: 'tcp://172.30.8.62:36628'
distributed.nanny - INFO -         Start Nanny at: 'tcp://172.30.8.62:36058'
distributed.nanny - INFO -         Start Nanny at: 'tcp://172.30.8.62:40597'
distributed.nanny - INFO -         Start Nanny at: 'tcp://172.30.8.62:44846'
distributed.nanny - INFO -         Start Nanny at: 'tcp://172.30.8.62:43346'
distributed.nanny - INFO -         Start Nanny at: 'tcp://172.30.8.62:41028'
distributed.nanny - INFO -         Start Nanny at: 'tcp://172.30.8.62:41250'
distributed.nanny - INFO -         Start Nanny at: 'tcp://172.30.8.62:41263'
distributed.nanny - INFO - Closing Nanny at 'tcp://172.30.8.62:45974'
distributed.nanny - INFO - Closing Nanny at 'tcp://172.30.8.62:39474'
distributed.nanny - INFO - Closing Nanny at 'tcp://172.30.8.62:34087'
distributed.nanny - INFO - Closing Nanny at 'tcp://172.30.8.62:37616'
distributed.nanny - INFO - Closing Nanny at 'tcp://172.30.8.62:36530'
distributed.nanny - INFO - Closing Nanny at 'tcp://172.30.8.62:42362'
distributed.nanny - INFO - Closing Nanny at 'tcp://172.30.8.62:41923'
distributed.nanny - INFO - Closing Nanny at 'tcp://172.30.8.62:34027'
distributed.nanny - INFO - Closing Nanny at 'tcp://172.30.8.62:36943'
distributed.nanny - INFO - Closing Nanny at 'tcp://172.30.8.62:33467'
distributed.nanny - INFO - Closing Nanny at 'tcp://172.30.8.62:41516'
distributed.nanny - INFO - Closing Nanny at 'tcp://172.30.8.62:39270'
distributed.nanny - INFO - Closing Nanny at 'tcp://172.30.8.62:36064'
distributed.nanny - INFO - Closing Nanny at 'tcp://172.30.8.62:38771'
distributed.nanny - INFO - Closing Nanny at 'tcp://172.30.8.62:40745'
distributed.nanny - INFO - Closing Nanny at 'tcp://172.30.8.62:33179'
distributed.nanny - INFO - Closing Nanny at 'tcp://172.30.8.62:43039'
distributed.nanny - INFO - Closing Nanny at 'tcp://172.30.8.62:34297'
distributed.nanny - INFO - Closing Nanny at 'tcp://172.30.8.62:33307'
distributed.nanny - INFO - Closing Nanny at 'tcp://172.30.8.62:42512'
distributed.nanny - INFO - Closing Nanny at 'tcp://172.30.8.62:36628'
distributed.nanny - INFO - Closing Nanny at 'tcp://172.30.8.62:36058'
distributed.nanny - INFO - Closing Nanny at 'tcp://172.30.8.62:40597'
distributed.nanny - INFO - Closing Nanny at 'tcp://172.30.8.62:44846'
distributed.nanny - INFO - Closing Nanny at 'tcp://172.30.8.62:43346'
distributed.nanny - INFO - Closing Nanny at 'tcp://172.30.8.62:41028'
distributed.nanny - INFO - Closing Nanny at 'tcp://172.30.8.62:41250'
distributed.nanny - INFO - Closing Nanny at 'tcp://172.30.8.62:41263'
/scratch/cnt0024/hmg2840/albert7a/anaconda3/lib/python3.7/site-packages/distributed/utils.py:136: RuntimeWarning: Couldn't detect a suitable IP address for reaching '8.8.8.8', defaulting to '127.0.0.1': [Errno 101] Network is unreachable
  RuntimeWarning,
/scratch/cnt0024/hmg2840/albert7a/anaconda3/lib/python3.7/contextlib.py:119: UserWarning: Creating scratch directories is taking a surprisingly long time. This is often due to running workers on a network file system. Consider specifying a local-directory to point workers to write scratch data to a local disk.
  next(self.gen)
distributed.worker - INFO - Stopping worker
/scratch/cnt0024/hmg2840/albert7a/anaconda3/lib/python3.7/site-packages/distributed/utils.py:136: RuntimeWarning: Couldn't detect a suitable IP address for reaching '8.8.8.8', defaulting to '127.0.0.1': [Errno 101] Network is unreachable
  RuntimeWarning,
/scratch/cnt0024/hmg2840/albert7a/anaconda3/lib/python3.7/contextlib.py:119: UserWarning: Creating scratch directories is taking a surprisingly long time. This is often due to running workers on a network file system. Consider specifying a local-directory to point workers to write scratch data to a local disk.
  next(self.gen)
distributed.worker - INFO - Stopping worker
/scratch/cnt0024/hmg2840/albert7a/anaconda3/lib/python3.7/site-packages/distributed/utils.py:136: RuntimeWarning: Couldn't detect a suitable IP address for reaching '8.8.8.8', defaulting to '127.0.0.1': [Errno 101] Network is unreachable
  RuntimeWarning,
/scratch/cnt0024/hmg2840/albert7a/anaconda3/lib/python3.7/contextlib.py:119: UserWarning: Creating scratch directories is taking a surprisingly long time. This is often due to running workers on a network file system. Consider specifying a local-directory to point workers to write scratch data to a local disk.
  next(self.gen)
distributed.worker - INFO -       Start worker at:    tcp://172.30.8.62:46502
/scratch/cnt0024/hmg2840/albert7a/anaconda3/lib/python3.7/site-packages/distributed/utils.py:136: RuntimeWarning: Couldn't detect a suitable IP address for reaching '8.8.8.8', defaulting to '127.0.0.1': [Errno 101] Network is unreachable
  RuntimeWarning,
/scratch/cnt0024/hmg2840/albert7a/anaconda3/lib/python3.7/contextlib.py:119: UserWarning: Creating scratch directories is taking a surprisingly long time. This is often due to running workers on a network file system. Consider specifying a local-directory to point workers to write scratch data to a local disk.
  next(self.gen)
distributed.worker - INFO -       Start worker at:    tcp://172.30.8.62:41981
/scratch/cnt0024/hmg2840/albert7a/anaconda3/lib/python3.7/site-packages/distributed/utils.py:136: RuntimeWarning: Couldn't detect a suitable IP address for reaching '8.8.8.8', defaulting to '127.0.0.1': [Errno 101] Network is unreachable
  RuntimeWarning,
/scratch/cnt0024/hmg2840/albert7a/anaconda3/lib/python3.7/contextlib.py:119: UserWarning: Creating scratch directories is taking a surprisingly long time. This is often due to running workers on a network file system. Consider specifying a local-directory to point workers to write scratch data to a local disk.
  next(self.gen)
distributed.worker - INFO -       Start worker at:    tcp://172.30.8.62:36058
/scratch/cnt0024/hmg2840/albert7a/anaconda3/lib/python3.7/site-packages/distributed/utils.py:136: RuntimeWarning: Couldn't detect a suitable IP address for reaching '8.8.8.8', defaulting to '127.0.0.1': [Errno 101] Network is unreachable
  RuntimeWarning,
/scratch/cnt0024/hmg2840/albert7a/anaconda3/lib/python3.7/contextlib.py:119: UserWarning: Creating scratch directories is taking a surprisingly long time. This is often due to running workers on a network file system. Consider specifying a local-directory to point workers to write scratch data to a local disk.
  next(self.gen)
distributed.worker - INFO -       Start worker at:    tcp://172.30.8.62:36582
distributed.worker - INFO -          Listening to:    tcp://172.30.8.62:46502
distributed.worker - INFO -          Listening to:    tcp://172.30.8.62:41981
distributed.worker - INFO -          Listening to:    tcp://172.30.8.62:36058
distributed.worker - INFO -          Listening to:    tcp://172.30.8.62:36582
distributed.worker - INFO -          dashboard at:          172.30.8.62:33084
distributed.worker - INFO -          dashboard at:          172.30.8.62:40499
distributed.worker - INFO -          dashboard at:          172.30.8.62:36742
/scratch/cnt0024/hmg2840/albert7a/anaconda3/lib/python3.7/site-packages/distributed/utils.py:136: RuntimeWarning: Couldn't detect a suitable IP address for reaching '8.8.8.8', defaulting to '127.0.0.1': [Errno 101] Network is unreachable
  RuntimeWarning,
/scratch/cnt0024/hmg2840/albert7a/anaconda3/lib/python3.7/contextlib.py:119: UserWarning: Creating scratch directories is taking a surprisingly long time. This is often due to running workers on a network file system. Consider specifying a local-directory to point workers to write scratch data to a local disk.
  next(self.gen)
distributed.worker - INFO -       Start worker at:    tcp://172.30.8.62:38921
distributed.worker - INFO - Waiting to connect to:   tcp://172.30.100.2:42247
distributed.worker - INFO -          dashboard at:          172.30.8.62:34668
distributed.worker - INFO - Waiting to connect to:   tcp://172.30.100.2:42247
distributed.worker - INFO - Waiting to connect to:   tcp://172.30.100.2:42247
distributed.worker - INFO - -------------------------------------------------
distributed.worker - INFO - Waiting to connect to:   tcp://172.30.100.2:42247
distributed.worker - INFO - -------------------------------------------------
distributed.worker - INFO - -------------------------------------------------
distributed.worker - INFO -          Listening to:    tcp://172.30.8.62:38921
distributed.worker - INFO - -------------------------------------------------
/scratch/cnt0024/hmg2840/albert7a/anaconda3/lib/python3.7/site-packages/distributed/utils.py:136: RuntimeWarning: Couldn't detect a suitable IP address for reaching '8.8.8.8', defaulting to '127.0.0.1': [Errno 101] Network is unreachable
  RuntimeWarning,
/scratch/cnt0024/hmg2840/albert7a/anaconda3/lib/python3.7/contextlib.py:119: UserWarning: Creating scratch directories is taking a surprisingly long time. This is often due to running workers on a network file system. Consider specifying a local-directory to point workers to write scratch data to a local disk.
  next(self.gen)
distributed.worker - INFO -       Start worker at:    tcp://172.30.8.62:36960
distributed.worker - INFO -               Threads:                          1
distributed.worker - INFO -               Threads:                          1
distributed.worker - INFO -               Threads:                          1
distributed.worker - INFO -          dashboard at:          172.30.8.62:38180
distributed.worker - INFO -               Threads:                          1
distributed.worker - INFO -          Listening to:    tcp://172.30.8.62:36960
distributed.worker - INFO -                Memory:                    4.29 GB
distributed.worker - INFO -                Memory:                    4.29 GB
distributed.worker - INFO -                Memory:                    4.29 GB
distributed.worker - INFO -       Local Directory: /scratch/cnt0024/hmg2840/albert7a/daskjobqueue/worker-qwrppquz
distributed.worker - INFO - Waiting to connect to:   tcp://172.30.100.2:42247
distributed.worker - INFO -                Memory:                    4.29 GB
distributed.worker - INFO -       Local Directory: /scratch/cnt0024/hmg2840/albert7a/daskjobqueue/worker-3q1961we
distributed.worker - INFO -       Local Directory: /scratch/cnt0024/hmg2840/albert7a/daskjobqueue/worker-3a_1pt7g
/scratch/cnt0024/hmg2840/albert7a/anaconda3/lib/python3.7/site-packages/distributed/utils.py:136: RuntimeWarning: Couldn't detect a suitable IP address for reaching '8.8.8.8', defaulting to '127.0.0.1': [Errno 101] Network is unreachable
  RuntimeWarning,
/scratch/cnt0024/hmg2840/albert7a/anaconda3/lib/python3.7/contextlib.py:119: UserWarning: Creating scratch directories is taking a surprisingly long time. This is often due to running workers on a network file system. Consider specifying a local-directory to point workers to write scratch data to a local disk.
  next(self.gen)
distributed.worker - INFO -       Start worker at:    tcp://172.30.8.62:36861
distributed.worker - INFO -          dashboard at:          172.30.8.62:39148
/scratch/cnt0024/hmg2840/albert7a/anaconda3/lib/python3.7/site-packages/distributed/utils.py:136: RuntimeWarning: Couldn't detect a suitable IP address for reaching '8.8.8.8', defaulting to '127.0.0.1': [Errno 101] Network is unreachable
  RuntimeWarning,
/scratch/cnt0024/hmg2840/albert7a/anaconda3/lib/python3.7/contextlib.py:119: UserWarning: Creating scratch directories is taking a surprisingly long time. This is often due to running workers on a network file system. Consider specifying a local-directory to point workers to write scratch data to a local disk.
  next(self.gen)
distributed.worker - INFO -       Start worker at:    tcp://172.30.8.62:38834
distributed.worker - INFO -       Local Directory: /scratch/cnt0024/hmg2840/albert7a/daskjobqueue/worker-wfcrqqg0
distributed.worker - INFO - -------------------------------------------------
distributed.worker - INFO -          Listening to:    tcp://172.30.8.62:36861
distributed.worker - INFO - Waiting to connect to:   tcp://172.30.100.2:42247
distributed.worker - INFO -          Listening to:    tcp://172.30.8.62:38834
distributed.worker - INFO -          dashboard at:          172.30.8.62:33995
distributed.worker - INFO - -------------------------------------------------
distributed.worker - INFO - -------------------------------------------------
distributed.worker - INFO - -------------------------------------------------
distributed.worker - INFO - Waiting to connect to:   tcp://172.30.100.2:42247
distributed.worker - INFO - -------------------------------------------------
distributed.worker - INFO - -------------------------------------------------
distributed.worker - INFO - -------------------------------------------------
distributed.worker - INFO -          dashboard at:          172.30.8.62:42159
/scratch/cnt0024/hmg2840/albert7a/anaconda3/lib/python3.7/site-packages/distributed/utils.py:136: RuntimeWarning: Couldn't detect a suitable IP address for reaching '8.8.8.8', defaulting to '127.0.0.1': [Errno 101] Network is unreachable
  RuntimeWarning,
/scratch/cnt0024/hmg2840/albert7a/anaconda3/lib/python3.7/contextlib.py:119: UserWarning: Creating scratch directories is taking a surprisingly long time. This is often due to running workers on a network file system. Consider specifying a local-directory to point workers to write scratch data to a local disk.
  next(self.gen)
distributed.worker - INFO -       Start worker at:    tcp://172.30.8.62:35455
distributed.worker - INFO -               Threads:                          1
distributed.worker - INFO -          Listening to:    tcp://172.30.8.62:35455
distributed.worker - INFO - Waiting to connect to:   tcp://172.30.100.2:42247
distributed.worker - INFO -               Threads:                          1
distributed.worker - INFO -                Memory:                    4.29 GB
distributed.worker - INFO -          dashboard at:          172.30.8.62:42349
distributed.worker - INFO -               Threads:                          1
distributed.worker - INFO -                Memory:                    4.29 GB
distributed.worker - INFO - -------------------------------------------------
distributed.worker - INFO -       Local Directory: /scratch/cnt0024/hmg2840/albert7a/daskjobqueue/worker-pxinf533
distributed.worker - INFO - Waiting to connect to:   tcp://172.30.100.2:42247
distributed.worker - INFO -       Local Directory: /scratch/cnt0024/hmg2840/albert7a/daskjobqueue/worker-umle6t39
distributed.worker - INFO -                Memory:                    4.29 GB
distributed.worker - INFO - -------------------------------------------------
/scratch/cnt0024/hmg2840/albert7a/anaconda3/lib/python3.7/site-packages/distributed/utils.py:136: RuntimeWarning: Couldn't detect a suitable IP address for reaching '8.8.8.8', defaulting to '127.0.0.1': [Errno 101] Network is unreachable
  RuntimeWarning,
/scratch/cnt0024/hmg2840/albert7a/anaconda3/lib/python3.7/contextlib.py:119: UserWarning: Creating scratch directories is taking a surprisingly long time. This is often due to running workers on a network file system. Consider specifying a local-directory to point workers to write scratch data to a local disk.
  next(self.gen)
distributed.worker - INFO -       Start worker at:    tcp://172.30.8.62:32798
distributed.worker - INFO -       Local Directory: /scratch/cnt0024/hmg2840/albert7a/daskjobqueue/worker-r8qkywql
distributed.worker - INFO -               Threads:                          1
distributed.worker - INFO -               Threads:                          1
distributed.worker - INFO -          Listening to:    tcp://172.30.8.62:32798
distributed.worker - INFO -                Memory:                    4.29 GB
distributed.worker - INFO - -------------------------------------------------
distributed.worker - INFO -                Memory:                    4.29 GB
distributed.worker - INFO - -------------------------------------------------
distributed.worker - INFO -       Local Directory: /scratch/cnt0024/hmg2840/albert7a/daskjobqueue/worker-w8nit4n6
distributed.worker - INFO -          dashboard at:          172.30.8.62:32792
distributed.worker - INFO -       Local Directory: /scratch/cnt0024/hmg2840/albert7a/daskjobqueue/worker-gsohva0w
distributed.worker - INFO - Waiting to connect to:   tcp://172.30.100.2:42247
distributed.worker - INFO - Stopping worker at tcp://172.30.8.62:36582
distributed.worker - INFO - Stopping worker at tcp://172.30.8.62:46502
distributed.worker - INFO - Stopping worker at tcp://172.30.8.62:36058
distributed.worker - INFO - -------------------------------------------------
distributed.worker - INFO - Stopping worker at tcp://172.30.8.62:41981
distributed.worker - INFO - -------------------------------------------------
distributed.worker - INFO - -------------------------------------------------
/scratch/cnt0024/hmg2840/albert7a/anaconda3/lib/python3.7/site-packages/distributed/utils.py:136: RuntimeWarning: Couldn't detect a suitable IP address for reaching '8.8.8.8', defaulting to '127.0.0.1': [Errno 101] Network is unreachable
  RuntimeWarning,
/scratch/cnt0024/hmg2840/albert7a/anaconda3/lib/python3.7/contextlib.py:119: UserWarning: Creating scratch directories is taking a surprisingly long time. This is often due to running workers on a network file system. Consider specifying a local-directory to point workers to write scratch data to a local disk.
  next(self.gen)
distributed.worker - INFO -       Start worker at:    tcp://172.30.8.62:45411
distributed.worker - INFO -          Listening to:    tcp://172.30.8.62:45411
distributed.worker - INFO - -------------------------------------------------
distributed.worker - INFO -          dashboard at:          172.30.8.62:43369
distributed.worker - INFO -               Threads:                          1
distributed.worker - INFO - Waiting to connect to:   tcp://172.30.100.2:42247
distributed.worker - INFO - -------------------------------------------------
distributed.worker - INFO -                Memory:                    4.29 GB
distributed.worker - INFO -               Threads:                          1
distributed.worker - INFO -       Local Directory: /scratch/cnt0024/hmg2840/albert7a/daskjobqueue/worker-ma0lhie8
distributed.worker - INFO -                Memory:                    4.29 GB
distributed.worker - INFO -       Local Directory: /scratch/cnt0024/hmg2840/albert7a/daskjobqueue/worker-1xxdfrjc
distributed.worker - INFO - -------------------------------------------------
distributed.worker - INFO - -------------------------------------------------
distributed.worker - INFO - Stopping worker at tcp://172.30.8.62:38921
distributed.worker - INFO - Stopping worker at tcp://172.30.8.62:36861
distributed.worker - INFO - Stopping worker at tcp://172.30.8.62:35455
distributed.worker - INFO - Stopping worker at tcp://172.30.8.62:36960
distributed.worker - INFO - Stopping worker at tcp://172.30.8.62:38834
distributed.worker - INFO - Stopping worker at tcp://172.30.8.62:45411
/scratch/cnt0024/hmg2840/albert7a/anaconda3/lib/python3.7/site-packages/distributed/utils.py:136: RuntimeWarning: Couldn't detect a suitable IP address for reaching '8.8.8.8', defaulting to '127.0.0.1': [Errno 101] Network is unreachable
  RuntimeWarning,
/scratch/cnt0024/hmg2840/albert7a/anaconda3/lib/python3.7/contextlib.py:119: UserWarning: Creating scratch directories is taking a surprisingly long time. This is often due to running workers on a network file system. Consider specifying a local-directory to point workers to write scratch data to a local disk.
  next(self.gen)
distributed.worker - INFO -       Start worker at:    tcp://172.30.8.62:34420
distributed.worker - INFO -          Listening to:    tcp://172.30.8.62:34420
distributed.worker - INFO - Stopping worker at tcp://172.30.8.62:32798
distributed.worker - INFO -          dashboard at:          172.30.8.62:45603
distributed.worker - INFO - Waiting to connect to:   tcp://172.30.100.2:42247
distributed.worker - INFO - -------------------------------------------------
distributed.worker - INFO -               Threads:                          1
distributed.worker - INFO -                Memory:                    4.29 GB
distributed.worker - INFO -       Local Directory: /scratch/cnt0024/hmg2840/albert7a/daskjobqueue/worker-zfai2vwa
distributed.worker - INFO - -------------------------------------------------
distributed.worker - INFO - Stopping worker at tcp://172.30.8.62:34420
/scratch/cnt0024/hmg2840/albert7a/anaconda3/lib/python3.7/site-packages/distributed/utils.py:136: RuntimeWarning: Couldn't detect a suitable IP address for reaching '8.8.8.8', defaulting to '127.0.0.1': [Errno 101] Network is unreachable
  RuntimeWarning,
/scratch/cnt0024/hmg2840/albert7a/anaconda3/lib/python3.7/contextlib.py:119: UserWarning: Creating scratch directories is taking a surprisingly long time. This is often due to running workers on a network file system. Consider specifying a local-directory to point workers to write scratch data to a local disk.
  next(self.gen)
distributed.worker - INFO -       Start worker at:    tcp://172.30.8.62:33722
/scratch/cnt0024/hmg2840/albert7a/anaconda3/lib/python3.7/site-packages/distributed/utils.py:136: RuntimeWarning: Couldn't detect a suitable IP address for reaching '8.8.8.8', defaulting to '127.0.0.1': [Errno 101] Network is unreachable
  RuntimeWarning,
/scratch/cnt0024/hmg2840/albert7a/anaconda3/lib/python3.7/contextlib.py:119: UserWarning: Creating scratch directories is taking a surprisingly long time. This is often due to running workers on a network file system. Consider specifying a local-directory to point workers to write scratch data to a local disk.
  next(self.gen)
distributed.worker - INFO -       Start worker at:    tcp://172.30.8.62:41330
distributed.worker - INFO -          Listening to:    tcp://172.30.8.62:33722
distributed.worker - INFO -          Listening to:    tcp://172.30.8.62:41330
distributed.worker - INFO -          dashboard at:          172.30.8.62:35829
distributed.worker - INFO -          dashboard at:          172.30.8.62:39671
distributed.worker - INFO - Waiting to connect to:   tcp://172.30.100.2:42247
distributed.worker - INFO - Waiting to connect to:   tcp://172.30.100.2:42247
distributed.worker - INFO - -------------------------------------------------
distributed.worker - INFO - -------------------------------------------------
distributed.worker - INFO -               Threads:                          1
/scratch/cnt0024/hmg2840/albert7a/anaconda3/lib/python3.7/site-packages/distributed/utils.py:136: RuntimeWarning: Couldn't detect a suitable IP address for reaching '8.8.8.8', defaulting to '127.0.0.1': [Errno 101] Network is unreachable
  RuntimeWarning,
/scratch/cnt0024/hmg2840/albert7a/anaconda3/lib/python3.7/contextlib.py:119: UserWarning: Creating scratch directories is taking a surprisingly long time. This is often due to running workers on a network file system. Consider specifying a local-directory to point workers to write scratch data to a local disk.
  next(self.gen)
distributed.worker - INFO -       Start worker at:    tcp://172.30.8.62:34217
distributed.worker - INFO -                Memory:                    4.29 GB
distributed.worker - INFO -          Listening to:    tcp://172.30.8.62:34217
distributed.worker - INFO -       Local Directory: /scratch/cnt0024/hmg2840/albert7a/daskjobqueue/worker-_q5mu_ew
distributed.worker - INFO -               Threads:                          1
distributed.worker - INFO -          dashboard at:          172.30.8.62:41123
distributed.worker - INFO -                Memory:                    4.29 GB
/scratch/cnt0024/hmg2840/albert7a/anaconda3/lib/python3.7/site-packages/distributed/utils.py:136: RuntimeWarning: Couldn't detect a suitable IP address for reaching '8.8.8.8', defaulting to '127.0.0.1': [Errno 101] Network is unreachable
  RuntimeWarning,
/scratch/cnt0024/hmg2840/albert7a/anaconda3/lib/python3.7/contextlib.py:119: UserWarning: Creating scratch directories is taking a surprisingly long time. This is often due to running workers on a network file system. Consider specifying a local-directory to point workers to write scratch data to a local disk.
  next(self.gen)
distributed.worker - INFO -       Start worker at:    tcp://172.30.8.62:40402
distributed.worker - INFO -       Local Directory: /scratch/cnt0024/hmg2840/albert7a/daskjobqueue/worker-47hzs_81
distributed.worker - INFO - Waiting to connect to:   tcp://172.30.100.2:42247
distributed.worker - INFO -          Listening to:    tcp://172.30.8.62:40402
distributed.worker - INFO - -------------------------------------------------
distributed.worker - INFO - -------------------------------------------------
distributed.worker - INFO -          dashboard at:          172.30.8.62:35616
distributed.worker - INFO - Waiting to connect to:   tcp://172.30.100.2:42247
distributed.worker - INFO - -------------------------------------------------
distributed.worker - INFO - -------------------------------------------------
distributed.worker - INFO -               Threads:                          1
distributed.worker - INFO -               Threads:                          1
distributed.worker - INFO -                Memory:                    4.29 GB
distributed.worker - INFO -                Memory:                    4.29 GB
distributed.worker - INFO -       Local Directory: /scratch/cnt0024/hmg2840/albert7a/daskjobqueue/worker-qav87vcp
distributed.worker - INFO -       Local Directory: /scratch/cnt0024/hmg2840/albert7a/daskjobqueue/worker-w8zj31xk
/scratch/cnt0024/hmg2840/albert7a/anaconda3/lib/python3.7/site-packages/distributed/utils.py:136: RuntimeWarning: Couldn't detect a suitable IP address for reaching '8.8.8.8', defaulting to '127.0.0.1': [Errno 101] Network is unreachable
  RuntimeWarning,
/scratch/cnt0024/hmg2840/albert7a/anaconda3/lib/python3.7/contextlib.py:119: UserWarning: Creating scratch directories is taking a surprisingly long time. This is often due to running workers on a network file system. Consider specifying a local-directory to point workers to write scratch data to a local disk.
  next(self.gen)
distributed.worker - INFO -       Start worker at:    tcp://172.30.8.62:45336
distributed.worker - INFO -          Listening to:    tcp://172.30.8.62:45336
distributed.worker - INFO -          dashboard at:          172.30.8.62:34895
distributed.worker - INFO - -------------------------------------------------
distributed.worker - INFO - Stopping worker at tcp://172.30.8.62:41330
distributed.worker - INFO - Waiting to connect to:   tcp://172.30.100.2:42247
distributed.worker - INFO - -------------------------------------------------
distributed.worker - INFO - -------------------------------------------------
distributed.worker - INFO -               Threads:                          1
distributed.worker - INFO -                Memory:                    4.29 GB
distributed.worker - INFO -       Local Directory: /scratch/cnt0024/hmg2840/albert7a/daskjobqueue/worker-0_sbhyse
distributed.worker - INFO - Stopping worker at tcp://172.30.8.62:33722
distributed.worker - INFO - -------------------------------------------------
distributed.worker - INFO - Stopping worker at tcp://172.30.8.62:34217
/scratch/cnt0024/hmg2840/albert7a/anaconda3/lib/python3.7/site-packages/distributed/utils.py:136: RuntimeWarning: Couldn't detect a suitable IP address for reaching '8.8.8.8', defaulting to '127.0.0.1': [Errno 101] Network is unreachable
  RuntimeWarning,
/scratch/cnt0024/hmg2840/albert7a/anaconda3/lib/python3.7/contextlib.py:119: UserWarning: Creating scratch directories is taking a surprisingly long time. This is often due to running workers on a network file system. Consider specifying a local-directory to point workers to write scratch data to a local disk.
  next(self.gen)
distributed.worker - INFO -       Start worker at:    tcp://172.30.8.62:40170
distributed.worker - INFO -          Listening to:    tcp://172.30.8.62:40170
distributed.worker - INFO - Stopping worker at tcp://172.30.8.62:40402
distributed.worker - INFO -          dashboard at:          172.30.8.62:35670
distributed.worker - INFO - Stopping worker at tcp://172.30.8.62:45336
distributed.worker - INFO - Waiting to connect to:   tcp://172.30.100.2:42247
/scratch/cnt0024/hmg2840/albert7a/anaconda3/lib/python3.7/site-packages/distributed/utils.py:136: RuntimeWarning: Couldn't detect a suitable IP address for reaching '8.8.8.8', defaulting to '127.0.0.1': [Errno 101] Network is unreachable
  RuntimeWarning,
/scratch/cnt0024/hmg2840/albert7a/anaconda3/lib/python3.7/contextlib.py:119: UserWarning: Creating scratch directories is taking a surprisingly long time. This is often due to running workers on a network file system. Consider specifying a local-directory to point workers to write scratch data to a local disk.
  next(self.gen)
distributed.worker - INFO -       Start worker at:    tcp://172.30.8.62:36530
distributed.worker - INFO - -------------------------------------------------
distributed.worker - INFO -          Listening to:    tcp://172.30.8.62:36530
distributed.worker - INFO -          dashboard at:          172.30.8.62:32803
distributed.worker - INFO - Waiting to connect to:   tcp://172.30.100.2:42247
distributed.worker - INFO -               Threads:                          1
distributed.worker - INFO - -------------------------------------------------
distributed.worker - INFO -                Memory:                    4.29 GB
distributed.worker - INFO -       Local Directory: /scratch/cnt0024/hmg2840/albert7a/daskjobqueue/worker-ji4ks_i3
distributed.worker - INFO -               Threads:                          1
distributed.worker - INFO -                Memory:                    4.29 GB
distributed.worker - INFO -       Local Directory: /scratch/cnt0024/hmg2840/albert7a/daskjobqueue/worker-8apkjvg8
distributed.worker - INFO - -------------------------------------------------
distributed.worker - INFO - -------------------------------------------------
distributed.worker - INFO - Stopping worker at tcp://172.30.8.62:36530
distributed.worker - INFO - Stopping worker at tcp://172.30.8.62:40170
/scratch/cnt0024/hmg2840/albert7a/anaconda3/lib/python3.7/site-packages/distributed/utils.py:136: RuntimeWarning: Couldn't detect a suitable IP address for reaching '8.8.8.8', defaulting to '127.0.0.1': [Errno 101] Network is unreachable
  RuntimeWarning,
/scratch/cnt0024/hmg2840/albert7a/anaconda3/lib/python3.7/contextlib.py:119: UserWarning: Creating scratch directories is taking a surprisingly long time. This is often due to running workers on a network file system. Consider specifying a local-directory to point workers to write scratch data to a local disk.
  next(self.gen)
distributed.worker - INFO -       Start worker at:    tcp://172.30.8.62:33406
distributed.worker - INFO -          Listening to:    tcp://172.30.8.62:33406
distributed.worker - INFO -          dashboard at:          172.30.8.62:40588
distributed.worker - INFO - Waiting to connect to:   tcp://172.30.100.2:42247
distributed.worker - INFO - -------------------------------------------------
distributed.worker - INFO -               Threads:                          1
distributed.worker - INFO -                Memory:                    4.29 GB
distributed.worker - INFO -       Local Directory: /scratch/cnt0024/hmg2840/albert7a/daskjobqueue/worker-s2ids8xb
distributed.worker - INFO - -------------------------------------------------
/scratch/cnt0024/hmg2840/albert7a/anaconda3/lib/python3.7/site-packages/distributed/utils.py:136: RuntimeWarning: Couldn't detect a suitable IP address for reaching '8.8.8.8', defaulting to '127.0.0.1': [Errno 101] Network is unreachable
  RuntimeWarning,
/scratch/cnt0024/hmg2840/albert7a/anaconda3/lib/python3.7/contextlib.py:119: UserWarning: Creating scratch directories is taking a surprisingly long time. This is often due to running workers on a network file system. Consider specifying a local-directory to point workers to write scratch data to a local disk.
  next(self.gen)
distributed.worker - INFO -       Start worker at:    tcp://172.30.8.62:33928
distributed.worker - INFO -          Listening to:    tcp://172.30.8.62:33928
distributed.worker - INFO -          dashboard at:          172.30.8.62:41395
distributed.worker - INFO - Waiting to connect to:   tcp://172.30.100.2:42247
distributed.worker - INFO - -------------------------------------------------
distributed.nanny - ERROR - Failed to start worker
Traceback (most recent call last):
  File "/scratch/cnt0024/hmg2840/albert7a/anaconda3/lib/python3.7/site-packages/distributed/nanny.py", line 674, in run
    yield worker._start(*worker_start_args)
  File "/scratch/cnt0024/hmg2840/albert7a/anaconda3/lib/python3.7/site-packages/tornado/gen.py", line 729, in run
    value = future.result()
  File "/scratch/cnt0024/hmg2840/albert7a/anaconda3/lib/python3.7/site-packages/tornado/gen.py", line 209, in wrapper
    yielded = next(result)
  File "/scratch/cnt0024/hmg2840/albert7a/anaconda3/lib/python3.7/site-packages/distributed/worker.py", line 896, in _start
    assert self.status is None
AssertionError
distributed.worker - INFO - Stopping worker at tcp://172.30.8.62:33406
distributed.worker - INFO -               Threads:                          1
distributed.worker - INFO -                Memory:                    4.29 GB
distributed.worker - INFO -       Local Directory: /scratch/cnt0024/hmg2840/albert7a/daskjobqueue/worker-29qp1kkr
/scratch/cnt0024/hmg2840/albert7a/anaconda3/lib/python3.7/site-packages/distributed/utils.py:136: RuntimeWarning: Couldn't detect a suitable IP address for reaching '8.8.8.8', defaulting to '127.0.0.1': [Errno 101] Network is unreachable
  RuntimeWarning,
/scratch/cnt0024/hmg2840/albert7a/anaconda3/lib/python3.7/contextlib.py:119: UserWarning: Creating scratch directories is taking a surprisingly long time. This is often due to running workers on a network file system. Consider specifying a local-directory to point workers to write scratch data to a local disk.
  next(self.gen)
distributed.worker - INFO -       Start worker at:    tcp://172.30.8.62:37659
/scratch/cnt0024/hmg2840/albert7a/anaconda3/lib/python3.7/site-packages/distributed/utils.py:136: RuntimeWarning: Couldn't detect a suitable IP address for reaching '8.8.8.8', defaulting to '127.0.0.1': [Errno 101] Network is unreachable
  RuntimeWarning,
/scratch/cnt0024/hmg2840/albert7a/anaconda3/lib/python3.7/contextlib.py:119: UserWarning: Creating scratch directories is taking a surprisingly long time. This is often due to running workers on a network file system. Consider specifying a local-directory to point workers to write scratch data to a local disk.
  next(self.gen)
distributed.worker - INFO -       Start worker at:    tcp://172.30.8.62:33673
distributed.worker - INFO -          Listening to:    tcp://172.30.8.62:33673
distributed.worker - INFO - -------------------------------------------------
distributed.worker - INFO -          dashboard at:          172.30.8.62:43998
/scratch/cnt0024/hmg2840/albert7a/anaconda3/lib/python3.7/site-packages/distributed/utils.py:136: RuntimeWarning: Couldn't detect a suitable IP address for reaching '8.8.8.8', defaulting to '127.0.0.1': [Errno 101] Network is unreachable
  RuntimeWarning,
/scratch/cnt0024/hmg2840/albert7a/anaconda3/lib/python3.7/contextlib.py:119: UserWarning: Creating scratch directories is taking a surprisingly long time. This is often due to running workers on a network file system. Consider specifying a local-directory to point workers to write scratch data to a local disk.
  next(self.gen)
distributed.worker - INFO -       Start worker at:    tcp://172.30.8.62:42835
distributed.worker - INFO - Waiting to connect to:   tcp://172.30.100.2:42247
distributed.worker - INFO -          Listening to:    tcp://172.30.8.62:37659
distributed.worker - INFO - -------------------------------------------------
distributed.worker - INFO -          Listening to:    tcp://172.30.8.62:42835
distributed.worker - INFO -          dashboard at:          172.30.8.62:33785
distributed.worker - INFO - Waiting to connect to:   tcp://172.30.100.2:42247
distributed.worker - INFO -          dashboard at:          172.30.8.62:37507
distributed.worker - INFO -               Threads:                          1
distributed.worker - INFO - -------------------------------------------------
distributed.worker - INFO - Waiting to connect to:   tcp://172.30.100.2:42247
distributed.worker - INFO -                Memory:                    4.29 GB
distributed.worker - INFO - -------------------------------------------------
distributed.worker - INFO -       Local Directory: /scratch/cnt0024/hmg2840/albert7a/daskjobqueue/worker-lgykagar
distributed.worker - INFO -               Threads:                          1
distributed.worker - INFO -               Threads:                          1
/scratch/cnt0024/hmg2840/albert7a/anaconda3/lib/python3.7/site-packages/distributed/utils.py:136: RuntimeWarning: Couldn't detect a suitable IP address for reaching '8.8.8.8', defaulting to '127.0.0.1': [Errno 101] Network is unreachable
  RuntimeWarning,
/scratch/cnt0024/hmg2840/albert7a/anaconda3/lib/python3.7/contextlib.py:119: UserWarning: Creating scratch directories is taking a surprisingly long time. This is often due to running workers on a network file system. Consider specifying a local-directory to point workers to write scratch data to a local disk.
  next(self.gen)
distributed.worker - INFO -       Start worker at:    tcp://172.30.8.62:37872
distributed.worker - INFO -                Memory:                    4.29 GB
distributed.worker - INFO -                Memory:                    4.29 GB
distributed.worker - INFO - -------------------------------------------------
distributed.worker - INFO -          Listening to:    tcp://172.30.8.62:37872
distributed.worker - INFO -       Local Directory: /scratch/cnt0024/hmg2840/albert7a/daskjobqueue/worker-jslmx11c
distributed.worker - INFO -       Local Directory: /scratch/cnt0024/hmg2840/albert7a/daskjobqueue/worker-vwu1idb8
distributed.worker - INFO -          dashboard at:          172.30.8.62:39503
distributed.nanny - ERROR - Failed to start worker
Traceback (most recent call last):
  File "/scratch/cnt0024/hmg2840/albert7a/anaconda3/lib/python3.7/site-packages/distributed/nanny.py", line 674, in run
    yield worker._start(*worker_start_args)
  File "/scratch/cnt0024/hmg2840/albert7a/anaconda3/lib/python3.7/site-packages/tornado/gen.py", line 729, in run
    value = future.result()
  File "/scratch/cnt0024/hmg2840/albert7a/anaconda3/lib/python3.7/site-packages/tornado/gen.py", line 209, in wrapper
    yielded = next(result)
  File "/scratch/cnt0024/hmg2840/albert7a/anaconda3/lib/python3.7/site-packages/distributed/worker.py", line 896, in _start
    assert self.status is None
AssertionError
distributed.worker - INFO - Waiting to connect to:   tcp://172.30.100.2:42247
distributed.worker - INFO - -------------------------------------------------
distributed.worker - INFO - -------------------------------------------------
distributed.worker - INFO - -------------------------------------------------
/scratch/cnt0024/hmg2840/albert7a/anaconda3/lib/python3.7/site-packages/distributed/utils.py:136: RuntimeWarning: Couldn't detect a suitable IP address for reaching '8.8.8.8', defaulting to '127.0.0.1': [Errno 101] Network is unreachable
  RuntimeWarning,
/scratch/cnt0024/hmg2840/albert7a/anaconda3/lib/python3.7/contextlib.py:119: UserWarning: Creating scratch directories is taking a surprisingly long time. This is often due to running workers on a network file system. Consider specifying a local-directory to point workers to write scratch data to a local disk.
  next(self.gen)
distributed.worker - INFO -       Start worker at:    tcp://172.30.8.62:33829
distributed.worker - INFO -               Threads:                          1
distributed.worker - INFO -          Listening to:    tcp://172.30.8.62:33829
distributed.worker - INFO - Stopping worker at tcp://172.30.8.62:33928
distributed.worker - INFO -          dashboard at:          172.30.8.62:38995
distributed.worker - INFO -                Memory:                    4.29 GB
distributed.worker - INFO - Waiting to connect to:   tcp://172.30.100.2:42247
distributed.worker - INFO -       Local Directory: /scratch/cnt0024/hmg2840/albert7a/daskjobqueue/worker-rq7r6_93
distributed.worker - INFO - Stopping worker at tcp://172.30.8.62:33673
distributed.worker - INFO - -------------------------------------------------
distributed.worker - INFO - -------------------------------------------------
distributed.worker - INFO -               Threads:                          1
distributed.worker - INFO - Stopping worker at tcp://172.30.8.62:42835
distributed.worker - INFO -                Memory:                    4.29 GB
distributed.worker - INFO - Stopping worker at tcp://172.30.8.62:37659
distributed.worker - INFO -       Local Directory: /scratch/cnt0024/hmg2840/albert7a/daskjobqueue/worker-cwx09ic8
distributed.worker - INFO - -------------------------------------------------
distributed.worker - INFO - Stopping worker at tcp://172.30.8.62:37872
distributed.worker - INFO - Stopping worker at tcp://172.30.8.62:33829
distributed.nanny - ERROR - Timed out connecting Nanny '<Nanny: None, threads: 1>' to scheduler 'tcp://172.30.100.2:42247'
Traceback (most recent call last):
  File "/scratch/cnt0024/hmg2840/albert7a/anaconda3/lib/python3.7/site-packages/distributed/nanny.py", line 303, in instantiate
    timedelta(seconds=self.death_timeout), self.process.start()
  File "/scratch/cnt0024/hmg2840/albert7a/anaconda3/lib/python3.7/site-packages/tornado/gen.py", line 729, in run
    value = future.result()
tornado.util.TimeoutError: Timeout
distributed.nanny - ERROR - Timed out connecting Nanny '<Nanny: None, threads: 1>' to scheduler 'tcp://172.30.100.2:42247'
Traceback (most recent call last):
  File "/scratch/cnt0024/hmg2840/albert7a/anaconda3/lib/python3.7/site-packages/distributed/nanny.py", line 303, in instantiate
    timedelta(seconds=self.death_timeout), self.process.start()
  File "/scratch/cnt0024/hmg2840/albert7a/anaconda3/lib/python3.7/site-packages/tornado/gen.py", line 729, in run
    value = future.result()
tornado.util.TimeoutError: Timeout
distributed.nanny - ERROR - Timed out connecting Nanny '<Nanny: None, threads: 1>' to scheduler 'tcp://172.30.100.2:42247'
Traceback (most recent call last):
  File "/scratch/cnt0024/hmg2840/albert7a/anaconda3/lib/python3.7/site-packages/distributed/nanny.py", line 303, in instantiate
    timedelta(seconds=self.death_timeout), self.process.start()
  File "/scratch/cnt0024/hmg2840/albert7a/anaconda3/lib/python3.7/site-packages/tornado/gen.py", line 729, in run
    value = future.result()
tornado.util.TimeoutError: Timeout
distributed.nanny - ERROR - Timed out connecting Nanny '<Nanny: None, threads: 1>' to scheduler 'tcp://172.30.100.2:42247'
Traceback (most recent call last):
  File "/scratch/cnt0024/hmg2840/albert7a/anaconda3/lib/python3.7/site-packages/distributed/nanny.py", line 303, in instantiate
    timedelta(seconds=self.death_timeout), self.process.start()
  File "/scratch/cnt0024/hmg2840/albert7a/anaconda3/lib/python3.7/site-packages/tornado/gen.py", line 729, in run
    value = future.result()
tornado.util.TimeoutError: Timeout
distributed.nanny - ERROR - Timed out connecting Nanny '<Nanny: None, threads: 1>' to scheduler 'tcp://172.30.100.2:42247'
Traceback (most recent call last):
  File "/scratch/cnt0024/hmg2840/albert7a/anaconda3/lib/python3.7/site-packages/distributed/nanny.py", line 303, in instantiate
    timedelta(seconds=self.death_timeout), self.process.start()
  File "/scratch/cnt0024/hmg2840/albert7a/anaconda3/lib/python3.7/site-packages/tornado/gen.py", line 729, in run
    value = future.result()
tornado.util.TimeoutError: Timeout
distributed.nanny - ERROR - Timed out connecting Nanny '<Nanny: None, threads: 1>' to scheduler 'tcp://172.30.100.2:42247'
Traceback (most recent call last):
  File "/scratch/cnt0024/hmg2840/albert7a/anaconda3/lib/python3.7/site-packages/distributed/nanny.py", line 303, in instantiate
    timedelta(seconds=self.death_timeout), self.process.start()
  File "/scratch/cnt0024/hmg2840/albert7a/anaconda3/lib/python3.7/site-packages/tornado/gen.py", line 729, in run
    value = future.result()
tornado.util.TimeoutError: Timeout
distributed.nanny - ERROR - Timed out connecting Nanny '<Nanny: None, threads: 1>' to scheduler 'tcp://172.30.100.2:42247'
Traceback (most recent call last):
  File "/scratch/cnt0024/hmg2840/albert7a/anaconda3/lib/python3.7/site-packages/distributed/nanny.py", line 303, in instantiate
    timedelta(seconds=self.death_timeout), self.process.start()
  File "/scratch/cnt0024/hmg2840/albert7a/anaconda3/lib/python3.7/site-packages/tornado/gen.py", line 729, in run
    value = future.result()
tornado.util.TimeoutError: Timeout
distributed.nanny - ERROR - Timed out connecting Nanny '<Nanny: None, threads: 1>' to scheduler 'tcp://172.30.100.2:42247'
Traceback (most recent call last):
  File "/scratch/cnt0024/hmg2840/albert7a/anaconda3/lib/python3.7/site-packages/distributed/nanny.py", line 303, in instantiate
    timedelta(seconds=self.death_timeout), self.process.start()
  File "/scratch/cnt0024/hmg2840/albert7a/anaconda3/lib/python3.7/site-packages/tornado/gen.py", line 729, in run
    value = future.result()
tornado.util.TimeoutError: Timeout
distributed.nanny - ERROR - Timed out connecting Nanny '<Nanny: None, threads: 1>' to scheduler 'tcp://172.30.100.2:42247'
Traceback (most recent call last):
  File "/scratch/cnt0024/hmg2840/albert7a/anaconda3/lib/python3.7/site-packages/distributed/nanny.py", line 303, in instantiate
    timedelta(seconds=self.death_timeout), self.process.start()
  File "/scratch/cnt0024/hmg2840/albert7a/anaconda3/lib/python3.7/site-packages/tornado/gen.py", line 729, in run
    value = future.result()
tornado.util.TimeoutError: Timeout
distributed.nanny - ERROR - Timed out connecting Nanny '<Nanny: None, threads: 1>' to scheduler 'tcp://172.30.100.2:42247'
Traceback (most recent call last):
  File "/scratch/cnt0024/hmg2840/albert7a/anaconda3/lib/python3.7/site-packages/distributed/nanny.py", line 303, in instantiate
    timedelta(seconds=self.death_timeout), self.process.start()
  File "/scratch/cnt0024/hmg2840/albert7a/anaconda3/lib/python3.7/site-packages/tornado/gen.py", line 729, in run
    value = future.result()
tornado.util.TimeoutError: Timeout
distributed.nanny - ERROR - Timed out connecting Nanny '<Nanny: None, threads: 1>' to scheduler 'tcp://172.30.100.2:42247'
Traceback (most recent call last):
  File "/scratch/cnt0024/hmg2840/albert7a/anaconda3/lib/python3.7/site-packages/distributed/nanny.py", line 303, in instantiate
    timedelta(seconds=self.death_timeout), self.process.start()
  File "/scratch/cnt0024/hmg2840/albert7a/anaconda3/lib/python3.7/site-packages/tornado/gen.py", line 729, in run
    value = future.result()
tornado.util.TimeoutError: Timeout
distributed.nanny - ERROR - Timed out connecting Nanny '<Nanny: None, threads: 1>' to scheduler 'tcp://172.30.100.2:42247'
Traceback (most recent call last):
  File "/scratch/cnt0024/hmg2840/albert7a/anaconda3/lib/python3.7/site-packages/distributed/nanny.py", line 303, in instantiate
    timedelta(seconds=self.death_timeout), self.process.start()
  File "/scratch/cnt0024/hmg2840/albert7a/anaconda3/lib/python3.7/site-packages/tornado/gen.py", line 729, in run
    value = future.result()
tornado.util.TimeoutError: Timeout
distributed.nanny - ERROR - Timed out connecting Nanny '<Nanny: None, threads: 1>' to scheduler 'tcp://172.30.100.2:42247'
Traceback (most recent call last):
  File "/scratch/cnt0024/hmg2840/albert7a/anaconda3/lib/python3.7/site-packages/distributed/nanny.py", line 303, in instantiate
    timedelta(seconds=self.death_timeout), self.process.start()
  File "/scratch/cnt0024/hmg2840/albert7a/anaconda3/lib/python3.7/site-packages/tornado/gen.py", line 729, in run
    value = future.result()
tornado.util.TimeoutError: Timeout
distributed.nanny - ERROR - Timed out connecting Nanny '<Nanny: None, threads: 1>' to scheduler 'tcp://172.30.100.2:42247'
Traceback (most recent call last):
  File "/scratch/cnt0024/hmg2840/albert7a/anaconda3/lib/python3.7/site-packages/distributed/nanny.py", line 303, in instantiate
    timedelta(seconds=self.death_timeout), self.process.start()
  File "/scratch/cnt0024/hmg2840/albert7a/anaconda3/lib/python3.7/site-packages/tornado/gen.py", line 729, in run
    value = future.result()
tornado.util.TimeoutError: Timeout
distributed.nanny - ERROR - Timed out connecting Nanny '<Nanny: None, threads: 1>' to scheduler 'tcp://172.30.100.2:42247'
Traceback (most recent call last):
  File "/scratch/cnt0024/hmg2840/albert7a/anaconda3/lib/python3.7/site-packages/distributed/nanny.py", line 303, in instantiate
    timedelta(seconds=self.death_timeout), self.process.start()
  File "/scratch/cnt0024/hmg2840/albert7a/anaconda3/lib/python3.7/site-packages/tornado/gen.py", line 729, in run
    value = future.result()
tornado.util.TimeoutError: Timeout
distributed.nanny - ERROR - Timed out connecting Nanny '<Nanny: None, threads: 1>' to scheduler 'tcp://172.30.100.2:42247'
Traceback (most recent call last):
  File "/scratch/cnt0024/hmg2840/albert7a/anaconda3/lib/python3.7/site-packages/distributed/nanny.py", line 303, in instantiate
    timedelta(seconds=self.death_timeout), self.process.start()
  File "/scratch/cnt0024/hmg2840/albert7a/anaconda3/lib/python3.7/site-packages/tornado/gen.py", line 729, in run
    value = future.result()
tornado.util.TimeoutError: Timeout
distributed.nanny - ERROR - Timed out connecting Nanny '<Nanny: None, threads: 1>' to scheduler 'tcp://172.30.100.2:42247'
Traceback (most recent call last):
  File "/scratch/cnt0024/hmg2840/albert7a/anaconda3/lib/python3.7/site-packages/distributed/nanny.py", line 303, in instantiate
    timedelta(seconds=self.death_timeout), self.process.start()
  File "/scratch/cnt0024/hmg2840/albert7a/anaconda3/lib/python3.7/site-packages/tornado/gen.py", line 729, in run
    value = future.result()
tornado.util.TimeoutError: Timeout
distributed.nanny - ERROR - Timed out connecting Nanny '<Nanny: None, threads: 1>' to scheduler 'tcp://172.30.100.2:42247'
Traceback (most recent call last):
  File "/scratch/cnt0024/hmg2840/albert7a/anaconda3/lib/python3.7/site-packages/distributed/nanny.py", line 303, in instantiate
    timedelta(seconds=self.death_timeout), self.process.start()
  File "/scratch/cnt0024/hmg2840/albert7a/anaconda3/lib/python3.7/site-packages/tornado/gen.py", line 729, in run
    value = future.result()
tornado.util.TimeoutError: Timeout
distributed.nanny - ERROR - Timed out connecting Nanny '<Nanny: None, threads: 1>' to scheduler 'tcp://172.30.100.2:42247'
Traceback (most recent call last):
  File "/scratch/cnt0024/hmg2840/albert7a/anaconda3/lib/python3.7/site-packages/distributed/nanny.py", line 303, in instantiate
    timedelta(seconds=self.death_timeout), self.process.start()
  File "/scratch/cnt0024/hmg2840/albert7a/anaconda3/lib/python3.7/site-packages/tornado/gen.py", line 729, in run
    value = future.result()
tornado.util.TimeoutError: Timeout
distributed.nanny - ERROR - Timed out connecting Nanny '<Nanny: None, threads: 1>' to scheduler 'tcp://172.30.100.2:42247'
Traceback (most recent call last):
  File "/scratch/cnt0024/hmg2840/albert7a/anaconda3/lib/python3.7/site-packages/distributed/nanny.py", line 303, in instantiate
    timedelta(seconds=self.death_timeout), self.process.start()
  File "/scratch/cnt0024/hmg2840/albert7a/anaconda3/lib/python3.7/site-packages/tornado/gen.py", line 729, in run
    value = future.result()
tornado.util.TimeoutError: Timeout
distributed.nanny - ERROR - Timed out connecting Nanny '<Nanny: None, threads: 1>' to scheduler 'tcp://172.30.100.2:42247'
Traceback (most recent call last):
  File "/scratch/cnt0024/hmg2840/albert7a/anaconda3/lib/python3.7/site-packages/distributed/nanny.py", line 303, in instantiate
    timedelta(seconds=self.death_timeout), self.process.start()
  File "/scratch/cnt0024/hmg2840/albert7a/anaconda3/lib/python3.7/site-packages/tornado/gen.py", line 729, in run
    value = future.result()
tornado.util.TimeoutError: Timeout
distributed.nanny - ERROR - Timed out connecting Nanny '<Nanny: None, threads: 1>' to scheduler 'tcp://172.30.100.2:42247'
Traceback (most recent call last):
  File "/scratch/cnt0024/hmg2840/albert7a/anaconda3/lib/python3.7/site-packages/distributed/nanny.py", line 303, in instantiate
    timedelta(seconds=self.death_timeout), self.process.start()
  File "/scratch/cnt0024/hmg2840/albert7a/anaconda3/lib/python3.7/site-packages/tornado/gen.py", line 729, in run
    value = future.result()
tornado.util.TimeoutError: Timeout
distributed.nanny - ERROR - Timed out connecting Nanny '<Nanny: None, threads: 1>' to scheduler 'tcp://172.30.100.2:42247'
Traceback (most recent call last):
  File "/scratch/cnt0024/hmg2840/albert7a/anaconda3/lib/python3.7/site-packages/distributed/nanny.py", line 303, in instantiate
    timedelta(seconds=self.death_timeout), self.process.start()
  File "/scratch/cnt0024/hmg2840/albert7a/anaconda3/lib/python3.7/site-packages/tornado/gen.py", line 729, in run
    value = future.result()
tornado.util.TimeoutError: Timeout
distributed.nanny - ERROR - Timed out connecting Nanny '<Nanny: None, threads: 1>' to scheduler 'tcp://172.30.100.2:42247'
Traceback (most recent call last):
  File "/scratch/cnt0024/hmg2840/albert7a/anaconda3/lib/python3.7/site-packages/distributed/nanny.py", line 303, in instantiate
    timedelta(seconds=self.death_timeout), self.process.start()
  File "/scratch/cnt0024/hmg2840/albert7a/anaconda3/lib/python3.7/site-packages/tornado/gen.py", line 729, in run
    value = future.result()
tornado.util.TimeoutError: Timeout
distributed.nanny - ERROR - Timed out connecting Nanny '<Nanny: None, threads: 1>' to scheduler 'tcp://172.30.100.2:42247'
Traceback (most recent call last):
  File "/scratch/cnt0024/hmg2840/albert7a/anaconda3/lib/python3.7/site-packages/distributed/nanny.py", line 303, in instantiate
    timedelta(seconds=self.death_timeout), self.process.start()
  File "/scratch/cnt0024/hmg2840/albert7a/anaconda3/lib/python3.7/site-packages/tornado/gen.py", line 729, in run
    value = future.result()
tornado.util.TimeoutError: Timeout
distributed.nanny - ERROR - Timed out connecting Nanny '<Nanny: None, threads: 1>' to scheduler 'tcp://172.30.100.2:42247'
Traceback (most recent call last):
  File "/scratch/cnt0024/hmg2840/albert7a/anaconda3/lib/python3.7/site-packages/distributed/nanny.py", line 303, in instantiate
    timedelta(seconds=self.death_timeout), self.process.start()
  File "/scratch/cnt0024/hmg2840/albert7a/anaconda3/lib/python3.7/site-packages/tornado/gen.py", line 729, in run
    value = future.result()
tornado.util.TimeoutError: Timeout
distributed.nanny - ERROR - Timed out connecting Nanny '<Nanny: None, threads: 1>' to scheduler 'tcp://172.30.100.2:42247'
Traceback (most recent call last):
  File "/scratch/cnt0024/hmg2840/albert7a/anaconda3/lib/python3.7/site-packages/distributed/nanny.py", line 303, in instantiate
    timedelta(seconds=self.death_timeout), self.process.start()
  File "/scratch/cnt0024/hmg2840/albert7a/anaconda3/lib/python3.7/site-packages/tornado/gen.py", line 729, in run
    value = future.result()
tornado.util.TimeoutError: Timeout
distributed.nanny - ERROR - Timed out connecting Nanny '<Nanny: None, threads: 1>' to scheduler 'tcp://172.30.100.2:42247'
Traceback (most recent call last):
  File "/scratch/cnt0024/hmg2840/albert7a/anaconda3/lib/python3.7/site-packages/distributed/nanny.py", line 303, in instantiate
    timedelta(seconds=self.death_timeout), self.process.start()
  File "/scratch/cnt0024/hmg2840/albert7a/anaconda3/lib/python3.7/site-packages/tornado/gen.py", line 729, in run
    value = future.result()
tornado.util.TimeoutError: Timeout
tornado.application - ERROR - Multiple exceptions in yield list
Traceback (most recent call last):
  File "/scratch/cnt0024/hmg2840/albert7a/anaconda3/lib/python3.7/site-packages/tornado/gen.py", line 501, in callback
    result_list.append(f.result())
  File "/scratch/cnt0024/hmg2840/albert7a/anaconda3/lib/python3.7/asyncio/tasks.py", line 603, in _wrap_awaitable
    return (yield from awaitable.__await__())
  File "/scratch/cnt0024/hmg2840/albert7a/anaconda3/lib/python3.7/site-packages/tornado/gen.py", line 736, in run
    yielded = self.gen.throw(*exc_info)  # type: ignore
  File "/scratch/cnt0024/hmg2840/albert7a/anaconda3/lib/python3.7/site-packages/distributed/nanny.py", line 224, in _start
    response = yield self.instantiate()
  File "/scratch/cnt0024/hmg2840/albert7a/anaconda3/lib/python3.7/site-packages/tornado/gen.py", line 729, in run
    value = future.result()
  File "/scratch/cnt0024/hmg2840/albert7a/anaconda3/lib/python3.7/site-packages/tornado/gen.py", line 742, in run
    yielded = self.gen.send(value)
  File "/scratch/cnt0024/hmg2840/albert7a/anaconda3/lib/python3.7/site-packages/distributed/nanny.py", line 303, in instantiate
    timedelta(seconds=self.death_timeout), self.process.start()
  File "/scratch/cnt0024/hmg2840/albert7a/anaconda3/lib/python3.7/site-packages/tornado/gen.py", line 729, in run
    value = future.result()
tornado.util.TimeoutError: Timeout
tornado.application - ERROR - Multiple exceptions in yield list
Traceback (most recent call last):
  File "/scratch/cnt0024/hmg2840/albert7a/anaconda3/lib/python3.7/site-packages/tornado/gen.py", line 501, in callback
    result_list.append(f.result())
  File "/scratch/cnt0024/hmg2840/albert7a/anaconda3/lib/python3.7/asyncio/tasks.py", line 603, in _wrap_awaitable
    return (yield from awaitable.__await__())
  File "/scratch/cnt0024/hmg2840/albert7a/anaconda3/lib/python3.7/site-packages/tornado/gen.py", line 736, in run
    yielded = self.gen.throw(*exc_info)  # type: ignore
  File "/scratch/cnt0024/hmg2840/albert7a/anaconda3/lib/python3.7/site-packages/distributed/nanny.py", line 224, in _start
    response = yield self.instantiate()
  File "/scratch/cnt0024/hmg2840/albert7a/anaconda3/lib/python3.7/site-packages/tornado/gen.py", line 729, in run
    value = future.result()
  File "/scratch/cnt0024/hmg2840/albert7a/anaconda3/lib/python3.7/site-packages/tornado/gen.py", line 742, in run
    yielded = self.gen.send(value)
  File "/scratch/cnt0024/hmg2840/albert7a/anaconda3/lib/python3.7/site-packages/distributed/nanny.py", line 303, in instantiate
    timedelta(seconds=self.death_timeout), self.process.start()
  File "/scratch/cnt0024/hmg2840/albert7a/anaconda3/lib/python3.7/site-packages/tornado/gen.py", line 729, in run
    value = future.result()
tornado.util.TimeoutError: Timeout
tornado.application - ERROR - Multiple exceptions in yield list
Traceback (most recent call last):
  File "/scratch/cnt0024/hmg2840/albert7a/anaconda3/lib/python3.7/site-packages/tornado/gen.py", line 501, in callback
    result_list.append(f.result())
  File "/scratch/cnt0024/hmg2840/albert7a/anaconda3/lib/python3.7/asyncio/tasks.py", line 603, in _wrap_awaitable
    return (yield from awaitable.__await__())
  File "/scratch/cnt0024/hmg2840/albert7a/anaconda3/lib/python3.7/site-packages/tornado/gen.py", line 736, in run
    yielded = self.gen.throw(*exc_info)  # type: ignore
  File "/scratch/cnt0024/hmg2840/albert7a/anaconda3/lib/python3.7/site-packages/distributed/nanny.py", line 224, in _start
    response = yield self.instantiate()
  File "/scratch/cnt0024/hmg2840/albert7a/anaconda3/lib/python3.7/site-packages/tornado/gen.py", line 729, in run
    value = future.result()
  File "/scratch/cnt0024/hmg2840/albert7a/anaconda3/lib/python3.7/site-packages/tornado/gen.py", line 742, in run
    yielded = self.gen.send(value)
  File "/scratch/cnt0024/hmg2840/albert7a/anaconda3/lib/python3.7/site-packages/distributed/nanny.py", line 303, in instantiate
    timedelta(seconds=self.death_timeout), self.process.start()
  File "/scratch/cnt0024/hmg2840/albert7a/anaconda3/lib/python3.7/site-packages/tornado/gen.py", line 729, in run
    value = future.result()
tornado.util.TimeoutError: Timeout
tornado.application - ERROR - Multiple exceptions in yield list
Traceback (most recent call last):
  File "/scratch/cnt0024/hmg2840/albert7a/anaconda3/lib/python3.7/site-packages/tornado/gen.py", line 501, in callback
    result_list.append(f.result())
  File "/scratch/cnt0024/hmg2840/albert7a/anaconda3/lib/python3.7/asyncio/tasks.py", line 603, in _wrap_awaitable
    return (yield from awaitable.__await__())
  File "/scratch/cnt0024/hmg2840/albert7a/anaconda3/lib/python3.7/site-packages/tornado/gen.py", line 736, in run
    yielded = self.gen.throw(*exc_info)  # type: ignore
  File "/scratch/cnt0024/hmg2840/albert7a/anaconda3/lib/python3.7/site-packages/distributed/nanny.py", line 224, in _start
    response = yield self.instantiate()
  File "/scratch/cnt0024/hmg2840/albert7a/anaconda3/lib/python3.7/site-packages/tornado/gen.py", line 729, in run
    value = future.result()
  File "/scratch/cnt0024/hmg2840/albert7a/anaconda3/lib/python3.7/site-packages/tornado/gen.py", line 742, in run
    yielded = self.gen.send(value)
  File "/scratch/cnt0024/hmg2840/albert7a/anaconda3/lib/python3.7/site-packages/distributed/nanny.py", line 303, in instantiate
    timedelta(seconds=self.death_timeout), self.process.start()
  File "/scratch/cnt0024/hmg2840/albert7a/anaconda3/lib/python3.7/site-packages/tornado/gen.py", line 729, in run
    value = future.result()
tornado.util.TimeoutError: Timeout
tornado.application - ERROR - Multiple exceptions in yield list
Traceback (most recent call last):
  File "/scratch/cnt0024/hmg2840/albert7a/anaconda3/lib/python3.7/site-packages/tornado/gen.py", line 501, in callback
    result_list.append(f.result())
  File "/scratch/cnt0024/hmg2840/albert7a/anaconda3/lib/python3.7/asyncio/tasks.py", line 603, in _wrap_awaitable
    return (yield from awaitable.__await__())
  File "/scratch/cnt0024/hmg2840/albert7a/anaconda3/lib/python3.7/site-packages/tornado/gen.py", line 736, in run
    yielded = self.gen.throw(*exc_info)  # type: ignore
  File "/scratch/cnt0024/hmg2840/albert7a/anaconda3/lib/python3.7/site-packages/distributed/nanny.py", line 224, in _start
    response = yield self.instantiate()
  File "/scratch/cnt0024/hmg2840/albert7a/anaconda3/lib/python3.7/site-packages/tornado/gen.py", line 729, in run
    value = future.result()
  File "/scratch/cnt0024/hmg2840/albert7a/anaconda3/lib/python3.7/site-packages/tornado/gen.py", line 742, in run
    yielded = self.gen.send(value)
  File "/scratch/cnt0024/hmg2840/albert7a/anaconda3/lib/python3.7/site-packages/distributed/nanny.py", line 303, in instantiate
    timedelta(seconds=self.death_timeout), self.process.start()
  File "/scratch/cnt0024/hmg2840/albert7a/anaconda3/lib/python3.7/site-packages/tornado/gen.py", line 729, in run
    value = future.result()
tornado.util.TimeoutError: Timeout
tornado.application - ERROR - Multiple exceptions in yield list
Traceback (most recent call last):
  File "/scratch/cnt0024/hmg2840/albert7a/anaconda3/lib/python3.7/site-packages/tornado/gen.py", line 501, in callback
    result_list.append(f.result())
  File "/scratch/cnt0024/hmg2840/albert7a/anaconda3/lib/python3.7/asyncio/tasks.py", line 603, in _wrap_awaitable
    return (yield from awaitable.__await__())
  File "/scratch/cnt0024/hmg2840/albert7a/anaconda3/lib/python3.7/site-packages/tornado/gen.py", line 736, in run
    yielded = self.gen.throw(*exc_info)  # type: ignore
  File "/scratch/cnt0024/hmg2840/albert7a/anaconda3/lib/python3.7/site-packages/distributed/nanny.py", line 224, in _start
    response = yield self.instantiate()
  File "/scratch/cnt0024/hmg2840/albert7a/anaconda3/lib/python3.7/site-packages/tornado/gen.py", line 729, in run
    value = future.result()
  File "/scratch/cnt0024/hmg2840/albert7a/anaconda3/lib/python3.7/site-packages/tornado/gen.py", line 742, in run
    yielded = self.gen.send(value)
  File "/scratch/cnt0024/hmg2840/albert7a/anaconda3/lib/python3.7/site-packages/distributed/nanny.py", line 303, in instantiate
    timedelta(seconds=self.death_timeout), self.process.start()
  File "/scratch/cnt0024/hmg2840/albert7a/anaconda3/lib/python3.7/site-packages/tornado/gen.py", line 729, in run
    value = future.result()
tornado.util.TimeoutError: Timeout
tornado.application - ERROR - Multiple exceptions in yield list
Traceback (most recent call last):
  File "/scratch/cnt0024/hmg2840/albert7a/anaconda3/lib/python3.7/site-packages/tornado/gen.py", line 501, in callback
    result_list.append(f.result())
  File "/scratch/cnt0024/hmg2840/albert7a/anaconda3/lib/python3.7/asyncio/tasks.py", line 603, in _wrap_awaitable
    return (yield from awaitable.__await__())
  File "/scratch/cnt0024/hmg2840/albert7a/anaconda3/lib/python3.7/site-packages/tornado/gen.py", line 736, in run
    yielded = self.gen.throw(*exc_info)  # type: ignore
  File "/scratch/cnt0024/hmg2840/albert7a/anaconda3/lib/python3.7/site-packages/distributed/nanny.py", line 224, in _start
    response = yield self.instantiate()
  File "/scratch/cnt0024/hmg2840/albert7a/anaconda3/lib/python3.7/site-packages/tornado/gen.py", line 729, in run
    value = future.result()
  File "/scratch/cnt0024/hmg2840/albert7a/anaconda3/lib/python3.7/site-packages/tornado/gen.py", line 742, in run
    yielded = self.gen.send(value)
  File "/scratch/cnt0024/hmg2840/albert7a/anaconda3/lib/python3.7/site-packages/distributed/nanny.py", line 303, in instantiate
    timedelta(seconds=self.death_timeout), self.process.start()
  File "/scratch/cnt0024/hmg2840/albert7a/anaconda3/lib/python3.7/site-packages/tornado/gen.py", line 729, in run
    value = future.result()
tornado.util.TimeoutError: Timeout
tornado.application - ERROR - Multiple exceptions in yield list
Traceback (most recent call last):
  File "/scratch/cnt0024/hmg2840/albert7a/anaconda3/lib/python3.7/site-packages/tornado/gen.py", line 501, in callback
    result_list.append(f.result())
  File "/scratch/cnt0024/hmg2840/albert7a/anaconda3/lib/python3.7/asyncio/tasks.py", line 603, in _wrap_awaitable
    return (yield from awaitable.__await__())
  File "/scratch/cnt0024/hmg2840/albert7a/anaconda3/lib/python3.7/site-packages/tornado/gen.py", line 736, in run
    yielded = self.gen.throw(*exc_info)  # type: ignore
  File "/scratch/cnt0024/hmg2840/albert7a/anaconda3/lib/python3.7/site-packages/distributed/nanny.py", line 224, in _start
    response = yield self.instantiate()
  File "/scratch/cnt0024/hmg2840/albert7a/anaconda3/lib/python3.7/site-packages/tornado/gen.py", line 729, in run
    value = future.result()
  File "/scratch/cnt0024/hmg2840/albert7a/anaconda3/lib/python3.7/site-packages/tornado/gen.py", line 742, in run
    yielded = self.gen.send(value)
  File "/scratch/cnt0024/hmg2840/albert7a/anaconda3/lib/python3.7/site-packages/distributed/nanny.py", line 303, in instantiate
    timedelta(seconds=self.death_timeout), self.process.start()
  File "/scratch/cnt0024/hmg2840/albert7a/anaconda3/lib/python3.7/site-packages/tornado/gen.py", line 729, in run
    value = future.result()
tornado.util.TimeoutError: Timeout
tornado.application - ERROR - Multiple exceptions in yield list
Traceback (most recent call last):
  File "/scratch/cnt0024/hmg2840/albert7a/anaconda3/lib/python3.7/site-packages/tornado/gen.py", line 501, in callback
    result_list.append(f.result())
  File "/scratch/cnt0024/hmg2840/albert7a/anaconda3/lib/python3.7/asyncio/tasks.py", line 603, in _wrap_awaitable
    return (yield from awaitable.__await__())
  File "/scratch/cnt0024/hmg2840/albert7a/anaconda3/lib/python3.7/site-packages/tornado/gen.py", line 736, in run
    yielded = self.gen.throw(*exc_info)  # type: ignore
  File "/scratch/cnt0024/hmg2840/albert7a/anaconda3/lib/python3.7/site-packages/distributed/nanny.py", line 224, in _start
    response = yield self.instantiate()
  File "/scratch/cnt0024/hmg2840/albert7a/anaconda3/lib/python3.7/site-packages/tornado/gen.py", line 729, in run
    value = future.result()
  File "/scratch/cnt0024/hmg2840/albert7a/anaconda3/lib/python3.7/site-packages/tornado/gen.py", line 742, in run
    yielded = self.gen.send(value)
  File "/scratch/cnt0024/hmg2840/albert7a/anaconda3/lib/python3.7/site-packages/distributed/nanny.py", line 303, in instantiate
    timedelta(seconds=self.death_timeout), self.process.start()
  File "/scratch/cnt0024/hmg2840/albert7a/anaconda3/lib/python3.7/site-packages/tornado/gen.py", line 729, in run
    value = future.result()
tornado.util.TimeoutError: Timeout
tornado.application - ERROR - Multiple exceptions in yield list
Traceback (most recent call last):
  File "/scratch/cnt0024/hmg2840/albert7a/anaconda3/lib/python3.7/site-packages/tornado/gen.py", line 501, in callback
    result_list.append(f.result())
  File "/scratch/cnt0024/hmg2840/albert7a/anaconda3/lib/python3.7/asyncio/tasks.py", line 603, in _wrap_awaitable
    return (yield from awaitable.__await__())
  File "/scratch/cnt0024/hmg2840/albert7a/anaconda3/lib/python3.7/site-packages/tornado/gen.py", line 736, in run
    yielded = self.gen.throw(*exc_info)  # type: ignore
  File "/scratch/cnt0024/hmg2840/albert7a/anaconda3/lib/python3.7/site-packages/distributed/nanny.py", line 224, in _start
    response = yield self.instantiate()
  File "/scratch/cnt0024/hmg2840/albert7a/anaconda3/lib/python3.7/site-packages/tornado/gen.py", line 729, in run
    value = future.result()
  File "/scratch/cnt0024/hmg2840/albert7a/anaconda3/lib/python3.7/site-packages/tornado/gen.py", line 742, in run
    yielded = self.gen.send(value)
  File "/scratch/cnt0024/hmg2840/albert7a/anaconda3/lib/python3.7/site-packages/distributed/nanny.py", line 303, in instantiate
    timedelta(seconds=self.death_timeout), self.process.start()
  File "/scratch/cnt0024/hmg2840/albert7a/anaconda3/lib/python3.7/site-packages/tornado/gen.py", line 729, in run
    value = future.result()
tornado.util.TimeoutError: Timeout
tornado.application - ERROR - Multiple exceptions in yield list
Traceback (most recent call last):
  File "/scratch/cnt0024/hmg2840/albert7a/anaconda3/lib/python3.7/site-packages/tornado/gen.py", line 501, in callback
    result_list.append(f.result())
  File "/scratch/cnt0024/hmg2840/albert7a/anaconda3/lib/python3.7/asyncio/tasks.py", line 603, in _wrap_awaitable
    return (yield from awaitable.__await__())
  File "/scratch/cnt0024/hmg2840/albert7a/anaconda3/lib/python3.7/site-packages/tornado/gen.py", line 736, in run
    yielded = self.gen.throw(*exc_info)  # type: ignore
  File "/scratch/cnt0024/hmg2840/albert7a/anaconda3/lib/python3.7/site-packages/distributed/nanny.py", line 224, in _start
    response = yield self.instantiate()
  File "/scratch/cnt0024/hmg2840/albert7a/anaconda3/lib/python3.7/site-packages/tornado/gen.py", line 729, in run
    value = future.result()
  File "/scratch/cnt0024/hmg2840/albert7a/anaconda3/lib/python3.7/site-packages/tornado/gen.py", line 742, in run
    yielded = self.gen.send(value)
  File "/scratch/cnt0024/hmg2840/albert7a/anaconda3/lib/python3.7/site-packages/distributed/nanny.py", line 303, in instantiate
    timedelta(seconds=self.death_timeout), self.process.start()
  File "/scratch/cnt0024/hmg2840/albert7a/anaconda3/lib/python3.7/site-packages/tornado/gen.py", line 729, in run
    value = future.result()
tornado.util.TimeoutError: Timeout
tornado.application - ERROR - Multiple exceptions in yield list
Traceback (most recent call last):
  File "/scratch/cnt0024/hmg2840/albert7a/anaconda3/lib/python3.7/site-packages/tornado/gen.py", line 501, in callback
    result_list.append(f.result())
  File "/scratch/cnt0024/hmg2840/albert7a/anaconda3/lib/python3.7/asyncio/tasks.py", line 603, in _wrap_awaitable
    return (yield from awaitable.__await__())
  File "/scratch/cnt0024/hmg2840/albert7a/anaconda3/lib/python3.7/site-packages/tornado/gen.py", line 736, in run
    yielded = self.gen.throw(*exc_info)  # type: ignore
  File "/scratch/cnt0024/hmg2840/albert7a/anaconda3/lib/python3.7/site-packages/distributed/nanny.py", line 224, in _start
    response = yield self.instantiate()
  File "/scratch/cnt0024/hmg2840/albert7a/anaconda3/lib/python3.7/site-packages/tornado/gen.py", line 729, in run
    value = future.result()
  File "/scratch/cnt0024/hmg2840/albert7a/anaconda3/lib/python3.7/site-packages/tornado/gen.py", line 742, in run
    yielded = self.gen.send(value)
  File "/scratch/cnt0024/hmg2840/albert7a/anaconda3/lib/python3.7/site-packages/distributed/nanny.py", line 303, in instantiate
    timedelta(seconds=self.death_timeout), self.process.start()
  File "/scratch/cnt0024/hmg2840/albert7a/anaconda3/lib/python3.7/site-packages/tornado/gen.py", line 729, in run
    value = future.result()
tornado.util.TimeoutError: Timeout
tornado.application - ERROR - Multiple exceptions in yield list
Traceback (most recent call last):
  File "/scratch/cnt0024/hmg2840/albert7a/anaconda3/lib/python3.7/site-packages/tornado/gen.py", line 501, in callback
    result_list.append(f.result())
  File "/scratch/cnt0024/hmg2840/albert7a/anaconda3/lib/python3.7/asyncio/tasks.py", line 603, in _wrap_awaitable
    return (yield from awaitable.__await__())
  File "/scratch/cnt0024/hmg2840/albert7a/anaconda3/lib/python3.7/site-packages/tornado/gen.py", line 736, in run
    yielded = self.gen.throw(*exc_info)  # type: ignore
  File "/scratch/cnt0024/hmg2840/albert7a/anaconda3/lib/python3.7/site-packages/distributed/nanny.py", line 224, in _start
    response = yield self.instantiate()
  File "/scratch/cnt0024/hmg2840/albert7a/anaconda3/lib/python3.7/site-packages/tornado/gen.py", line 729, in run
    value = future.result()
  File "/scratch/cnt0024/hmg2840/albert7a/anaconda3/lib/python3.7/site-packages/tornado/gen.py", line 742, in run
    yielded = self.gen.send(value)
  File "/scratch/cnt0024/hmg2840/albert7a/anaconda3/lib/python3.7/site-packages/distributed/nanny.py", line 303, in instantiate
    timedelta(seconds=self.death_timeout), self.process.start()
  File "/scratch/cnt0024/hmg2840/albert7a/anaconda3/lib/python3.7/site-packages/tornado/gen.py", line 729, in run
    value = future.result()
tornado.util.TimeoutError: Timeout
tornado.application - ERROR - Multiple exceptions in yield list
Traceback (most recent call last):
  File "/scratch/cnt0024/hmg2840/albert7a/anaconda3/lib/python3.7/site-packages/tornado/gen.py", line 501, in callback
    result_list.append(f.result())
  File "/scratch/cnt0024/hmg2840/albert7a/anaconda3/lib/python3.7/asyncio/tasks.py", line 603, in _wrap_awaitable
    return (yield from awaitable.__await__())
  File "/scratch/cnt0024/hmg2840/albert7a/anaconda3/lib/python3.7/site-packages/tornado/gen.py", line 736, in run
    yielded = self.gen.throw(*exc_info)  # type: ignore
  File "/scratch/cnt0024/hmg2840/albert7a/anaconda3/lib/python3.7/site-packages/distributed/nanny.py", line 224, in _start
    response = yield self.instantiate()
  File "/scratch/cnt0024/hmg2840/albert7a/anaconda3/lib/python3.7/site-packages/tornado/gen.py", line 729, in run
    value = future.result()
  File "/scratch/cnt0024/hmg2840/albert7a/anaconda3/lib/python3.7/site-packages/tornado/gen.py", line 742, in run
    yielded = self.gen.send(value)
  File "/scratch/cnt0024/hmg2840/albert7a/anaconda3/lib/python3.7/site-packages/distributed/nanny.py", line 303, in instantiate
    timedelta(seconds=self.death_timeout), self.process.start()
  File "/scratch/cnt0024/hmg2840/albert7a/anaconda3/lib/python3.7/site-packages/tornado/gen.py", line 729, in run
    value = future.result()
tornado.util.TimeoutError: Timeout
tornado.application - ERROR - Multiple exceptions in yield list
Traceback (most recent call last):
  File "/scratch/cnt0024/hmg2840/albert7a/anaconda3/lib/python3.7/site-packages/tornado/gen.py", line 501, in callback
    result_list.append(f.result())
  File "/scratch/cnt0024/hmg2840/albert7a/anaconda3/lib/python3.7/asyncio/tasks.py", line 603, in _wrap_awaitable
    return (yield from awaitable.__await__())
  File "/scratch/cnt0024/hmg2840/albert7a/anaconda3/lib/python3.7/site-packages/tornado/gen.py", line 736, in run
    yielded = self.gen.throw(*exc_info)  # type: ignore
  File "/scratch/cnt0024/hmg2840/albert7a/anaconda3/lib/python3.7/site-packages/distributed/nanny.py", line 224, in _start
    response = yield self.instantiate()
  File "/scratch/cnt0024/hmg2840/albert7a/anaconda3/lib/python3.7/site-packages/tornado/gen.py", line 729, in run
    value = future.result()
  File "/scratch/cnt0024/hmg2840/albert7a/anaconda3/lib/python3.7/site-packages/tornado/gen.py", line 742, in run
    yielded = self.gen.send(value)
  File "/scratch/cnt0024/hmg2840/albert7a/anaconda3/lib/python3.7/site-packages/distributed/nanny.py", line 303, in instantiate
    timedelta(seconds=self.death_timeout), self.process.start()
  File "/scratch/cnt0024/hmg2840/albert7a/anaconda3/lib/python3.7/site-packages/tornado/gen.py", line 729, in run
    value = future.result()
tornado.util.TimeoutError: Timeout
tornado.application - ERROR - Multiple exceptions in yield list
Traceback (most recent call last):
  File "/scratch/cnt0024/hmg2840/albert7a/anaconda3/lib/python3.7/site-packages/tornado/gen.py", line 501, in callback
    result_list.append(f.result())
  File "/scratch/cnt0024/hmg2840/albert7a/anaconda3/lib/python3.7/asyncio/tasks.py", line 603, in _wrap_awaitable
    return (yield from awaitable.__await__())
  File "/scratch/cnt0024/hmg2840/albert7a/anaconda3/lib/python3.7/site-packages/tornado/gen.py", line 736, in run
    yielded = self.gen.throw(*exc_info)  # type: ignore
  File "/scratch/cnt0024/hmg2840/albert7a/anaconda3/lib/python3.7/site-packages/distributed/nanny.py", line 224, in _start
    response = yield self.instantiate()
  File "/scratch/cnt0024/hmg2840/albert7a/anaconda3/lib/python3.7/site-packages/tornado/gen.py", line 729, in run
    value = future.result()
  File "/scratch/cnt0024/hmg2840/albert7a/anaconda3/lib/python3.7/site-packages/tornado/gen.py", line 742, in run
    yielded = self.gen.send(value)
  File "/scratch/cnt0024/hmg2840/albert7a/anaconda3/lib/python3.7/site-packages/distributed/nanny.py", line 303, in instantiate
    timedelta(seconds=self.death_timeout), self.process.start()
  File "/scratch/cnt0024/hmg2840/albert7a/anaconda3/lib/python3.7/site-packages/tornado/gen.py", line 729, in run
    value = future.result()
tornado.util.TimeoutError: Timeout
tornado.application - ERROR - Multiple exceptions in yield list
Traceback (most recent call last):
  File "/scratch/cnt0024/hmg2840/albert7a/anaconda3/lib/python3.7/site-packages/tornado/gen.py", line 501, in callback
    result_list.append(f.result())
  File "/scratch/cnt0024/hmg2840/albert7a/anaconda3/lib/python3.7/asyncio/tasks.py", line 603, in _wrap_awaitable
    return (yield from awaitable.__await__())
  File "/scratch/cnt0024/hmg2840/albert7a/anaconda3/lib/python3.7/site-packages/tornado/gen.py", line 736, in run
    yielded = self.gen.throw(*exc_info)  # type: ignore
  File "/scratch/cnt0024/hmg2840/albert7a/anaconda3/lib/python3.7/site-packages/distributed/nanny.py", line 224, in _start
    response = yield self.instantiate()
  File "/scratch/cnt0024/hmg2840/albert7a/anaconda3/lib/python3.7/site-packages/tornado/gen.py", line 729, in run
    value = future.result()
  File "/scratch/cnt0024/hmg2840/albert7a/anaconda3/lib/python3.7/site-packages/tornado/gen.py", line 742, in run
    yielded = self.gen.send(value)
  File "/scratch/cnt0024/hmg2840/albert7a/anaconda3/lib/python3.7/site-packages/distributed/nanny.py", line 303, in instantiate
    timedelta(seconds=self.death_timeout), self.process.start()
  File "/scratch/cnt0024/hmg2840/albert7a/anaconda3/lib/python3.7/site-packages/tornado/gen.py", line 729, in run
    value = future.result()
tornado.util.TimeoutError: Timeout
tornado.application - ERROR - Multiple exceptions in yield list
Traceback (most recent call last):
  File "/scratch/cnt0024/hmg2840/albert7a/anaconda3/lib/python3.7/site-packages/tornado/gen.py", line 501, in callback
    result_list.append(f.result())
  File "/scratch/cnt0024/hmg2840/albert7a/anaconda3/lib/python3.7/asyncio/tasks.py", line 603, in _wrap_awaitable
    return (yield from awaitable.__await__())
  File "/scratch/cnt0024/hmg2840/albert7a/anaconda3/lib/python3.7/site-packages/tornado/gen.py", line 736, in run
    yielded = self.gen.throw(*exc_info)  # type: ignore
  File "/scratch/cnt0024/hmg2840/albert7a/anaconda3/lib/python3.7/site-packages/distributed/nanny.py", line 224, in _start
    response = yield self.instantiate()
  File "/scratch/cnt0024/hmg2840/albert7a/anaconda3/lib/python3.7/site-packages/tornado/gen.py", line 729, in run
    value = future.result()
  File "/scratch/cnt0024/hmg2840/albert7a/anaconda3/lib/python3.7/site-packages/tornado/gen.py", line 742, in run
    yielded = self.gen.send(value)
  File "/scratch/cnt0024/hmg2840/albert7a/anaconda3/lib/python3.7/site-packages/distributed/nanny.py", line 303, in instantiate
    timedelta(seconds=self.death_timeout), self.process.start()
  File "/scratch/cnt0024/hmg2840/albert7a/anaconda3/lib/python3.7/site-packages/tornado/gen.py", line 729, in run
    value = future.result()
tornado.util.TimeoutError: Timeout
tornado.application - ERROR - Multiple exceptions in yield list
Traceback (most recent call last):
  File "/scratch/cnt0024/hmg2840/albert7a/anaconda3/lib/python3.7/site-packages/tornado/gen.py", line 501, in callback
    result_list.append(f.result())
  File "/scratch/cnt0024/hmg2840/albert7a/anaconda3/lib/python3.7/asyncio/tasks.py", line 603, in _wrap_awaitable
    return (yield from awaitable.__await__())
  File "/scratch/cnt0024/hmg2840/albert7a/anaconda3/lib/python3.7/site-packages/tornado/gen.py", line 736, in run
    yielded = self.gen.throw(*exc_info)  # type: ignore
  File "/scratch/cnt0024/hmg2840/albert7a/anaconda3/lib/python3.7/site-packages/distributed/nanny.py", line 224, in _start
    response = yield self.instantiate()
  File "/scratch/cnt0024/hmg2840/albert7a/anaconda3/lib/python3.7/site-packages/tornado/gen.py", line 729, in run
    value = future.result()
  File "/scratch/cnt0024/hmg2840/albert7a/anaconda3/lib/python3.7/site-packages/tornado/gen.py", line 742, in run
    yielded = self.gen.send(value)
  File "/scratch/cnt0024/hmg2840/albert7a/anaconda3/lib/python3.7/site-packages/distributed/nanny.py", line 303, in instantiate
    timedelta(seconds=self.death_timeout), self.process.start()
  File "/scratch/cnt0024/hmg2840/albert7a/anaconda3/lib/python3.7/site-packages/tornado/gen.py", line 729, in run
    value = future.result()
tornado.util.TimeoutError: Timeout
tornado.application - ERROR - Multiple exceptions in yield list
Traceback (most recent call last):
  File "/scratch/cnt0024/hmg2840/albert7a/anaconda3/lib/python3.7/site-packages/tornado/gen.py", line 501, in callback
    result_list.append(f.result())
  File "/scratch/cnt0024/hmg2840/albert7a/anaconda3/lib/python3.7/asyncio/tasks.py", line 603, in _wrap_awaitable
    return (yield from awaitable.__await__())
  File "/scratch/cnt0024/hmg2840/albert7a/anaconda3/lib/python3.7/site-packages/tornado/gen.py", line 736, in run
    yielded = self.gen.throw(*exc_info)  # type: ignore
  File "/scratch/cnt0024/hmg2840/albert7a/anaconda3/lib/python3.7/site-packages/distributed/nanny.py", line 224, in _start
    response = yield self.instantiate()
  File "/scratch/cnt0024/hmg2840/albert7a/anaconda3/lib/python3.7/site-packages/tornado/gen.py", line 729, in run
    value = future.result()
  File "/scratch/cnt0024/hmg2840/albert7a/anaconda3/lib/python3.7/site-packages/tornado/gen.py", line 742, in run
    yielded = self.gen.send(value)
  File "/scratch/cnt0024/hmg2840/albert7a/anaconda3/lib/python3.7/site-packages/distributed/nanny.py", line 303, in instantiate
    timedelta(seconds=self.death_timeout), self.process.start()
  File "/scratch/cnt0024/hmg2840/albert7a/anaconda3/lib/python3.7/site-packages/tornado/gen.py", line 729, in run
    value = future.result()
tornado.util.TimeoutError: Timeout
tornado.application - ERROR - Multiple exceptions in yield list
Traceback (most recent call last):
  File "/scratch/cnt0024/hmg2840/albert7a/anaconda3/lib/python3.7/site-packages/tornado/gen.py", line 501, in callback
    result_list.append(f.result())
  File "/scratch/cnt0024/hmg2840/albert7a/anaconda3/lib/python3.7/asyncio/tasks.py", line 603, in _wrap_awaitable
    return (yield from awaitable.__await__())
  File "/scratch/cnt0024/hmg2840/albert7a/anaconda3/lib/python3.7/site-packages/tornado/gen.py", line 736, in run
    yielded = self.gen.throw(*exc_info)  # type: ignore
  File "/scratch/cnt0024/hmg2840/albert7a/anaconda3/lib/python3.7/site-packages/distributed/nanny.py", line 224, in _start
    response = yield self.instantiate()
  File "/scratch/cnt0024/hmg2840/albert7a/anaconda3/lib/python3.7/site-packages/tornado/gen.py", line 729, in run
    value = future.result()
  File "/scratch/cnt0024/hmg2840/albert7a/anaconda3/lib/python3.7/site-packages/tornado/gen.py", line 742, in run
    yielded = self.gen.send(value)
  File "/scratch/cnt0024/hmg2840/albert7a/anaconda3/lib/python3.7/site-packages/distributed/nanny.py", line 303, in instantiate
    timedelta(seconds=self.death_timeout), self.process.start()
  File "/scratch/cnt0024/hmg2840/albert7a/anaconda3/lib/python3.7/site-packages/tornado/gen.py", line 729, in run
    value = future.result()
tornado.util.TimeoutError: Timeout
tornado.application - ERROR - Multiple exceptions in yield list
Traceback (most recent call last):
  File "/scratch/cnt0024/hmg2840/albert7a/anaconda3/lib/python3.7/site-packages/tornado/gen.py", line 501, in callback
    result_list.append(f.result())
  File "/scratch/cnt0024/hmg2840/albert7a/anaconda3/lib/python3.7/asyncio/tasks.py", line 603, in _wrap_awaitable
    return (yield from awaitable.__await__())
  File "/scratch/cnt0024/hmg2840/albert7a/anaconda3/lib/python3.7/site-packages/tornado/gen.py", line 736, in run
    yielded = self.gen.throw(*exc_info)  # type: ignore
  File "/scratch/cnt0024/hmg2840/albert7a/anaconda3/lib/python3.7/site-packages/distributed/nanny.py", line 224, in _start
    response = yield self.instantiate()
  File "/scratch/cnt0024/hmg2840/albert7a/anaconda3/lib/python3.7/site-packages/tornado/gen.py", line 729, in run
    value = future.result()
  File "/scratch/cnt0024/hmg2840/albert7a/anaconda3/lib/python3.7/site-packages/tornado/gen.py", line 742, in run
    yielded = self.gen.send(value)
  File "/scratch/cnt0024/hmg2840/albert7a/anaconda3/lib/python3.7/site-packages/distributed/nanny.py", line 303, in instantiate
    timedelta(seconds=self.death_timeout), self.process.start()
  File "/scratch/cnt0024/hmg2840/albert7a/anaconda3/lib/python3.7/site-packages/tornado/gen.py", line 729, in run
    value = future.result()
tornado.util.TimeoutError: Timeout
tornado.application - ERROR - Multiple exceptions in yield list
Traceback (most recent call last):
  File "/scratch/cnt0024/hmg2840/albert7a/anaconda3/lib/python3.7/site-packages/tornado/gen.py", line 501, in callback
    result_list.append(f.result())
  File "/scratch/cnt0024/hmg2840/albert7a/anaconda3/lib/python3.7/asyncio/tasks.py", line 603, in _wrap_awaitable
    return (yield from awaitable.__await__())
  File "/scratch/cnt0024/hmg2840/albert7a/anaconda3/lib/python3.7/site-packages/tornado/gen.py", line 736, in run
    yielded = self.gen.throw(*exc_info)  # type: ignore
  File "/scratch/cnt0024/hmg2840/albert7a/anaconda3/lib/python3.7/site-packages/distributed/nanny.py", line 224, in _start
    response = yield self.instantiate()
  File "/scratch/cnt0024/hmg2840/albert7a/anaconda3/lib/python3.7/site-packages/tornado/gen.py", line 729, in run
    value = future.result()
  File "/scratch/cnt0024/hmg2840/albert7a/anaconda3/lib/python3.7/site-packages/tornado/gen.py", line 742, in run
    yielded = self.gen.send(value)
  File "/scratch/cnt0024/hmg2840/albert7a/anaconda3/lib/python3.7/site-packages/distributed/nanny.py", line 303, in instantiate
    timedelta(seconds=self.death_timeout), self.process.start()
  File "/scratch/cnt0024/hmg2840/albert7a/anaconda3/lib/python3.7/site-packages/tornado/gen.py", line 729, in run
    value = future.result()
tornado.util.TimeoutError: Timeout
tornado.application - ERROR - Multiple exceptions in yield list
Traceback (most recent call last):
  File "/scratch/cnt0024/hmg2840/albert7a/anaconda3/lib/python3.7/site-packages/tornado/gen.py", line 501, in callback
    result_list.append(f.result())
  File "/scratch/cnt0024/hmg2840/albert7a/anaconda3/lib/python3.7/asyncio/tasks.py", line 603, in _wrap_awaitable
    return (yield from awaitable.__await__())
  File "/scratch/cnt0024/hmg2840/albert7a/anaconda3/lib/python3.7/site-packages/tornado/gen.py", line 736, in run
    yielded = self.gen.throw(*exc_info)  # type: ignore
  File "/scratch/cnt0024/hmg2840/albert7a/anaconda3/lib/python3.7/site-packages/distributed/nanny.py", line 224, in _start
    response = yield self.instantiate()
  File "/scratch/cnt0024/hmg2840/albert7a/anaconda3/lib/python3.7/site-packages/tornado/gen.py", line 729, in run
    value = future.result()
  File "/scratch/cnt0024/hmg2840/albert7a/anaconda3/lib/python3.7/site-packages/tornado/gen.py", line 742, in run
    yielded = self.gen.send(value)
  File "/scratch/cnt0024/hmg2840/albert7a/anaconda3/lib/python3.7/site-packages/distributed/nanny.py", line 303, in instantiate
    timedelta(seconds=self.death_timeout), self.process.start()
  File "/scratch/cnt0024/hmg2840/albert7a/anaconda3/lib/python3.7/site-packages/tornado/gen.py", line 729, in run
    value = future.result()
tornado.util.TimeoutError: Timeout
tornado.application - ERROR - Multiple exceptions in yield list
Traceback (most recent call last):
  File "/scratch/cnt0024/hmg2840/albert7a/anaconda3/lib/python3.7/site-packages/tornado/gen.py", line 501, in callback
    result_list.append(f.result())
  File "/scratch/cnt0024/hmg2840/albert7a/anaconda3/lib/python3.7/asyncio/tasks.py", line 603, in _wrap_awaitable
    return (yield from awaitable.__await__())
  File "/scratch/cnt0024/hmg2840/albert7a/anaconda3/lib/python3.7/site-packages/tornado/gen.py", line 736, in run
    yielded = self.gen.throw(*exc_info)  # type: ignore
  File "/scratch/cnt0024/hmg2840/albert7a/anaconda3/lib/python3.7/site-packages/distributed/nanny.py", line 224, in _start
    response = yield self.instantiate()
  File "/scratch/cnt0024/hmg2840/albert7a/anaconda3/lib/python3.7/site-packages/tornado/gen.py", line 729, in run
    value = future.result()
  File "/scratch/cnt0024/hmg2840/albert7a/anaconda3/lib/python3.7/site-packages/tornado/gen.py", line 742, in run
    yielded = self.gen.send(value)
  File "/scratch/cnt0024/hmg2840/albert7a/anaconda3/lib/python3.7/site-packages/distributed/nanny.py", line 303, in instantiate
    timedelta(seconds=self.death_timeout), self.process.start()
  File "/scratch/cnt0024/hmg2840/albert7a/anaconda3/lib/python3.7/site-packages/tornado/gen.py", line 729, in run
    value = future.result()
tornado.util.TimeoutError: Timeout
tornado.application - ERROR - Multiple exceptions in yield list
Traceback (most recent call last):
  File "/scratch/cnt0024/hmg2840/albert7a/anaconda3/lib/python3.7/site-packages/tornado/gen.py", line 501, in callback
    result_list.append(f.result())
  File "/scratch/cnt0024/hmg2840/albert7a/anaconda3/lib/python3.7/asyncio/tasks.py", line 603, in _wrap_awaitable
    return (yield from awaitable.__await__())
  File "/scratch/cnt0024/hmg2840/albert7a/anaconda3/lib/python3.7/site-packages/tornado/gen.py", line 736, in run
    yielded = self.gen.throw(*exc_info)  # type: ignore
  File "/scratch/cnt0024/hmg2840/albert7a/anaconda3/lib/python3.7/site-packages/distributed/nanny.py", line 224, in _start
    response = yield self.instantiate()
  File "/scratch/cnt0024/hmg2840/albert7a/anaconda3/lib/python3.7/site-packages/tornado/gen.py", line 729, in run
    value = future.result()
  File "/scratch/cnt0024/hmg2840/albert7a/anaconda3/lib/python3.7/site-packages/tornado/gen.py", line 742, in run
    yielded = self.gen.send(value)
  File "/scratch/cnt0024/hmg2840/albert7a/anaconda3/lib/python3.7/site-packages/distributed/nanny.py", line 303, in instantiate
    timedelta(seconds=self.death_timeout), self.process.start()
  File "/scratch/cnt0024/hmg2840/albert7a/anaconda3/lib/python3.7/site-packages/tornado/gen.py", line 729, in run
    value = future.result()
tornado.util.TimeoutError: Timeout
tornado.application - ERROR - Multiple exceptions in yield list
Traceback (most recent call last):
  File "/scratch/cnt0024/hmg2840/albert7a/anaconda3/lib/python3.7/site-packages/tornado/gen.py", line 501, in callback
    result_list.append(f.result())
  File "/scratch/cnt0024/hmg2840/albert7a/anaconda3/lib/python3.7/asyncio/tasks.py", line 603, in _wrap_awaitable
    return (yield from awaitable.__await__())
  File "/scratch/cnt0024/hmg2840/albert7a/anaconda3/lib/python3.7/site-packages/tornado/gen.py", line 736, in run
    yielded = self.gen.throw(*exc_info)  # type: ignore
  File "/scratch/cnt0024/hmg2840/albert7a/anaconda3/lib/python3.7/site-packages/distributed/nanny.py", line 224, in _start
    response = yield self.instantiate()
  File "/scratch/cnt0024/hmg2840/albert7a/anaconda3/lib/python3.7/site-packages/tornado/gen.py", line 729, in run
    value = future.result()
  File "/scratch/cnt0024/hmg2840/albert7a/anaconda3/lib/python3.7/site-packages/tornado/gen.py", line 742, in run
    yielded = self.gen.send(value)
  File "/scratch/cnt0024/hmg2840/albert7a/anaconda3/lib/python3.7/site-packages/distributed/nanny.py", line 303, in instantiate
    timedelta(seconds=self.death_timeout), self.process.start()
  File "/scratch/cnt0024/hmg2840/albert7a/anaconda3/lib/python3.7/site-packages/tornado/gen.py", line 729, in run
    value = future.result()
tornado.util.TimeoutError: Timeout
distributed.dask_worker - INFO - End worker
Traceback (most recent call last):
  File "/scratch/cnt0024/hmg2840/albert7a/anaconda3/lib/python3.7/runpy.py", line 193, in _run_module_as_main
    "__main__", mod_spec)
  File "/scratch/cnt0024/hmg2840/albert7a/anaconda3/lib/python3.7/runpy.py", line 85, in _run_code
    exec(code, run_globals)
  File "/scratch/cnt0024/hmg2840/albert7a/anaconda3/lib/python3.7/site-packages/distributed/cli/dask_worker.py", line 405, in <module>
    go()
  File "/scratch/cnt0024/hmg2840/albert7a/anaconda3/lib/python3.7/site-packages/distributed/cli/dask_worker.py", line 401, in go
    main()
  File "/scratch/cnt0024/hmg2840/albert7a/anaconda3/lib/python3.7/site-packages/click/core.py", line 764, in __call__
    return self.main(*args, **kwargs)
  File "/scratch/cnt0024/hmg2840/albert7a/anaconda3/lib/python3.7/site-packages/click/core.py", line 717, in main
    rv = self.invoke(ctx)
  File "/scratch/cnt0024/hmg2840/albert7a/anaconda3/lib/python3.7/site-packages/click/core.py", line 956, in invoke
    return ctx.invoke(self.callback, **ctx.params)
  File "/scratch/cnt0024/hmg2840/albert7a/anaconda3/lib/python3.7/site-packages/click/core.py", line 555, in invoke
    return callback(*args, **kwargs)
  File "/scratch/cnt0024/hmg2840/albert7a/anaconda3/lib/python3.7/site-packages/distributed/cli/dask_worker.py", line 392, in main
    raise TimeoutError("Timed out starting worker.") from None
tornado.util.TimeoutError: Timed out starting worker.
/scratch/cnt0024/hmg2840/albert7a/anaconda3/lib/python3.7/site-packages/distributed/utils.py:136: RuntimeWarning: Couldn't detect a suitable IP address for reaching '8.8.8.8', defaulting to '127.0.0.1': [Errno 101] Network is unreachable
  RuntimeWarning,
